Workbook

Sheet HOW TO USE
B1: 📊 PANDUAN PENGGUNAAN — DATA PENCAPAIAN 2026
B3: CARA PENGGUNAAN HARIAN
B4: LANGKAH 1 | C4: Buka sheet bulan yang aktif (JAN / FEB / MAR / dst.)
B5: LANGKAH 2 | C5: Pergi ke bagian INPUT DATA (sel berwarna kuning).
B6: LANGKAH 3 | C6: Drop / paste data dari file DATA MKS hari ini ke tabel INPUT MKS.
B7: LANGKAH 4 | C7: Drop / paste data dari file DATA NESTLE hari ini ke tabel INPUT NESTLE.
B8: LANGKAH 5 | C8: Update sel HARI TERSISA (kuning) dengan jumlah hari kerja yang tersisa di bulan ini.
B9: LANGKAH 6 | C9: Semua tabel FOOD & BEVERAGES dan NESTLE akan ter-update otomatis.
B11: ⚠ CATATAN PENTING
B12: MKS - Penggabungan | C12: I MADE LUIH + I Made Luih (Sanur) → digabung menjadi DENPASAR - SANUR
B13: MKS - Penggabungan | C13: Ni Ketut Sriasih (GT) + Ni Ketut Sriasih (MT) → digabung menjadi MODERN TRADE + GT
B14: MKS - Dikecualikan | C14: Management Bali → TIDAK dihitung dalam total
B15: MKS - Dikecualikan | C15: KA → dipindahkan ke perhitungan NESTLE (NP5)
B16: NESTLE - NP5 | C16: NP5 = nilai baris kosong (nama kosong) + KA dari MKS + NP5 raw
B17: NESTLE - NP3 | C17: NP3 final = NP3 raw + NP4 + NP5 (yang sudah dihitung di atas)
B18: TARGETS | C18: Target per sales per bulan diatur di sheet TARGETS — update di sana jika ada perubahan.

Sheet TARGETS
B1: TARGET BULANAN — FOOD & BEVERAGES + NESTLE
B3: FOOD & BEVERAGES TARGETS | D3: JAN | F3: FEB | H3: MAR | J3: APR | L3: MEI | N3: JUN | P3: JUL | R3: AGU | T3: SEP | V3: OKT | X3: NOV | Z3: DES
B4: AREA | C4: SALES | D4: JAN FOOD | E4: JAN BEV | F4: FEB FOOD | G4: FEB BEV | H4: MAR FOOD | I4: MAR BEV | J4: APR FOOD | K4: APR BEV | L4: MEI FOOD | M4: MEI BEV | N4: JUN FOOD | O4: JUN BEV | P4: JUL FOOD | Q4: JUL BEV | R4: AGU FOOD | S4: AGU BEV | T4: SEP FOOD | U4: SEP BEV | V4: OKT FOOD | W4: OKT BEV | X4: NOV FOOD | Y4: NOV BEV | Z4: DES FOOD | AA4: DES BEV
B5: UBUD | C5: PICROM | D5: 341958382 | E5: 50089195 | F5: 321645623 | G5: 42789365 | H5: 317433802 | I5: 49588709 | J5: 3.9668348e+08 | K5: 49588709 | L5: 416683478 | M5: 68270401 | N5: 0 | O5: 0 | P5: 0 | Q5: 0 | R5: 0 | S5: 0 | T5: 0 | U5: 0 | V5: 0 | W5: 0 | X5: 0 | Y5: 0 | Z5: 0 | AA5: 0
B6: DENPASAR - SANUR | C6: I MADE LUIH | D6: 1058997546 | E6: 173866062 | F6: 1018372028 | G6: 159266402 | H6: 1009948386 | I6: 172865092 | J6: 535182371 | K6: 172865092 | L6: 555182371 | M6: 191546784 | N6: 0 | O6: 0 | P6: 0 | Q6: 0 | R6: 0 | S6: 0 | T6: 0 | U6: 0 | V6: 0 | W6: 0 | X6: 0 | Y6: 0 | Z6: 0 | AA6: 0
B7: NAUGHTY NURIS | C7: NN MADE LUIH | D7: 241473268 | E7: 0 | F7: 0 | G7: 0 | H7: 0 | I7: 0 | J7: 241473268 | K7: 0 | L7: 241473268
B8: KUTA SELATAN - ULUWATU | C8: JUNI | D8: 491334077 | E8: 28700620 | F8: 471021318 | G8: 21400790 | H8: 466809497 | I8: 28200135 | J8: 5.9071247e+08 | K8: 28200135 | L8: 610712472 | M8: 46881827 | N8: 0 | O8: 0 | P8: 0 | Q8: 0 | R8: 0 | S8: 0 | T8: 0 | U8: 0 | V8: 0 | W8: 0 | X8: 0 | Y8: 0 | Z8: 0 | AA8: 0
B9: KUTA - INDUSTRI | C9: LANI | D9: 475292301 | E9: 74028954 | F9: 454979542 | G9: 66729124 | H9: 450767722 | I9: 73528469 | J9: 3.9506328e+08 | K9: 73528469 | L9: 405063284 | M9: 82869315 | N9: 0 | O9: 0 | P9: 0 | Q9: 0 | R9: 0 | S9: 0 | T9: 0 | U9: 0 | V9: 0 | W9: 0 | X9: 0 | Y9: 0 | Z9: 0 | AA9: 0
B10: KUTA - HOTEL | C10: LANI | D10: 519152974 | E10: 72399034 | F10: 498840215 | G10: 65099204 | H10: 494628394 | I10: 71898548 | J10: 4.6391883e+08 | K10: 71898548 | L10: 473918832 | M10: 81239394 | N10: 0 | O10: 0 | P10: 0 | Q10: 0 | R10: 0 | S10: 0 | T10: 0 | U10: 0 | V10: 0 | W10: 0 | X10: 0 | Y10: 0 | Z10: 0 | AA10: 0
B11: KUTA SELATAN - NUSA DUA (HOTEL) | C11: MONICA | D11: 919556575 | E11: 73747369 | F11: 899243816 | G11: 66447539 | H11: 895031995 | I11: 73246884 | J11: 9.4175835e+08 | K11: 73246884 | L11: 961758345 | M11: 91928576 | N11: 0 | O11: 0 | P11: 0 | Q11: 0 | R11: 0 | S11: 0 | T11: 0 | U11: 0 | V11: 0 | W11: 0 | X11: 0 | Y11: 0 | Z11: 0 | AA11: 0
B12: SEMINYAK | C12: SUJANA | D12: 988070138 | E12: 45600197 | F12: 967757378 | G12: 38300367 | H12: 963545558 | I12: 45099712 | J12: 485287059 | K12: 45099712 | L12: 505287059 | M12: 63781404 | N12: 0 | O12: 0 | P12: 0 | Q12: 0 | R12: 0 | S12: 0 | T12: 0 | U12: 0 | V12: 0 | W12: 0 | X12: 0 | Y12: 0 | Z12: 0 | AA12: 0
B13: NAUGHTY NURIS | C13: NN SUJANA | D13: 404133664 | E13: 0 | F13: 0 | G13: 0 | H13: 0 | I13: 0 | J13: 404133664 | K13: 0 | L13: 404133664
B14: KUTA - LEGIAN | C14: EKA | D14: 479914486 | E14: 120283183 | F14: 459601727 | G14: 112983353 | H14: 455389906 | I14: 119782698 | J14: 3.8401731e+08 | K14: 119782698 | L14: 404017309 | M14: 1.3846439e+08 | N14: 0 | O14: 0 | P14: 0 | Q14: 0 | R14: 0 | S14: 0 | T14: 0 | U14: 0 | V14: 0 | W14: 0 | X14: 0 | Y14: 0 | Z14: 0 | AA14: 0
B15: CANGGU 1 | C15: TAUFIK | D15: 564064928 | E15: 40560395 | F15: 543752169 | G15: 33260564 | H15: 539540348 | I15: 40059909 | J15: 6.116296e+08 | K15: 40059909 | L15: 631629596 | M15: 58741601 | N15: 0 | O15: 0 | P15: 0 | Q15: 0 | R15: 0 | S15: 0 | T15: 0 | U15: 0 | V15: 0 | W15: 0 | X15: 0 | Y15: 0 | Z15: 0 | AA15: 0
B16: CANGGU 2 | C16: DEWI KRISTIANI | D16: 365124134 | E16: 45582949 | F16: 344811375 | G16: 38283119 | H16: 340599555 | I16: 45082463 | J16: 3.6654302e+08 | K16: 45082463 | L16: 386543023 | M16: 63764155 | N16: 0 | O16: 0 | P16: 0 | Q16: 0 | R16: 0 | S16: 0 | T16: 0 | U16: 0 | V16: 0 | W16: 0 | X16: 0 | Y16: 0 | Z16: 0 | AA16: 0
B17: GT + FOODY | C17: WIRA | D17: 533473768 | E17: 311625739 | F17: 513161009 | G17: 304325909 | H17: 508949188 | I17: 311125253 | J17: 5.6335094e+08 | K17: 311125253 | L17: 583350942 | M17: 3.2980694e+08 | N17: 0 | O17: 0 | P17: 0 | Q17: 0 | R17: 0 | S17: 0 | T17: 0 | U17: 0 | V17: 0 | W17: 0 | X17: 0 | Y17: 0 | Z17: 0 | AA17: 0
B18: MODERN TRADE + GENERAL TRADE | C18: SRIASIH | D18: 332561215 | E18: 240289310 | F18: 291935697 | G18: 225689650 | H18: 283512056 | I18: 239288340 | J18: 2.3952569e+08 | K18: 239288340 | L18: 259525689 | M18: 2.5797003e+08 | N18: 0 | O18: 0 | P18: 0 | Q18: 0 | R18: 0 | S18: 0 | T18: 0 | U18: 0 | V18: 0 | W18: 0 | X18: 0 | Y18: 0 | Z18: 0 | AA18: 0
B20: NESTLE TARGETS
B21: CHANNEL | C21: SALES | D21: JAN | E21: FEB | F21: MAR | G21: APR | H21: MEI | I21: JUN | J21: JUL | K21: AGU | L21: SEP | M21: OKT | N21: NOV | O21: DES
B22: NP - 1 | C22: RIDWAN | D22: 333545989 | E22: 332600635 | F22: 323873505 | G22: 2.793919e+08 | H22: 2.7806462e+08 | I22: 0 | J22: 0 | K22: 0 | L22: 0 | M22: 0 | N22: 0 | O22: 0
B23: NP - 2 | C23: REDI | D23: 439764978 | E23: 467649702 | F23: 455379010 | G23: 4.1961196e+08 | H23: 4.1761855e+08 | I23: 0 | J23: 0 | K23: 0 | L23: 0 | M23: 0 | N23: 0 | O23: 0
B24: NP - 3 | C24: GEK MAS | D24: 403437384 | E24: 1016486951 | F24: 989815282 | G24: 1.0924855e+09 | H24: 1.0872956e+09 | I24: 0 | J24: 0 | K24: 0 | L24: 0 | M24: 0 | N24: 0 | O24: 0
B25: NP - 4 | C25: VACANT | D25: 490272925 | E25: 0 | F25: 0 | G25: 0 | H25: 0 | I25: 0 | J25: 0 | K25: 0 | L25: 0 | M25: 0 | N25: 0 | O25: 0
B26: NP - 5 | C26: - | D26: 0 | E26: 0 | F26: 0 | G26: 0 | H26: 0 | I26: 0 | J26: 0 | K26: 0 | L26: 0 | M26: 0 | N26: 0 | O26: 0
B29: 💡 Sel berwarna KUNING dapat diubah untuk memperbarui target. Angka biru = input manual.

Sheet JAN
B1: DATA PENCAPAIAN — FEBRUARY 2026
B3: HARI TERSISA (auto): | C3: =MAX(0,NETWORKDAYS.INTL(MAX(TODAY(),DATE(YEAR(TODAY()),1,1)),EOMONTH(DATE(YEAR(TODAY()),1,1),0),11)) -> 0 | D3: Hari kerja tersisa bulan ini (Sab s/d akhir bulan) — otomatis | E3: =DAY(EOMONTH(DATE(YEAR(TODAY()),1,1),0)) -> 31
B6: 📥 INPUT DATA HARIAN — Paste dari file sistem di sini | P6: FOOD_ACHIV (calc) | Q6: BEV_ACHIV (calc)
B7: INPUT: DATA MKS (FOOD & BEVERAGES) | P7: =C9 -> 0 | Q7: =D9 -> 0
B8: Nama_Kry | C8: GLOBAL (Food) | D8: BEVERAGE | E8: Grand Total | P8: =C22 -> 0 | Q8: =D22 -> 0
P9: =C12+C13 -> 0 | Q9: =D12+D13 -> 0
B10: Dewi Kristiani | P10: =C14 -> 0 | Q10: =D14 -> 0
B11: Eka | P11: =C17 -> 0 | Q11: =D17 -> 0
B12: I MADE LUIH | P12: =C16 -> 0 | Q12: =D16 -> 0
B13: I Made Luih (Sanur) | P13: =C19 -> 0 | Q13: =D19 -> 0
B14: Juni | P14: =C23 -> 0 | Q14: =D23 -> 0
B15: KA | P15: =C11 -> 0 | Q15: =D11 -> 0
B16: LANI | P16: =C24 -> 0 | Q16: =D24 -> 0
B17: Lani P | P17: =C10 -> 0 | Q17: =D10 -> 0
B18: Management Bali | P18: =C25 -> 0 | Q18: =D25 -> 0
B19: Monica | P19: =C20+C21 -> 0 | Q19: =D20+D21 -> 0
B20: Ni Ketut Sriasih (GT) | P20: =IFERROR(C29,0)+IFERROR(C15,0)+IFERROR(C34,0) -> 0 | Q20: NP5_calc
B21: Ni Ketut Sriasih (MT) | P21: =IFERROR(C32,0)+IFERROR(C33,0)+P20 -> 0 | Q21: NP3_final
B22: Picrom Stalyon
B23: Sujana
B24: Taufik
B25: Wira
B27: INPUT: DATA NESTLE
B28: Nama Kry | C28: Total
B30: NP1
B31: NP2
B32: NP3
B33: NP4
B34: NP5
B39: DATA PENCAPAIAN — GLOBAL — APRIL 2026 | E39: TARGET | F39: 1
B40: KATAGORI | C40: AREA | D40: TARGET | E40: ACHIEVEMENT | F40: % | G40: SELISIH | H40: PER HARI
B41: FOOD | C41: HORECA, GT, MT | D41: =SUM(TARGETS!D5:D18) -> 7715107456 | E41: =P8+P9+P10+P11+P12+P13+P14+P15+P16+P17+P18+P19 -> 0 | F41: =IFERROR(E41/D41,0) -> 0 | G41: =D41-E41 -> 7715107456 | H41: =IFERROR(G41/C3,0) -> 0
B42: BEVERAGE | C42: HORECA, GT, MT | D42: =SUM(TARGETS!E5:E18) -> 1276773007 | E42: =Q8+Q9+Q10+Q11+Q12+Q13+Q14+Q15+Q16+Q17+Q18+Q19 -> 0 | F42: =IFERROR(E42/D42,0) -> 0 | G42: =D42-E42 -> 1276773007 | H42: =IFERROR(G42/C3,0) -> 0
B43: NESTLE | C43: HORECA, GT, MT | D43: =SUM(TARGETS!D22:D26) -> 1667021276 | E43: =IFERROR(C30,0)+IFERROR(C31,0)+P21+E9 -> 0 | F43: =IFERROR(E43/D43,0) -> 0 | G43: =D43-E43 -> 1667021276 | H43: =IFERROR(G43/C3,0) -> 0
B44: TOTAL | D44: =D41+D42+D43 -> 10658901739 | E44: =E41+E42+E43 -> 0 | F44: =IFERROR(E44/D44,0) -> 0 | G44: =G41+G42+G43 -> 10658901739 | H44: =IFERROR(G44/C3,0) -> 0
B46: FOOD & BEVERAGES
B47: AREA | C47: SALES | D47: TARGET | G47: ACHIEVEMENT | J47: % | K47: SELISIH (Target - Achiv) | N47: PER HARI (sisa hari)
D48: Food | E48: Beverage | F48: Total | G48: Food | H48: Beverage | I48: Total | K48: FOOD | L48: BEVERAGE | M48: TOTAL
B49: UBUD | C49: PICROM | D49: =TARGETS!D5 -> 341958382 | E49: =TARGETS!E5 -> 50089195 | F49: =D49+E49 -> 392047577 | G49: =P8 -> 0 | H49: =Q8 -> 0 | I49: =G49+H49 -> 0 | J49: =IFERROR(I49/F49,0) -> 0 | K49: =D49-G49 -> 341958382 | L49: =E49-H49 -> 50089195 | M49: =F49-I49 -> 392047577 | N49: =IFERROR(M49/C3,0) -> 0
B50: DENPASAR - SANUR | C50: I MADE LUIH | D50: =TARGETS!D6 -> 1058997546 | E50: =TARGETS!E6 -> 173866062 | F50: =D50+E50 -> 1232863608 | G50: =P9 -> 0 | H50: =Q9 -> 0 | I50: =G50+H50 -> 0 | J50: =IFERROR(I50/F50,0) -> 0 | K50: =D50-G50 -> 1058997546 | L50: =E50-H50 -> 173866062 | M50: =F50-I50 -> 1232863608 | N50: =IFERROR(M50/C3,0) -> 0
...

Sheet FEB
B1: DATA PENCAPAIAN — FEBRUARY 2026
B3: HARI TERSISA (auto): | C3: =MAX(0,NETWORKDAYS.INTL(MAX(TODAY(),DATE(YEAR(TODAY()),2,1)),EOMONTH(DATE(YEAR(TODAY()),2,1),0),11)) -> 0 | D3: Hari kerja tersisa bulan ini (Sab s/d akhir bulan) — otomatis | E3: =DAY(EOMONTH(DATE(YEAR(TODAY()),2,1),0)) -> 28
B6: 📥 INPUT DATA HARIAN — Paste dari file sistem di sini | P6: FOOD_ACHIV (calc) | Q6: BEV_ACHIV (calc)
B7: INPUT: DATA MKS (FOOD & BEVERAGES) | P7: =C9 -> 0 | Q7: =D9 -> 0
B8: Nama_Kry | C8: GLOBAL (Food) | D8: BEVERAGE | E8: Grand Total | P8: =C22 -> 0 | Q8: =D22 -> 0
P9: =C12+C13 -> 0 | Q9: =D12+D13 -> 0
B10: Dewi Kristiani | P10: =C14 -> 0 | Q10: =D14 -> 0
B11: Eka | P11: =C17 -> 0 | Q11: =D17 -> 0
B12: I MADE LUIH | P12: =C16 -> 0 | Q12: =D16 -> 0
B13: I Made Luih (Sanur) | P13: =C19 -> 0 | Q13: =D19 -> 0
B14: Juni | P14: =C23 -> 0 | Q14: =D23 -> 0
B15: KA | P15: =C11 -> 0 | Q15: =D11 -> 0
B16: LANI | P16: =C24 -> 0 | Q16: =D24 -> 0
B17: Lani P | P17: =C10 -> 0 | Q17: =D10 -> 0
B18: Management Bali | P18: =C25 -> 0 | Q18: =D25 -> 0
B19: Monica | P19: =C20+C21 -> 0 | Q19: =D20+D21 -> 0
B20: Ni Ketut Sriasih (GT) | P20: =IFERROR(C29,0)+IFERROR(C15,0)+IFERROR(C34,0) -> 0 | Q20: NP5_calc
B21: Ni Ketut Sriasih (MT) | P21: =IFERROR(C32,0)+IFERROR(C33,0)+P20 -> 0 | Q21: NP3_final
B22: Picrom Stalyon
B23: Sujana
B24: Taufik
B25: Wira
B27: INPUT: DATA NESTLE
B28: Nama Kry | C28: Total
B30: NP1
B31: NP2
B32: NP3
B33: NP4
B34: NP5
B39: DATA PENCAPAIAN — GLOBAL — APRIL 2026 | E39: TARGET | F39: 1
B40: KATAGORI | C40: AREA | D40: TARGET | E40: ACHIEVEMENT | F40: % | G40: SELISIH | H40: PER HARI
B41: FOOD | C41: HORECA, GT, MT | D41: =SUM(TARGETS!F5:F18) -> 6785121897 | E41: =P8+P9+P10+P11+P12+P13+P14+P15+P16+P17+P18+P19 -> 0 | F41: =IFERROR(E41/D41,0) -> 0 | G41: =D41-E41 -> 6785121897 | H41: =IFERROR(G41/C3,0) -> 0
B42: BEVERAGE | C42: HORECA, GT, MT | D42: =SUM(TARGETS!G5:G18) -> 1174575386 | E42: =Q8+Q9+Q10+Q11+Q12+Q13+Q14+Q15+Q16+Q17+Q18+Q19 -> 0 | F42: =IFERROR(E42/D42,0) -> 0 | G42: =D42-E42 -> 1174575386 | H42: =IFERROR(G42/C3,0) -> 0
B43: NESTLE | C43: HORECA, GT, MT | D43: =SUM(TARGETS!E22:E26) -> 1816737288 | E43: =IFERROR(C30,0)+IFERROR(C31,0)+P21+E9 -> 0 | F43: =IFERROR(E43/D43,0) -> 0 | G43: =D43-E43 -> 1816737288 | H43: =IFERROR(G43/C3,0) -> 0
B44: TOTAL | D44: =D41+D42+D43 -> 9776434571 | E44: =E41+E42+E43 -> 0 | F44: =IFERROR(E44/D44,0) -> 0 | G44: =G41+G42+G43 -> 9776434571 | H44: =IFERROR(G44/C3,0) -> 0
B46: FOOD & BEVERAGES
B47: AREA | C47: SALES | D47: TARGET | G47: ACHIEVEMENT | J47: % | K47: SELISIH (Target - Achiv) | N47: PER HARI (sisa hari)
D48: Food | E48: Beverage | F48: Total | G48: Food | H48: Beverage | I48: Total | K48: FOOD | L48: BEVERAGE | M48: TOTAL
B49: UBUD | C49: PICROM | D49: =TARGETS!F5 -> 321645623 | E49: =TARGETS!G5 -> 42789365 | F49: =D49+E49 -> 364434988 | G49: =P8 -> 0 | H49: =Q8 -> 0 | I49: =G49+H49 -> 0 | J49: =IFERROR(I49/F49,0) -> 0 | K49: =D49-G49 -> 321645623 | L49: =E49-H49 -> 42789365 | M49: =F49-I49 -> 364434988 | N49: =IFERROR(M49/C3,0) -> 0
B50: DENPASAR - SANUR | C50: I MADE LUIH | D50: =TARGETS!F6 -> 1018372028 | E50: =TARGETS!G6 -> 159266402 | F50: =D50+E50 -> 1177638430 | G50: =P9 -> 0 | H50: =Q9 -> 0 | I50: =G50+H50 -> 0 | J50: =IFERROR(I50/F50,0) -> 0 | K50: =D50-G50 -> 1018372028 | L50: =E50-H50 -> 159266402 | M50: =F50-I50 -> 1177638430 | N50: =IFERROR(M50/C3,0) -> 0
...

Sheet MAR
B1: DATA PENCAPAIAN — MARET 2026
B3: HARI TERSISA (auto): | C3: =MAX(0,NETWORKDAYS.INTL(MAX(TODAY(),DATE(YEAR(TODAY()),3,1)),EOMONTH(DATE(YEAR(TODAY()),3,1),0),11)) -> 0 | D3: Hari kerja tersisa bulan ini (Sab s/d akhir bulan) — otomatis | E3: =DAY(EOMONTH(DATE(YEAR(TODAY()),3,1),0)) -> 31
B6: 📥 INPUT DATA HARIAN — Paste dari file sistem di sini | P6: FOOD_ACHIV (calc) | Q6: BEV_ACHIV (calc)
B7: INPUT: DATA MKS (FOOD & BEVERAGES) | P7: =C9 -> 188107.92 | Q7: =D9 -> 0
B8: Nama_Kry | C8: GLOBAL (Food) | D8: BEVERAGE | E8: Grand Total | P8: =C22 -> 2.5616173e+08 | Q8: =D22 -> 33244870
B9: ANGELIA | C9: 188107.92 | D9: 0 | E9: 188107.92 | P9: =C12+C13 -> 4.009844e+08 | Q9: =D12+D13 -> 97493652
B10: Dewi Kristiani | C10: 2.4179305e+08 | D10: 27052169 | E10: 2.6884521e+08 | P10: =C14 -> 4.4895174e+08 | Q10: =D14 -> 25395525
B11: Eka | C11: 2.7524889e+08 | D11: 67651089 | E11: 3.4289998e+08 | P11: =C17 -> 2.7357432e+08 | Q11: =D17 -> 65561081
B12: I MADE LUIH | C12: 1.8366472e+08 | D12: 65497608 | E12: 2.4916233e+08 | P12: =C16 -> 3.4153385e+08 | Q12: =D16 -> 55146187
B13: I Made Luih (Sanur) | C13: 2.1731968e+08 | D13: 31996044 | E13: 2.4931573e+08 | P13: =C19 -> 7.2499612e+08 | Q13: =D19 -> 66333666
B14: Juni | C14: 4.4895174e+08 | D14: 25395525 | E14: 4.7434727e+08 | P14: =C23 -> 4.7402635e+08 | Q14: =D23 -> 42452264
B15: KA | C15: 282161.88 | E15: 282161.88 | P15: =C11 -> 2.7524889e+08 | Q15: =D11 -> 67651089
B16: LANI | C16: 3.4153385e+08 | D16: 55146187 | E16: 3.9668003e+08 | P16: =C24 -> 3.9123193e+08 | Q16: =D24 -> 47651173
B17: Lani P | C17: 2.7357432e+08 | D17: 65561081 | E17: 3.391354e+08 | P17: =C10 -> 2.4179305e+08 | Q17: =D10 -> 27052169
B18: Management Bali | C18: 1.4545809e+09 | D18: 24019256 | E18: 1.4786001e+09 | P18: =C25 -> 5.5177326e+08 | Q18: =D25 -> 1.7603189e+08
B19: Monica | C19: 7.2499612e+08 | D19: 66333666 | E19: 7.9132978e+08 | P19: =C20+C21 -> 1.8568238e+08 | Q19: =D20+D21 -> 1.4648446e+08
B20: Ni Ketut Sriasih (GT) | C20: 1.4318064e+08 | D20: 24973221 | E20: 1.6815386e+08 | P20: =IFERROR(C29,0)+IFERROR(C15,0)+IFERROR(C34,0) -> 11690499 | Q20: NP5_calc
B21: Ni Ketut Sriasih (MT) | C21: 42501732 | D21: 1.2151124e+08 | E21: 1.6401297e+08 | P21: =IFERROR(C32,0)+IFERROR(C33,0)+P20 -> 6.873782e+08 | Q21: NP3_final
B22: Picrom Stalyon | C22: 2.5616173e+08 | D22: 33244870 | E22: 2.894066e+08
B23: Sujana | C23: 4.7402635e+08 | D23: 42452264 | E23: 5.1647861e+08
B24: Taufik | C24: 3.9123193e+08 | D24: 47651173 | E24: 4.3888311e+08
B25: Wira | C25: 5.5177326e+08 | D25: 1.7603189e+08 | E25: 7.2780515e+08
B27: INPUT: DATA NESTLE
B28: Nama Kry | C28: Total
C29: 3087270.3
B30: NP1 | C30: 1.7421393e+08
B31: NP2 | C31: 3.0977874e+08
B32: NP3 | C32: 2.7639741e+08
B33: NP4 | C33: 3.992903e+08
B34: NP5 | C34: 8321067.2
B39: DATA PENCAPAIAN — GLOBAL — MARET 2026 | E39: TARGET | F39: 1
B40: KATAGORI | C40: AREA | D40: TARGET | E40: ACHIEVEMENT | G40: SELISIH | H40: PER HARI
B41: FOOD | C41: HORECA, GT, MT | D41: =SUM(TARGETS!H5:H18) -> 6726156407 | E41: =P8+P9+P10+P11+P12+P13+P14+P15+P16+P17+P18+P19 -> 4.565958e+09 | F41: =IFERROR(E41/D41,0) -> 0.67883613 | G41: =D41-E41 -> 2.1601984e+09 | H41: =IFERROR(G41/C3,0) -> 0
B42: BEVERAGE | C42: HORECA, GT, MT | D42: =SUM(TARGETS!I5:I18) -> 1269766212 | E42: =Q7+Q8+Q9+Q10+Q11+Q12+Q13+Q14+Q15+Q16+Q17+Q18+Q19 -> 8.5049803e+08 | F42: =IFERROR(E42/D42,0) -> 0.66980679 | G42: =D42-E42 -> 4.1926819e+08 | H42: =IFERROR(G42/C3,0) -> 0
B43: NESTLE | C43: HORECA, GT, MT | D43: =SUM(TARGETS!F22:F26) -> 1769067797 | E43: =IFERROR(C30,0)+IFERROR(C31,0)+P21+E9 -> 1.171559e+09 | F43: =IFERROR(E43/D43,0) -> 0.66224651 | G43: =D43-E43 -> 5.9750882e+08 | H43: =IFERROR(G43/C3,0) -> 0
B44: TOTAL | D44: =D41+D42+D43 -> 9764990416 | E44: =E41+E42+E43 -> 6.588015e+09 | F44: =IFERROR(E44/D44,0) -> 0.67465658 | G44: =G41+G42+G43 -> 3.1769754e+09 | H44: =IFERROR(G44/C3,0) -> 0
B46: FOOD & BEVERAGES
B47: AREA | C47: SALES | D47: TARGET | G47: ACHIEVEMENT | J47: % | K47: SELISIH (Target - Achiv) | N47: PER HARI (sisa hari)
D48: Food | E48: Beverage | F48: Total | G48: Food | H48: Beverage | I48: Total | K48: FOOD | L48: BEVERAGE | M48: TOTAL
B49: UBUD | C49: PICROM | D49: =TARGETS!H5 -> 317433802 | E49: =TARGETS!I5 -> 49588709 | F49: =D49+E49 -> 367022511 | G49: =P8 -> 2.5616173e+08 | H49: =Q8 -> 33244870 | I49: =G49+H49 -> 2.894066e+08 | J49: =IFERROR(I49/F49,0) -> 0.78852549 | K49: =D49-G49 -> 61272068 | L49: =E49-H49 -> 16343839 | M49: =F49-I49 -> 77615907 | N49: =IFERROR(M49/C3,0) -> 0
...

Sheet APR
B1: DATA PENCAPAIAN — APRIL 2026
B3: HARI TERSISA (auto): | C3: =MAX(0,NETWORKDAYS.INTL(MAX(TODAY(),DATE(YEAR(TODAY()),4,1)),EOMONTH(DATE(YEAR(TODAY()),4,1),0),11)) -> 0 | D3: Hari kerja tersisa bulan ini (Sab s/d akhir bulan) — otomatis | E3: =DAY(EOMONTH(DATE(YEAR(TODAY()),4,1),0)) -> 30
B6: 📥 INPUT DATA HARIAN — Paste dari file sistem di sini | M6: FOOD_ACHIV (calc) | N6: BEV_ACHIV (calc)
B7: INPUT: DATA MKS (FOOD & BEVERAGES) | M7: =C9 -> 0 | N7: =D9 -> 0
B8: Nama_Kry | C8: GLOBAL (Food) | D8: BEVERAGE | E8: Balian | F8: Grand Total | M8: =C24 -> 2.9977057e+08 | N8: =D24 -> 45375105
C9: 0 | D9: 0 | E9: 0 | M9: =C12+C13 -> 4.9166979e+08 | N9: =D12+D13 -> 1.2024821e+08
B10: Dewi Kristiani | C10: 3.0343956e+08 | D10: 28364315 | E10: 61031206 | F10: 3.9283508e+08 | M10: =C14 -> 5.3799728e+08 | N10: =D14 -> 21205741
B11: Eka | C11: 3.0413774e+08 | D11: 1.1970715e+08 | E11: 34053355 | F11: 4.5789825e+08 | M11: =C17 -> 3.5562612e+08 | N11: =D17 -> 44657676
B12: I MADE LUIH | C12: 2.5527224e+08 | D12: 80101515 | E12: 71143242 | F12: 4.06517e+08 | M12: =C16 -> 4.4968261e+08 | N12: =D16 -> 60505589
B13: I Made Luih (Sanur) | C13: 2.3639755e+08 | D13: 40146697 | E13: 10759099 | F13: 2.8730334e+08 | M13: =C19 -> 1.0309154e+09 | N13: =D19 -> 59498536
B14: Juni | C14: 5.3799728e+08 | D14: 21205741 | E14: 66130324 | F14: 6.2533334e+08 | M14: =C25 -> 3.7875454e+08 | N14: =D25 -> 62284985
B15: KA | M15: =C11 -> 3.0413774e+08 | N15: =D11 -> 1.1970715e+08
B16: LANI | C16: 4.4968261e+08 | D16: 60505589 | E16: 2883783.8 | F16: 5.1307199e+08 | M16: =C26 -> 4.7929173e+08 | N16: =D26 -> 61629600
B17: Lani P | C17: 3.5562612e+08 | D17: 44657676 | F17: 4.002838e+08 | M17: =C10 -> 3.0343956e+08 | N17: =D10 -> 28364315
B18: Management Bali | C18: 1.2675771e+09 | D18: 9652531.9 | E18: 3932432.4 | F18: 1.281162e+09 | M18: =C27 -> 6.6355982e+08 | N18: =D27 -> 2.0025323e+08
B19: Monica | C19: 1.0309154e+09 | D19: 59498536 | E19: 2.8720362e+08 | F19: 1.3776175e+09 | M19: =C20+C21 -> 1.62675e+08 | N19: =D20+D21 -> 1.5270811e+08
B20: Ni Ketut Sriasih (GT) | C20: 1.0531506e+08 | D20: 16467728 | F20: 1.2178279e+08 | M20: =IFERROR(C31,0)+IFERROR(C15,0)+IFERROR(C36,0) -> 3.1129081e+08 | N20: NP5_calc
B21: Ni Ketut Sriasih (MT) | C21: 57359939 | D21: 1.3624038e+08 | F21: 1.9360032e+08 | M21: =IFERROR(C34,0)+IFERROR(C35,0)+M20 -> 8.9713048e+08 | N21: NP3_final
B22: NN Made Luih | C22: 38884329 | E22: 12315315 | F22: 51199644
B23: NN Sujana | C23: 1.2055049e+08 | E23: 17151621 | F23: 1.3770211e+08
B24: Picrom Stalyon | C24: 2.9977057e+08 | D24: 45375105 | E24: 24325369 | F24: 3.6947104e+08
B25: Sujana | C25: 3.7875454e+08 | D25: 62284985 | E25: 26407801 | F25: 4.6744732e+08
B26: Taufik | C26: 4.7929173e+08 | D26: 61629600 | E26: 1.1273604e+08 | F26: 6.5365737e+08
B27: Wira | C27: 6.6355982e+08 | D27: 2.0025323e+08 | F27: 8.6381306e+08
B29: INPUT: DATA NESTLE
B30: Nama Kry | C30: Total
B32: NP1 | C32: 2.402376e+08
B33: NP2 | C33: 4.4993374e+08
B34: NP3 | C34: 3.1827859e+08
B35: NP4 | C35: 2.6756109e+08
B36: NP5 | C36: 3.1129081e+08
B41: DATA PENCAPAIAN — GLOBAL — 30 APRIL 2026 | E41: TARGET | F41: 1
B42: KATAGORI | C42: AREA | D42: TARGET | E42: ACHIEVEMENT | F42: % | G42: SELISIH | H42: PER HARI
B43: FOOD | C43: HORECA, GT, MT | D43: =SUM(TARGETS!J5:J7,TARGETS!J8:J13,TARGETS!J14:J18) -> 6.6192793e+09 | E43: =G65 -> 5.6169549e+09 | F43: =IFERROR(E43/D43,0) -> 0.848575 | G43: =D43-E43 -> 1.0023244e+09 | H43: =IFERROR(G43/C3,0) -> 0
B44: BEVERAGE | C44: HORECA, GT, MT | D44: =SUM(TARGETS!K5:K6,TARGETS!K8:K12,TARGETS!K14:K18) -> 1269766212 | E44: =N8+N9+N10+N11+N12+N13+N14+N15+N16+N17+N18+N19 -> 9.7643825e+08 | F44: =IFERROR(E44/D44,0) -> 0.76899058 | G44: =D44-E44 -> 2.9332796e+08 | H44: =IFERROR(G44/C3,0) -> 0
B45: NESTLE | C45: HORECA, GT, MT | D45: =SUM(TARGETS!G22:G26) -> 1.7914894e+09 | E45: =IFERROR(C32,0)+IFERROR(C33,0)+M21+F9 -> 1.5873018e+09 | F45: =IFERROR(E45/D45,0) -> 0.88602358 | G45: =D45-E45 -> 2.0418754e+08 | H45: =IFERROR(G45/C3,0) -> 0
B46: TOTAL | D46: =D43+D44+D45 -> 9.6805349e+09 | E46: =E43+E44+E45 -> 8.180695e+09 | F46: =IFERROR(E46/D46,0) -> 0.84506643 | G46: =G43+G44+G45 -> 1.4998399e+09 | H46: =IFERROR(G46/C3,0) -> 0
B48: FOOD & BEVERAGES
B49: AREA | C49: SALES | D49: TARGET | G49: ACHIEVEMENT | J49: % | K49: SELISIH (Target - Achiv) | N49: PER HARI (sisa hari)
D50: Food | E50: Beverage | F50: Total | G50: Food | H50: Beverage | I50: Total | K50: FOOD | L50: BEVERAGE | M50: TOTAL
...

Sheet MEI
B1: DATA PENCAPAIAN — MEI 2026
B3: HARI TERSISA (auto): | C3: =NETWORKDAYS.INTL(TODAY(),EOMONTH(TODAY(),0),11) -> 5 | D3: Hari kerja tersisa bulan ini (Sab s/d akhir bulan) — otomatis | E3: =DAY(EOMONTH(TODAY(),0)) -> 31
B6: 📥 INPUT DATA HARIAN — Paste dari file sistem di sini | M6: FOOD_ACHIV (calc) | N6: BEV_ACHIV (calc)
B7: INPUT: DATA MKS (FOOD & BEVERAGES) | M7: =C9 -> 0 | N7: =D9 -> 0
B8: Nama_Kry | C8: GLOBAL (Food) | D8: BEVERAGE | E8: Balian | F8: Grand Total | M8: =C24 -> 2.5451239e+08 | N8: =D24 -> 37644372
C9: 0 | D9: 0 | M9: =C12+C13 -> 4.5016343e+08 | N9: =D12+D13 -> 87396621
B10: Dewi Kristiani | C10: 2.4590466e+08 | D10: 30000486 | E10: 1.3545924e+08 | F10: 4.1136439e+08 | M10: =C14 -> 5.3146329e+08 | N10: =D14 -> 24103560
B11: Eka | C11: 3.2804427e+08 | D11: 83068875 | E11: 38843244 | F11: 4.4995639e+08 | M11: =C17 -> 3.143507e+08 | N11: =D17 -> 33550551
B12: I MADE LUIH | C12: 2.4418549e+08 | D12: 58807482 | E12: 37261125 | F12: 3.402541e+08 | M12: =C16 -> 3.643925e+08 | N12: =D16 -> 57646325
B13: I Made Luih (Sanur) | C13: 2.0597794e+08 | D13: 28589139 | E13: 36852139 | F13: 2.7141922e+08 | M13: =C19 -> 7.8353056e+08 | N13: =D19 -> 63122837
B14: Juni | C14: 5.3146329e+08 | D14: 24103560 | E14: 1.8561874e+08 | F14: 7.4118559e+08 | M14: =C25 -> 3.3398469e+08 | N14: =D25 -> 58336777
B15: KA | M15: =C11 -> 3.2804427e+08 | N15: =D11 -> 83068875
B16: LANI | C16: 3.643925e+08 | D16: 57646325 | E16: 11608108 | F16: 4.3364693e+08 | M16: =C26 -> 3.8902552e+08 | N16: =D26 -> 52235613
B17: Lani P | C17: 3.143507e+08 | D17: 33550551 | F17: 3.4790125e+08 | M17: =C10 -> 2.4590466e+08 | N17: =D10 -> 30000486
B18: Management Bali | C18: 8.8298378e+08 | D18: 8619114.3 | E18: 10706757 | F18: 9.0230965e+08 | M18: =C27 -> 5.8553833e+08 | N18: =D27 -> 1.7285992e+08
B19: Monica | C19: 7.8353056e+08 | D19: 63122837 | E19: 5.994313e+08 | F19: 1.4460847e+09 | M19: =C20+C21 -> 2.0294631e+08 | N19: =D20+D21 -> 1.1844698e+08
B20: Ni Ketut Sriasih (GT) | C20: 1.589515e+08 | D20: 28556300 | E20: 3816216.3 | F20: 1.9132401e+08 | M20: =IFERROR(C31,0)+IFERROR(C15,0)+IFERROR(C36,0) -> 822000 | N20: NP5_calc
B21: Ni Ketut Sriasih (MT) | C21: 43994814 | D21: 89890683 | E21: 48551352 | F21: 1.8243685e+08 | M21: =IFERROR(C34,0)+IFERROR(C35,0)+M20 -> 5.5430346e+08 | N21: NP3_final
B22: NN Made Luih | C22: 2.1128161e+08 | E22: 10814414 | F22: 2.2209602e+08
B23: NN Sujana | C23: 2.4146098e+08 | E23: 10300180 | F23: 2.5176116e+08
B24: Picrom Stalyon | C24: 2.5451239e+08 | D24: 37644372 | E24: 99482755 | F24: 3.9163952e+08
B25: Sujana | C25: 3.3398469e+08 | D25: 58336777 | E25: 2.0805153e+08 | F25: 6.00373e+08
B26: Taufik | C26: 3.8902552e+08 | D26: 52235613 | E26: 3.685054e+08 | F26: 8.0976654e+08
B27: Wira | C27: 5.8553833e+08 | D27: 1.7285992e+08 | E27: 18025946 | F27: 7.7642419e+08
B29: INPUT: DATA NESTLE
B30: Nama Kry | C30: Total
B32: NP1 | C32: 2.337264e+08
B33: NP2 | C33: 3.2159658e+08
B34: NP3 | C34: 2.6988009e+08
B35: NP4 | C35: 2.8360137e+08
B36: NP5 | C36: 822000
B41: DATA PENCAPAIAN — GLOBAL — 26 MEI 2026 | E41: TARGET | F41: =IF(MONTH(TODAY())=5,DAY(TODAY())/DAY(EOMONTH(TODAY(),0)),IF(MONTH(TODAY())>5,1,0)) -> 0.83870968
B42: KATAGORI | C42: AREA | D42: TARGET | E42: ACHIEVEMENT | F42: % | G42: SELISIH | H42: PER HARI
B43: FOOD | C43: HORECA, GT, MT | D43: =SUM(TARGETS!L5:L7,TARGETS!L8:L13,TARGETS!L14:L18) -> 6839279332 | E43: =G65 -> 5.2365992e+09 | F43: =IFERROR(E43/D43,0) -> 0.76566535 | G43: =D43-E43 -> 1.6026801e+09 | H43: =IFERROR(G43/C3,0) -> 3.2053602e+08
B44: BEVERAGE | C44: HORECA, GT, MT | D44: =SUM(TARGETS!M5:M6,TARGETS!M8:M12,TARGETS!M14:M18) -> 1.4752648e+09 | E44: =N8+N9+N10+N11+N12+N13+N14+N15+N16+N17+N18+N19 -> 8.1841291e+08 | F44: =IFERROR(E44/D44,0) -> 0.55475661 | G44: =D44-E44 -> 6.5685191e+08 | H44: =IFERROR(G44/C3,0) -> 1.3137038e+08
B45: NESTLE | C45: HORECA, GT, MT | D45: =SUM(TARGETS!H22:H26) -> 1.7829787e+09 | E45: =IFERROR(C32,0)+IFERROR(C33,0)+M21+F9 -> 1.1096264e+09 | F45: =IFERROR(E45/D45,0) -> 0.62234418 | G45: =D45-E45 -> 6.7335229e+08 | H45: =IFERROR(G45/C3,0) -> 1.3467046e+08
B46: TOTAL | D46: =D43+D44+D45 -> 1.0097523e+10 | E46: =E43+E44+E45 -> 7.1646386e+09 | F46: =IFERROR(E46/D46,0) -> 0.70954418 | G46: =G43+G44+G45 -> 2.9328843e+09 | H46: =IFERROR(G46/C3,0) -> 5.8657686e+08
B48: FOOD & BEVERAGES
B49: AREA | C49: SALES | D49: TARGET | G49: ACHIEVEMENT | J49: % | K49: SELISIH (Target - Achiv) | N49: PER HARI (sisa hari)
D50: Food | E50: Beverage | F50: Total | G50: Food | H50: Beverage | I50: Total | K50: FOOD | L50: BEVERAGE | M50: TOTAL
...

Sheet JUN
B1: DATA PENCAPAIAN — JUNI 2026
B3: HARI TERSISA (auto): | C3: =MAX(0,NETWORKDAYS.INTL(MAX(TODAY(),DATE(YEAR(TODAY()),6,1)),EOMONTH(DATE(YEAR(TODAY()),6,1),0),11)) -> 26 | D3: Hari kerja tersisa bulan ini (Sab s/d akhir bulan) — otomatis | E3: =DAY(EOMONTH(DATE(YEAR(TODAY()),6,1),0)) -> 30
B6: 📥 INPUT DATA HARIAN — Paste dari file sistem di sini | M6: FOOD_ACHIV (calc) | N6: BEV_ACHIV (calc)
B7: INPUT: DATA MKS (FOOD & BEVERAGES) | M7: =C9 -> 0 | N7: =D9 -> 0
B8: Nama_Kry | C8: GLOBAL (Food) | D8: BEVERAGE | E8: Balian | F8: Grand Total | M8: =C24 -> 0 | N8: =D24 -> 0
C9: 0 | D9: 0 | M9: =C12+C13 -> 0 | N9: =D12+D13 -> 0
B10: Dewi Kristiani | M10: =C14 -> 0 | N10: =D14 -> 0
B11: Eka | M11: =C17 -> 0 | N11: =D17 -> 0
B12: I MADE LUIH | M12: =C16 -> 0 | N12: =D16 -> 0
B13: I Made Luih (Sanur) | M13: =C19 -> 0 | N13: =D19 -> 0
B14: Juni | M14: =C25 -> 0 | N14: =D25 -> 0
B15: KA | M15: =C11 -> 0 | N15: =D11 -> 0
B16: LANI | M16: =C26 -> 0 | N16: =D26 -> 0
B17: Lani P | M17: =C10 -> 0 | N17: =D10 -> 0
B18: Management Bali | M18: =C27 -> 0 | N18: =D27 -> 0
B19: Monica | M19: =C20+C21 -> 0 | N19: =D20+D21 -> 0
B20: Ni Ketut Sriasih (GT) | M20: =IFERROR(C31,0)+IFERROR(C15,0)+IFERROR(C36,0) -> 0 | N20: NP5_calc
B21: Ni Ketut Sriasih (MT) | M21: =IFERROR(C34,0)+IFERROR(C35,0)+M20 -> 0 | N21: NP3_final
B22: NN Made Luih
B23: NN Sujana
B24: Picrom Stalyon
B25: Sujana
B26: Taufik
B27: Wira
B29: INPUT: DATA NESTLE
B30: Nama Kry | C30: Total
B32: NP1 | C32: 0
B33: NP2 | C33: 0
B34: NP3 | C34: 0
B35: NP4 | C35: 0
B36: NP5 | C36: 0
B41: DATA PENCAPAIAN — GLOBAL — JUNI 2026 | E41: TARGET | F41: =IF(MONTH(TODAY())=6,DAY(TODAY())/DAY(EOMONTH(TODAY(),0)),IF(MONTH(TODAY())>6,1,0)) -> 0
B42: KATAGORI | C42: AREA | D42: TARGET | E42: ACHIEVEMENT | F42: % | G42: SELISIH | H42: PER HARI
B43: FOOD | C43: HORECA, GT, MT | D43: =SUM(TARGETS!N5:N7,TARGETS!N8:N13,TARGETS!N14:N18) -> 0 | E43: =G65 -> 0 | F43: =IFERROR(E43/D43,0) -> 0 | G43: =D43-E43 -> 0 | H43: =IFERROR(G43/C3,0) -> 0
B44: BEVERAGE | C44: HORECA, GT, MT | D44: =SUM(TARGETS!O5:O6,TARGETS!O8:O12,TARGETS!O14:O18) -> 0 | E44: =N8+N9+N10+N11+N12+N13+N14+N15+N16+N17+N18+N19 -> 0 | F44: =IFERROR(E44/D44,0) -> 0 | G44: =D44-E44 -> 0 | H44: =IFERROR(G44/C3,0) -> 0
B45: NESTLE | C45: HORECA, GT, MT | D45: =SUM(TARGETS!I22:I26) -> 0 | E45: =IFERROR(C32,0)+IFERROR(C33,0)+M21+F9 -> 0 | F45: =IFERROR(E45/D45,0) -> 0 | G45: =D45-E45 -> 0 | H45: =IFERROR(G45/C3,0) -> 0
B46: TOTAL | D46: =D43+D44+D45 -> 0 | E46: =E43+E44+E45 -> 0 | F46: =IFERROR(E46/D46,0) -> 0 | G46: =G43+G44+G45 -> 0 | H46: =IFERROR(G46/C3,0) -> 0
B48: FOOD & BEVERAGES
B49: AREA | C49: SALES | D49: TARGET | G49: ACHIEVEMENT | J49: % | K49: SELISIH (Target - Achiv) | N49: PER HARI (sisa hari)
D50: Food | E50: Beverage | F50: Total | G50: Food | H50: Beverage | I50: Total | K50: FOOD | L50: BEVERAGE | M50: TOTAL
...

Sheet JUL
B1: DATA PENCAPAIAN — JULI 2026
B3: HARI TERSISA (auto): | C3: =MAX(0,NETWORKDAYS.INTL(MAX(TODAY(),DATE(YEAR(TODAY()),7,1)),EOMONTH(DATE(YEAR(TODAY()),7,1),0),11)) -> 27 | D3: Hari kerja tersisa bulan ini (Sab s/d akhir bulan) — otomatis | E3: =DAY(EOMONTH(DATE(YEAR(TODAY()),7,1),0)) -> 31
B6: 📥 INPUT DATA HARIAN — Paste dari file sistem di sini | M6: FOOD_ACHIV (calc) | N6: BEV_ACHIV (calc)
B7: INPUT: DATA MKS (FOOD & BEVERAGES) | M7: =C9 -> 0 | N7: =D9 -> 0
B8: Nama_Kry | C8: GLOBAL (Food) | D8: BEVERAGE | E8: Balian | F8: Grand Total | M8: =C24 -> 0 | N8: =D24 -> 0
C9: 0 | D9: 0 | M9: =C12+C13 -> 0 | N9: =D12+D13 -> 0
B10: Dewi Kristiani | M10: =C14 -> 0 | N10: =D14 -> 0
B11: Eka | M11: =C17 -> 0 | N11: =D17 -> 0
B12: I MADE LUIH | M12: =C16 -> 0 | N12: =D16 -> 0
B13: I Made Luih (Sanur) | M13: =C19 -> 0 | N13: =D19 -> 0
B14: Juni | M14: =C25 -> 0 | N14: =D25 -> 0
B15: KA | M15: =C11 -> 0 | N15: =D11 -> 0
B16: LANI | M16: =C26 -> 0 | N16: =D26 -> 0
B17: Lani P | M17: =C10 -> 0 | N17: =D10 -> 0
B18: Management Bali | M18: =C27 -> 0 | N18: =D27 -> 0
B19: Monica | M19: =C20+C21 -> 0 | N19: =D20+D21 -> 0
B20: Ni Ketut Sriasih (GT) | M20: =IFERROR(C31,0)+IFERROR(C15,0)+IFERROR(C36,0) -> 0 | N20: NP5_calc
B21: Ni Ketut Sriasih (MT) | M21: =IFERROR(C34,0)+IFERROR(C35,0)+M20 -> 0 | N21: NP3_final
B22: NN Made Luih
B23: NN Sujana
B24: Picrom Stalyon
B25: Sujana
B26: Taufik
B27: Wira
B29: INPUT: DATA NESTLE
B30: Nama Kry | C30: Total
B32: NP1 | C32: 0
B33: NP2 | C33: 0
B34: NP3 | C34: 0
B35: NP4 | C35: 0
B36: NP5 | C36: 0
B41: DATA PENCAPAIAN — GLOBAL — JULI 2026 | E41: TARGET | F41: =IF(MONTH(TODAY())=7,DAY(TODAY())/DAY(EOMONTH(TODAY(),0)),IF(MONTH(TODAY())>7,1,0)) -> 0
B42: KATAGORI | C42: AREA | D42: TARGET | E42: ACHIEVEMENT | F42: % | G42: SELISIH | H42: PER HARI
B43: FOOD | C43: HORECA, GT, MT | D43: =SUM(TARGETS!P5:P7,TARGETS!P8:P13,TARGETS!P14:P18) -> 0 | E43: =G65 -> 0 | F43: =IFERROR(E43/D43,0) -> 0 | G43: =D43-E43 -> 0 | H43: =IFERROR(G43/C3,0) -> 0
B44: BEVERAGE | C44: HORECA, GT, MT | D44: =SUM(TARGETS!Q5:Q6,TARGETS!Q8:Q12,TARGETS!Q14:Q18) -> 0 | E44: =N8+N9+N10+N11+N12+N13+N14+N15+N16+N17+N18+N19 -> 0 | F44: =IFERROR(E44/D44,0) -> 0 | G44: =D44-E44 -> 0 | H44: =IFERROR(G44/C3,0) -> 0
B45: NESTLE | C45: HORECA, GT, MT | D45: =SUM(TARGETS!J22:J26) -> 0 | E45: =IFERROR(C32,0)+IFERROR(C33,0)+M21+F9 -> 0 | F45: =IFERROR(E45/D45,0) -> 0 | G45: =D45-E45 -> 0 | H45: =IFERROR(G45/C3,0) -> 0
B46: TOTAL | D46: =D43+D44+D45 -> 0 | E46: =E43+E44+E45 -> 0 | F46: =IFERROR(E46/D46,0) -> 0 | G46: =G43+G44+G45 -> 0 | H46: =IFERROR(G46/C3,0) -> 0
B48: FOOD & BEVERAGES
B49: AREA | C49: SALES | D49: TARGET | G49: ACHIEVEMENT | J49: % | K49: SELISIH (Target - Achiv) | N49: PER HARI (sisa hari)
D50: Food | E50: Beverage | F50: Total | G50: Food | H50: Beverage | I50: Total | K50: FOOD | L50: BEVERAGE | M50: TOTAL
...

Sheet AGU
B1: DATA PENCAPAIAN — AGUSTUS 2026
B3: HARI TERSISA (auto): | C3: =MAX(0,NETWORKDAYS.INTL(MAX(TODAY(),DATE(YEAR(TODAY()),8,1)),EOMONTH(DATE(YEAR(TODAY()),8,1),0),11)) -> 26 | D3: Hari kerja tersisa bulan ini (Sab s/d akhir bulan) — otomatis | E3: =DAY(EOMONTH(DATE(YEAR(TODAY()),8,1),0)) -> 31
B6: 📥 INPUT DATA HARIAN — Paste dari file sistem di sini | M6: FOOD_ACHIV (calc) | N6: BEV_ACHIV (calc)
B7: INPUT: DATA MKS (FOOD & BEVERAGES) | M7: =C9 -> 0 | N7: =D9 -> 0
B8: Nama_Kry | C8: GLOBAL (Food) | D8: BEVERAGE | E8: Balian | F8: Grand Total | M8: =C24 -> 0 | N8: =D24 -> 0
C9: 0 | D9: 0 | M9: =C12+C13 -> 0 | N9: =D12+D13 -> 0
B10: Dewi Kristiani | M10: =C14 -> 0 | N10: =D14 -> 0
B11: Eka | M11: =C17 -> 0 | N11: =D17 -> 0
B12: I MADE LUIH | M12: =C16 -> 0 | N12: =D16 -> 0
B13: I Made Luih (Sanur) | M13: =C19 -> 0 | N13: =D19 -> 0
B14: Juni | M14: =C25 -> 0 | N14: =D25 -> 0
B15: KA | M15: =C11 -> 0 | N15: =D11 -> 0
B16: LANI | M16: =C26 -> 0 | N16: =D26 -> 0
B17: Lani P | M17: =C10 -> 0 | N17: =D10 -> 0
B18: Management Bali | M18: =C27 -> 0 | N18: =D27 -> 0
B19: Monica | M19: =C20+C21 -> 0 | N19: =D20+D21 -> 0
B20: Ni Ketut Sriasih (GT) | M20: =IFERROR(C31,0)+IFERROR(C15,0)+IFERROR(C36,0) -> 0 | N20: NP5_calc
B21: Ni Ketut Sriasih (MT) | M21: =IFERROR(C34,0)+IFERROR(C35,0)+M20 -> 0 | N21: NP3_final
B22: NN Made Luih
B23: NN Sujana
B24: Picrom Stalyon
B25: Sujana
B26: Taufik
B27: Wira
B29: INPUT: DATA NESTLE
B30: Nama Kry | C30: Total
B32: NP1 | C32: 0
B33: NP2 | C33: 0
B34: NP3 | C34: 0
B35: NP4 | C35: 0
B36: NP5 | C36: 0
B41: DATA PENCAPAIAN — GLOBAL — AGUSTUS 2026 | E41: TARGET | F41: =IF(MONTH(TODAY())=8,DAY(TODAY())/DAY(EOMONTH(TODAY(),0)),IF(MONTH(TODAY())>8,1,0)) -> 0
B42: KATAGORI | C42: AREA | D42: TARGET | E42: ACHIEVEMENT | F42: % | G42: SELISIH | H42: PER HARI
B43: FOOD | C43: HORECA, GT, MT | D43: =SUM(TARGETS!R5:R7,TARGETS!R8:R13,TARGETS!R14:R18) -> 0 | E43: =G65 -> 0 | F43: =IFERROR(E43/D43,0) -> 0 | G43: =D43-E43 -> 0 | H43: =IFERROR(G43/C3,0) -> 0
B44: BEVERAGE | C44: HORECA, GT, MT | D44: =SUM(TARGETS!S5:S6,TARGETS!S8:S12,TARGETS!S14:S18) -> 0 | E44: =N8+N9+N10+N11+N12+N13+N14+N15+N16+N17+N18+N19 -> 0 | F44: =IFERROR(E44/D44,0) -> 0 | G44: =D44-E44 -> 0 | H44: =IFERROR(G44/C3,0) -> 0
B45: NESTLE | C45: HORECA, GT, MT | D45: =SUM(TARGETS!K22:K26) -> 0 | E45: =IFERROR(C32,0)+IFERROR(C33,0)+M21+F9 -> 0 | F45: =IFERROR(E45/D45,0) -> 0 | G45: =D45-E45 -> 0 | H45: =IFERROR(G45/C3,0) -> 0
B46: TOTAL | D46: =D43+D44+D45 -> 0 | E46: =E43+E44+E45 -> 0 | F46: =IFERROR(E46/D46,0) -> 0 | G46: =G43+G44+G45 -> 0 | H46: =IFERROR(G46/C3,0) -> 0
B48: FOOD & BEVERAGES
B49: AREA | C49: SALES | D49: TARGET | G49: ACHIEVEMENT | J49: % | K49: SELISIH (Target - Achiv) | N49: PER HARI (sisa hari)
D50: Food | E50: Beverage | F50: Total | G50: Food | H50: Beverage | I50: Total | K50: FOOD | L50: BEVERAGE | M50: TOTAL
...

Sheet SEP
B1: DATA PENCAPAIAN — SEPTEMBER 2026
B3: HARI TERSISA (auto): | C3: =MAX(0,NETWORKDAYS.INTL(MAX(TODAY(),DATE(YEAR(TODAY()),9,1)),EOMONTH(DATE(YEAR(TODAY()),9,1),0),11)) -> 26 | D3: Hari kerja tersisa bulan ini (Sab s/d akhir bulan) — otomatis | E3: =DAY(EOMONTH(DATE(YEAR(TODAY()),9,1),0)) -> 30
B6: 📥 INPUT DATA HARIAN — Paste dari file sistem di sini | M6: FOOD_ACHIV (calc) | N6: BEV_ACHIV (calc)
B7: INPUT: DATA MKS (FOOD & BEVERAGES) | M7: =C9 -> 0 | N7: =D9 -> 0
B8: Nama_Kry | C8: GLOBAL (Food) | D8: BEVERAGE | E8: Balian | F8: Grand Total | M8: =C24 -> 0 | N8: =D24 -> 0
C9: 0 | D9: 0 | M9: =C12+C13 -> 0 | N9: =D12+D13 -> 0
B10: Dewi Kristiani | M10: =C14 -> 0 | N10: =D14 -> 0
B11: Eka | M11: =C17 -> 0 | N11: =D17 -> 0
B12: I MADE LUIH | M12: =C16 -> 0 | N12: =D16 -> 0
B13: I Made Luih (Sanur) | M13: =C19 -> 0 | N13: =D19 -> 0
B14: Juni | M14: =C25 -> 0 | N14: =D25 -> 0
B15: KA | M15: =C11 -> 0 | N15: =D11 -> 0
B16: LANI | M16: =C26 -> 0 | N16: =D26 -> 0
B17: Lani P | M17: =C10 -> 0 | N17: =D10 -> 0
B18: Management Bali | M18: =C27 -> 0 | N18: =D27 -> 0
B19: Monica | M19: =C20+C21 -> 0 | N19: =D20+D21 -> 0
B20: Ni Ketut Sriasih (GT) | M20: =IFERROR(C31,0)+IFERROR(C15,0)+IFERROR(C36,0) -> 0 | N20: NP5_calc
B21: Ni Ketut Sriasih (MT) | M21: =IFERROR(C34,0)+IFERROR(C35,0)+M20 -> 0 | N21: NP3_final
B22: NN Made Luih
B23: NN Sujana
B24: Picrom Stalyon
B25: Sujana
B26: Taufik
B27: Wira
B29: INPUT: DATA NESTLE
B30: Nama Kry | C30: Total
B32: NP1 | C32: 0
B33: NP2 | C33: 0
B34: NP3 | C34: 0
B35: NP4 | C35: 0
B36: NP5 | C36: 0
B41: DATA PENCAPAIAN — GLOBAL — SEPTEMBER 2026 | E41: TARGET | F41: =IF(MONTH(TODAY())=9,DAY(TODAY())/DAY(EOMONTH(TODAY(),0)),IF(MONTH(TODAY())>9,1,0)) -> 0
B42: KATAGORI | C42: AREA | D42: TARGET | E42: ACHIEVEMENT | F42: % | G42: SELISIH | H42: PER HARI
B43: FOOD | C43: HORECA, GT, MT | D43: =SUM(TARGETS!T5:T7,TARGETS!T8:T13,TARGETS!T14:T18) -> 0 | E43: =G65 -> 0 | F43: =IFERROR(E43/D43,0) -> 0 | G43: =D43-E43 -> 0 | H43: =IFERROR(G43/C3,0) -> 0
B44: BEVERAGE | C44: HORECA, GT, MT | D44: =SUM(TARGETS!U5:U6,TARGETS!U8:U12,TARGETS!U14:U18) -> 0 | E44: =N8+N9+N10+N11+N12+N13+N14+N15+N16+N17+N18+N19 -> 0 | F44: =IFERROR(E44/D44,0) -> 0 | G44: =D44-E44 -> 0 | H44: =IFERROR(G44/C3,0) -> 0
B45: NESTLE | C45: HORECA, GT, MT | D45: =SUM(TARGETS!L22:L26) -> 0 | E45: =IFERROR(C32,0)+IFERROR(C33,0)+M21+F9 -> 0 | F45: =IFERROR(E45/D45,0) -> 0 | G45: =D45-E45 -> 0 | H45: =IFERROR(G45/C3,0) -> 0
B46: TOTAL | D46: =D43+D44+D45 -> 0 | E46: =E43+E44+E45 -> 0 | F46: =IFERROR(E46/D46,0) -> 0 | G46: =G43+G44+G45 -> 0 | H46: =IFERROR(G46/C3,0) -> 0
B48: FOOD & BEVERAGES
B49: AREA | C49: SALES | D49: TARGET | G49: ACHIEVEMENT | J49: % | K49: SELISIH (Target - Achiv) | N49: PER HARI (sisa hari)
D50: Food | E50: Beverage | F50: Total | G50: Food | H50: Beverage | I50: Total | K50: FOOD | L50: BEVERAGE | M50: TOTAL
...

Sheet OKT
B1: DATA PENCAPAIAN — OKTOBER 2026
B3: HARI TERSISA (auto): | C3: =MAX(0,NETWORKDAYS.INTL(MAX(TODAY(),DATE(YEAR(TODAY()),10,1)),EOMONTH(DATE(YEAR(TODAY()),10,1),0),11)) -> 27 | D3: Hari kerja tersisa bulan ini (Sab s/d akhir bulan) — otomatis | E3: =DAY(EOMONTH(DATE(YEAR(TODAY()),10,1),0)) -> 31
B6: 📥 INPUT DATA HARIAN — Paste dari file sistem di sini | M6: FOOD_ACHIV (calc) | N6: BEV_ACHIV (calc)
B7: INPUT: DATA MKS (FOOD & BEVERAGES) | M7: =C9 -> 0 | N7: =D9 -> 0
B8: Nama_Kry | C8: GLOBAL (Food) | D8: BEVERAGE | E8: Balian | F8: Grand Total | M8: =C24 -> 0 | N8: =D24 -> 0
C9: 0 | D9: 0 | M9: =C12+C13 -> 0 | N9: =D12+D13 -> 0
B10: Dewi Kristiani | M10: =C14 -> 0 | N10: =D14 -> 0
B11: Eka | M11: =C17 -> 0 | N11: =D17 -> 0
B12: I MADE LUIH | M12: =C16 -> 0 | N12: =D16 -> 0
B13: I Made Luih (Sanur) | M13: =C19 -> 0 | N13: =D19 -> 0
B14: Juni | M14: =C25 -> 0 | N14: =D25 -> 0
B15: KA | M15: =C11 -> 0 | N15: =D11 -> 0
B16: LANI | M16: =C26 -> 0 | N16: =D26 -> 0
B17: Lani P | M17: =C10 -> 0 | N17: =D10 -> 0
B18: Management Bali | M18: =C27 -> 0 | N18: =D27 -> 0
B19: Monica | M19: =C20+C21 -> 0 | N19: =D20+D21 -> 0
B20: Ni Ketut Sriasih (GT) | M20: =IFERROR(C31,0)+IFERROR(C15,0)+IFERROR(C36,0) -> 0 | N20: NP5_calc
B21: Ni Ketut Sriasih (MT) | M21: =IFERROR(C34,0)+IFERROR(C35,0)+M20 -> 0 | N21: NP3_final
B22: NN Made Luih
B23: NN Sujana
B24: Picrom Stalyon
B25: Sujana
B26: Taufik
B27: Wira
B29: INPUT: DATA NESTLE
B30: Nama Kry | C30: Total
B32: NP1 | C32: 0
B33: NP2 | C33: 0
B34: NP3 | C34: 0
B35: NP4 | C35: 0
B36: NP5 | C36: 0
B41: DATA PENCAPAIAN — GLOBAL — OKTOBER 2026 | E41: TARGET | F41: =IF(MONTH(TODAY())=10,DAY(TODAY())/DAY(EOMONTH(TODAY(),0)),IF(MONTH(TODAY())>10,1,0)) -> 0
B42: KATAGORI | C42: AREA | D42: TARGET | E42: ACHIEVEMENT | F42: % | G42: SELISIH | H42: PER HARI
B43: FOOD | C43: HORECA, GT, MT | D43: =SUM(TARGETS!V5:V7,TARGETS!V8:V13,TARGETS!V14:V18) -> 0 | E43: =G65 -> 0 | F43: =IFERROR(E43/D43,0) -> 0 | G43: =D43-E43 -> 0 | H43: =IFERROR(G43/C3,0) -> 0
B44: BEVERAGE | C44: HORECA, GT, MT | D44: =SUM(TARGETS!W5:W6,TARGETS!W8:W12,TARGETS!W14:W18) -> 0 | E44: =N8+N9+N10+N11+N12+N13+N14+N15+N16+N17+N18+N19 -> 0 | F44: =IFERROR(E44/D44,0) -> 0 | G44: =D44-E44 -> 0 | H44: =IFERROR(G44/C3,0) -> 0
B45: NESTLE | C45: HORECA, GT, MT | D45: =SUM(TARGETS!M22:M26) -> 0 | E45: =IFERROR(C32,0)+IFERROR(C33,0)+M21+F9 -> 0 | F45: =IFERROR(E45/D45,0) -> 0 | G45: =D45-E45 -> 0 | H45: =IFERROR(G45/C3,0) -> 0
B46: TOTAL | D46: =D43+D44+D45 -> 0 | E46: =E43+E44+E45 -> 0 | F46: =IFERROR(E46/D46,0) -> 0 | G46: =G43+G44+G45 -> 0 | H46: =IFERROR(G46/C3,0) -> 0
B48: FOOD & BEVERAGES
B49: AREA | C49: SALES | D49: TARGET | G49: ACHIEVEMENT | J49: % | K49: SELISIH (Target - Achiv) | N49: PER HARI (sisa hari)
D50: Food | E50: Beverage | F50: Total | G50: Food | H50: Beverage | I50: Total | K50: FOOD | L50: BEVERAGE | M50: TOTAL
...

Sheet NOV
B1: DATA PENCAPAIAN — NOVEMBER 2026
B3: HARI TERSISA (auto): | C3: =MAX(0,NETWORKDAYS.INTL(MAX(TODAY(),DATE(YEAR(TODAY()),11,1)),EOMONTH(DATE(YEAR(TODAY()),11,1),0),11)) -> 25 | D3: Hari kerja tersisa bulan ini (Sab s/d akhir bulan) — otomatis | E3: =DAY(EOMONTH(DATE(YEAR(TODAY()),11,1),0)) -> 30
B6: 📥 INPUT DATA HARIAN — Paste dari file sistem di sini | M6: FOOD_ACHIV (calc) | N6: BEV_ACHIV (calc)
B7: INPUT: DATA MKS (FOOD & BEVERAGES) | M7: =C9 -> 0 | N7: =D9 -> 0
B8: Nama_Kry | C8: GLOBAL (Food) | D8: BEVERAGE | E8: Balian | F8: Grand Total | M8: =C24 -> 0 | N8: =D24 -> 0
C9: 0 | D9: 0 | M9: =C12+C13 -> 0 | N9: =D12+D13 -> 0
B10: Dewi Kristiani | M10: =C14 -> 0 | N10: =D14 -> 0
B11: Eka | M11: =C17 -> 0 | N11: =D17 -> 0
B12: I MADE LUIH | M12: =C16 -> 0 | N12: =D16 -> 0
B13: I Made Luih (Sanur) | M13: =C19 -> 0 | N13: =D19 -> 0
B14: Juni | M14: =C25 -> 0 | N14: =D25 -> 0
B15: KA | M15: =C11 -> 0 | N15: =D11 -> 0
B16: LANI | M16: =C26 -> 0 | N16: =D26 -> 0
B17: Lani P | M17: =C10 -> 0 | N17: =D10 -> 0
B18: Management Bali | M18: =C27 -> 0 | N18: =D27 -> 0
B19: Monica | M19: =C20+C21 -> 0 | N19: =D20+D21 -> 0
B20: Ni Ketut Sriasih (GT) | M20: =IFERROR(C31,0)+IFERROR(C15,0)+IFERROR(C36,0) -> 0 | N20: NP5_calc
B21: Ni Ketut Sriasih (MT) | M21: =IFERROR(C34,0)+IFERROR(C35,0)+M20 -> 0 | N21: NP3_final
B22: NN Made Luih
B23: NN Sujana
B24: Picrom Stalyon
B25: Sujana
B26: Taufik
B27: Wira
B29: INPUT: DATA NESTLE
B30: Nama Kry | C30: Total
B32: NP1 | C32: 0
B33: NP2 | C33: 0
B34: NP3 | C34: 0
B35: NP4 | C35: 0
B36: NP5 | C36: 0
B41: DATA PENCAPAIAN — GLOBAL — NOVEMBER 2026 | E41: TARGET | F41: =IF(MONTH(TODAY())=11,DAY(TODAY())/DAY(EOMONTH(TODAY(),0)),IF(MONTH(TODAY())>11,1,0)) -> 0
B42: KATAGORI | C42: AREA | D42: TARGET | E42: ACHIEVEMENT | F42: % | G42: SELISIH | H42: PER HARI
B43: FOOD | C43: HORECA, GT, MT | D43: =SUM(TARGETS!X5:X7,TARGETS!X8:X13,TARGETS!X14:X18) -> 0 | E43: =G65 -> 0 | F43: =IFERROR(E43/D43,0) -> 0 | G43: =D43-E43 -> 0 | H43: =IFERROR(G43/C3,0) -> 0
B44: BEVERAGE | C44: HORECA, GT, MT | D44: =SUM(TARGETS!Y5:Y6,TARGETS!Y8:Y12,TARGETS!Y14:Y18) -> 0 | E44: =N8+N9+N10+N11+N12+N13+N14+N15+N16+N17+N18+N19 -> 0 | F44: =IFERROR(E44/D44,0) -> 0 | G44: =D44-E44 -> 0 | H44: =IFERROR(G44/C3,0) -> 0
B45: NESTLE | C45: HORECA, GT, MT | D45: =SUM(TARGETS!N22:N26) -> 0 | E45: =IFERROR(C32,0)+IFERROR(C33,0)+M21+F9 -> 0 | F45: =IFERROR(E45/D45,0) -> 0 | G45: =D45-E45 -> 0 | H45: =IFERROR(G45/C3,0) -> 0
B46: TOTAL | D46: =D43+D44+D45 -> 0 | E46: =E43+E44+E45 -> 0 | F46: =IFERROR(E46/D46,0) -> 0 | G46: =G43+G44+G45 -> 0 | H46: =IFERROR(G46/C3,0) -> 0
B48: FOOD & BEVERAGES
B49: AREA | C49: SALES | D49: TARGET | G49: ACHIEVEMENT | J49: % | K49: SELISIH (Target - Achiv) | N49: PER HARI (sisa hari)
D50: Food | E50: Beverage | F50: Total | G50: Food | H50: Beverage | I50: Total | K50: FOOD | L50: BEVERAGE | M50: TOTAL
...

Sheet DES
B1: DATA PENCAPAIAN — DESEMBER 2026
B3: HARI TERSISA (auto): | C3: =MAX(0,NETWORKDAYS.INTL(MAX(TODAY(),DATE(YEAR(TODAY()),12,1)),EOMONTH(DATE(YEAR(TODAY()),12,1),0),11)) -> 27 | D3: Hari kerja tersisa bulan ini (Sab s/d akhir bulan) — otomatis | E3: =DAY(EOMONTH(DATE(YEAR(TODAY()),12,1),0)) -> 31
B6: 📥 INPUT DATA HARIAN — Paste dari file sistem di sini | M6: FOOD_ACHIV (calc) | N6: BEV_ACHIV (calc)
B7: INPUT: DATA MKS (FOOD & BEVERAGES) | M7: =C9 -> 0 | N7: =D9 -> 0
B8: Nama_Kry | C8: GLOBAL (Food) | D8: BEVERAGE | E8: Balian | F8: Grand Total | M8: =C24 -> 0 | N8: =D24 -> 0
C9: 0 | D9: 0 | M9: =C12+C13 -> 0 | N9: =D12+D13 -> 0
B10: Dewi Kristiani | M10: =C14 -> 0 | N10: =D14 -> 0
B11: Eka | M11: =C17 -> 0 | N11: =D17 -> 0
B12: I MADE LUIH | M12: =C16 -> 0 | N12: =D16 -> 0
B13: I Made Luih (Sanur) | M13: =C19 -> 0 | N13: =D19 -> 0
B14: Juni | M14: =C25 -> 0 | N14: =D25 -> 0
B15: KA | M15: =C11 -> 0 | N15: =D11 -> 0
B16: LANI | M16: =C26 -> 0 | N16: =D26 -> 0
B17: Lani P | M17: =C10 -> 0 | N17: =D10 -> 0
B18: Management Bali | M18: =C27 -> 0 | N18: =D27 -> 0
B19: Monica | M19: =C20+C21 -> 0 | N19: =D20+D21 -> 0
B20: Ni Ketut Sriasih (GT) | M20: =IFERROR(C31,0)+IFERROR(C15,0)+IFERROR(C36,0) -> 0 | N20: NP5_calc
B21: Ni Ketut Sriasih (MT) | M21: =IFERROR(C34,0)+IFERROR(C35,0)+M20 -> 0 | N21: NP3_final
B22: NN Made Luih
B23: NN Sujana
B24: Picrom Stalyon
B25: Sujana
B26: Taufik
B27: Wira
B29: INPUT: DATA NESTLE
B30: Nama Kry | C30: Total
B32: NP1 | C32: 0
B33: NP2 | C33: 0
B34: NP3 | C34: 0
B35: NP4 | C35: 0
B36: NP5 | C36: 0
B41: DATA PENCAPAIAN — GLOBAL — DESEMBER 2026 | E41: TARGET | F41: =IF(MONTH(TODAY())=12,DAY(TODAY())/DAY(EOMONTH(TODAY(),0)),IF(MONTH(TODAY())>12,1,0)) -> 0
B42: KATAGORI | C42: AREA | D42: TARGET | E42: ACHIEVEMENT | F42: % | G42: SELISIH | H42: PER HARI
B43: FOOD | C43: HORECA, GT, MT | D43: =SUM(TARGETS!Z5:Z7,TARGETS!Z8:Z13,TARGETS!Z14:Z18) -> 0 | E43: =G65 -> 0 | F43: =IFERROR(E43/D43,0) -> 0 | G43: =D43-E43 -> 0 | H43: =IFERROR(G43/C3,0) -> 0
B44: BEVERAGE | C44: HORECA, GT, MT | D44: 0 | E44: =N8+N9+N10+N11+N12+N13+N14+N15+N16+N17+N18+N19 -> 0 | F44: =IFERROR(E44/D44,0) -> 0 | G44: =D44-E44 -> 0 | H44: =IFERROR(G44/C3,0) -> 0
B45: NESTLE | C45: HORECA, GT, MT | D45: =SUM(TARGETS!O22:O26) -> 0 | E45: =IFERROR(C32,0)+IFERROR(C33,0)+M21+F9 -> 0 | F45: =IFERROR(E45/D45,0) -> 0 | G45: =D45-E45 -> 0 | H45: =IFERROR(G45/C3,0) -> 0
B46: TOTAL | D46: =D43+D44+D45 -> 0 | E46: =E43+E44+E45 -> 0 | F46: =IFERROR(E46/D46,0) -> 0 | G46: =G43+G44+G45 -> 0 | H46: =IFERROR(G46/C3,0) -> 0
B48: FOOD & BEVERAGES
B49: AREA | C49: SALES | D49: TARGET | G49: ACHIEVEMENT | J49: % | K49: SELISIH (Target - Achiv) | N49: PER HARI (sisa hari)
D50: Food | E50: Beverage | F50: Total | G50: Food | H50: Beverage | I50: Total | K50: FOOD | L50: BEVERAGE | M50: TOTAL
...
