Workbook

Sheet HOW TO USE
B1: 📊 PANDUAN PENGGUNAAN — DATA PENCAPAIAN 2026
B3: CARA PENGGUNAAN HARIAN
B4: LANGKAH 1 | C4: Buka sheet bulan yang aktif (JAN / FEB / MAR / dst.)
B5: LANGKAH 2 | C5: Pergi ke bagian INPUT DATA (sel berwarna kuning).
B6: LANGKAH 3 | C6: Drop / paste data dari file DATA MKS hari ini ke tabel INPUT MKS.
B7: LANGKAH 4 | C7: Drop / paste data dari file DATA NESTLE hari ini ke tabel INPUT NESTLE.
B8: LANGKAH 5 | C8: Update sel HARI TERSISA (kuning) dengan jumlah hari kerja yang tersisa di bulan ini.
B9: LANGKAH 6 | C9: Semua tabel FOOD & BEVERAGES dan NESTLE akan ter-update otomatis.
B11: ⚠ CATATAN PENTING
B12: MKS - Penggabungan | C12: I MADE LUIH + I Made Luih (Sanur) → digabung menjadi DENPASAR - SANUR
B13: MKS - Penggabungan | C13: Ni Ketut Sriasih (GT) + Ni Ketut Sriasih (MT) → digabung menjadi MODERN TRADE + GT
B14: MKS - Dikecualikan | C14: Management Bali → TIDAK dihitung dalam total
B15: MKS - Dikecualikan | C15: KA → dipindahkan ke perhitungan NESTLE (NP5)
B16: NESTLE - NP5 | C16: NP5 = nilai baris kosong (nama kosong) + KA dari MKS + NP5 raw
B17: NESTLE - NP3 | C17: NP3 final = NP3 raw + NP4 + NP5 (yang sudah dihitung di atas)
B18: TARGETS | C18: Target per sales per bulan diatur di sheet TARGETS — update di sana jika ada perubahan.
B19: MKS - BAKERY | C19: Global Food kini dipisah: urutan paste = GLOBAL (Food), BEVERAGE, BAKERY, BALIAN, Grand Total. Sel kosong otomatis dihitung 0. Target Bakery diisi di sheet TARGETS (kolom '<BULAN> BAKERY').

Sheet TARGETS
B1: TARGET BULANAN — FOOD & BEVERAGES + NESTLE
B3: FOOD & BEVERAGES TARGETS | D3: JAN | G3: FEB | J3: MAR | M3: APR | P3: MEI | S3: JUN | V3: JUL | Y3: AGU | AB3: SEP | AE3: OKT | AH3: NOV | AK3: DES
B4: AREA | C4: SALES | D4: JAN FOOD | E4: JAN BEV | F4: JAN BAKERY | G4: FEB FOOD | H4: FEB BEV | I4: FEB BAKERY | J4: MAR FOOD | K4: MAR BEV | L4: MAR BAKERY | M4: APR FOOD | N4: APR BEV | O4: APR BAKERY | P4: MEI FOOD | Q4: MEI BEV | R4: MEI BAKERY | S4: JUN FOOD | T4: JUN BEV | U4: JUN BAKERY | V4: JUL FOOD | W4: JUL BEV | X4: JUL BAKERY | Y4: AGU FOOD | Z4: AGU BEV | AA4: AGU BAKERY | AB4: SEP FOOD | AC4: SEP BEV | AD4: SEP BAKERY | AE4: OKT FOOD | AF4: OKT BEV | AG4: OKT BAKERY | AH4: NOV FOOD | AI4: NOV BEV | AJ4: NOV BAKERY | AK4: DES FOOD | AL4: DES BEV | AM4: DES BAKERY
B5: UBUD | C5: PICROM | D5: 341958382 | E5: 50089195 | F5: 0 | G5: 321645623 | H5: 42789365 | I5: 0 | J5: 317433802 | K5: 49588709 | L5: 0 | M5: 3.9668348e+08 | N5: 49588709 | O5: 0 | P5: 416683478 | Q5: 68270401 | R5: 0 | S5: 451683478 | T5: 101830423 | U5: 0 | V5: 4.9123718e+08 | W5: 76328678 | X5: 0 | Y5: 306848843 | Z5: 60640124 | AA5: 198385865 | AB5: 2.690478e+08 | AC5: 69550316 | AD5: 1.757694e+08 | AE5: 2.6475695e+08 | AF5: 58508748 | AG5: 1.7296879e+08 | AH5: 0 | AI5: 0 | AJ5: 0 | AK5: 0 | AL5: 0 | AM5: 0
B6: DENPASAR - SANUR | C6: I MADE LUIH | D6: 1058997546 | E6: 173866062 | F6: 0 | G6: 1018372028 | H6: 159266402 | I6: 0 | J6: 1009948386 | K6: 172865092 | L6: 0 | M6: 535182371 | N6: 172865092 | O6: 0 | P6: 555182371 | Q6: 191546784 | R6: 0 | S6: 590182371 | T6: 225106806 | U6: 0 | V6: 6.5745716e+08 | W6: 1.8126506e+08 | X6: 0 | Y6: 222144871 | Z6: 1.655765e+08 | AA6: 449309820 | AB6: 1.8434383e+08 | AC6: 1.744867e+08 | AD6: 4.2669336e+08 | AE6: 1.8005298e+08 | AF6: 1.6344513e+08 | AG6: 4.2389275e+08 | AH6: 0 | AI6: 0 | AJ6: 0 | AK6: 0 | AL6: 0 | AM6: 0
B7: NAUGHTY NURIS | C7: NN MADE LUIH | D7: 241473268 | E7: 0 | F7: 0 | G7: 0 | H7: 0 | I7: 0 | J7: 0 | K7: 0 | L7: 0 | M7: 241473268 | N7: 0 | O7: 0 | P7: 241473268 | R7: 0 | S7: 241473268 | U7: 0 | V7: 2.4895557e+08 | X7: 0 | Y7: 262953105 | AA7: 0 | AB7: 2.6295311e+08 | AC7: 0 | AD7: 0 | AE7: 2.6295311e+08 | AF7: 0 | AG7: 0 | AJ7: 0 | AM7: 0
B8: KUTA SELATAN - ULUWATU | C8: JUNI | D8: 491334077 | E8: 28700620 | F8: 0 | G8: 471021318 | H8: 21400790 | I8: 0 | J8: 466809497 | K8: 28200135 | L8: 0 | M8: 5.9071247e+08 | N8: 28200135 | O8: 0 | P8: 610712472 | Q8: 46881827 | R8: 0 | S8: 645712472 | T8: 80441848 | U8: 0 | V8: 7.2838728e+08 | W8: 51482867 | X8: 0 | Y8: 633046146 | Z8: 35794312 | AA8: 109338663 | AB8: 5.952451e+08 | AC8: 44704505 | AD8: 86722202 | AE8: 5.9095425e+08 | AF8: 33662937 | AG8: 83921592 | AH8: 0 | AI8: 0 | AJ8: 0 | AK8: 0 | AL8: 0 | AM8: 0
B9: KUTA - INDUSTRI | C9: WAHYU FIB | D9: 475292301 | E9: 74028954 | F9: 0 | G9: 454979542 | H9: 66729124 | I9: 0 | J9: 450767722 | K9: 73528469 | L9: 0 | M9: 3.9506328e+08 | N9: 73528469 | O9: 0 | P9: 405063284 | Q9: 82869315 | R9: 0 | S9: 508918832 | T9: 80519404 | U9: 0 | V9: 4.8231218e+08 | W9: 70286112 | X9: 0 | Y9: 5575802 | Z9: 54597558 | AA9: 490733908 | AB9: 5575802 | AC9: 63507750 | AD9: 4.6811745e+08 | AE9: 5575802 | AF9: 63507750 | AG9: 4.6811745e+08 | AH9: 0 | AI9: 0 | AJ9: 0 | AK9: 0 | AL9: 0 | AM9: 0
B10: KUTA - HOTEL | C10: RONALD | D10: 519152974 | E10: 72399034 | F10: 0 | G10: 498840215 | H10: 65099204 | I10: 0 | J10: 494628394 | K10: 71898548 | L10: 0 | M10: 4.6391883e+08 | N10: 71898548 | O10: 0 | P10: 473918832 | Q10: 81239394 | R10: 0 | S10: 440063284 | T10: 82149325 | U10: 0 | V10: 5.05192e+08 | W10: 1.2295232e+08 | X10: 0 | Y10: 309612765 | Z10: 1.0726377e+08 | AA10: 209576770 | AB10: 2.7181172e+08 | AC10: 1.1617396e+08 | AD10: 1.8696031e+08 | AE10: 2.6752087e+08 | AF10: 1.0513239e+08 | AG10: 1.841597e+08 | AH10: 0 | AI10: 0 | AJ10: 0 | AK10: 0 | AL10: 0 | AM10: 0
B11: KUTA SELATAN - NUSA DUA (HOTEL) | C11: MONICA | D11: 919556575 | E11: 73747369 | F11: 0 | G11: 899243816 | H11: 66447539 | I11: 0 | J11: 895031995 | K11: 73246884 | L11: 0 | M11: 9.4175835e+08 | N11: 73246884 | O11: 0 | P11: 961758345 | Q11: 91928576 | R11: 0 | S11: 996758345 | T11: 125488598 | U11: 0 | V11: 1.0612454e+09 | W11: 1.01137e+08 | X11: 0 | Y11: 706692044 | Z11: 85448443 | AA11: 368550890 | AB11: 6.68891e+08 | AC11: 94358636 | AD11: 3.4593443e+08 | AE11: 6.6460015e+08 | AF11: 83317068 | AG11: 3.4313382e+08 | AH11: 0 | AI11: 0 | AJ11: 0 | AK11: 0 | AL11: 0 | AM11: 0
B12: SEMINYAK | C12: SUJANA | D12: 988070138 | E12: 45600197 | F12: 0 | G12: 967757378 | H12: 38300367 | I12: 0 | J12: 963545558 | K12: 45099712 | L12: 0 | M12: 485287059 | N12: 45099712 | O12: 0 | P12: 505287059 | Q12: 63781404 | R12: 0 | S12: 540287059 | T12: 97341426 | U12: 0 | V12: 5.6311417e+08 | W12: 1.0466503e+08 | X12: 0 | Y12: 302084971 | Z12: 88976480 | AA12: 275026731 | AB12: 2.6428393e+08 | AC12: 97886673 | AD12: 2.5241027e+08 | AE12: 2.5999308e+08 | AF12: 86845105 | AG12: 2.4960966e+08 | AH12: 0 | AI12: 0 | AJ12: 0 | AK12: 0 | AL12: 0 | AM12: 0
B13: NAUGHTY NURIS | C13: NN SUJANA | D13: 404133664 | E13: 0 | F13: 0 | G13: 0 | H13: 0 | I13: 0 | J13: 0 | K13: 0 | L13: 0 | M13: 404133664 | N13: 0 | O13: 0 | P13: 404133664 | R13: 0 | S13: 404133664 | U13: 0 | V13: 4.2984918e+08 | X13: 0 | Y13: 443846716 | AA13: 0 | AB13: 4.4384672e+08 | AC13: 0 | AD13: 0 | AE13: 4.4384672e+08 | AF13: 0 | AG13: 0 | AJ13: 0 | AM13: 0
B14: KUTA - LEGIAN | C14: WAHYU | D14: 479914486 | E14: 120283183 | F14: 0 | G14: 459601727 | H14: 112983353 | I14: 0 | J14: 455389906 | K14: 119782698 | L14: 0 | M14: 3.8401731e+08 | N14: 119782698 | O14: 0 | P14: 404017309 | Q14: 1.3846439e+08 | R14: 0 | S14: 439017309 | T14: 172024412 | U14: 0 | V14: 5.1472111e+08 | W14: 1.1766343e+08 | X14: 0 | Y14: 387829132 | Z14: 1.0197488e+08 | AA14: 140889511 | AB14: 3.5002809e+08 | AC14: 1.1088507e+08 | AD14: 1.1827305e+08 | AE14: 3.4573724e+08 | AF14: 99843502 | AG14: 1.1547244e+08 | AH14: 0 | AI14: 0 | AJ14: 0 | AK14: 0 | AL14: 0 | AM14: 0
B15: CANGGU 1 | C15: TAUFIK | D15: 564064928 | E15: 40560395 | F15: 0 | G15: 543752169 | H15: 33260564 | I15: 0 | J15: 539540348 | K15: 40059909 | L15: 0 | M15: 6.116296e+08 | N15: 40059909 | O15: 0 | P15: 631629596 | Q15: 58741601 | R15: 0 | S15: 666629596 | T15: 92301622 | U15: 0 | V15: 6.9884518e+08 | W15: 70945961 | X15: 0 | Y15: 518888039 | Z15: 55257406 | AA15: 193954669 | AB15: 4.8108699e+08 | AC15: 64167599 | AD15: 1.7133821e+08 | AE15: 4.7679614e+08 | AF15: 53126031 | AG15: 1.685376e+08 | AH15: 0 | AI15: 0 | AJ15: 0 | AK15: 0 | AL15: 0 | AM15: 0
B16: CANGGU 2 | C16: DEWI KRISTIANI | D16: 365124134 | E16: 45582949 | F16: 0 | G16: 344811375 | H16: 38283119 | I16: 0 | J16: 340599555 | K16: 45082463 | L16: 0 | M16: 3.6654302e+08 | N16: 45082463 | O16: 0 | P16: 386543023 | Q16: 63764155 | R16: 0 | S16: 421543023 | T16: 97324176 | U16: 0 | V16: 4.8187036e+08 | W16: 48351229 | X16: 0 | Y16: 210599044 | Z16: 32662674 | AA16: 285268852 | AB16: 1.72798e+08 | AC16: 41572867 | AD16: 2.6265239e+08 | AE16: 1.6850715e+08 | AF16: 30531299 | AG16: 2.5985178e+08 | AH16: 0 | AI16: 0 | AJ16: 0 | AK16: 0 | AL16: 0 | AM16: 0
B17: GT + FOODY | C17: WIRA | D17: 533473768 | E17: 311625739 | F17: 0 | G17: 513161009 | H17: 304325909 | I17: 0 | J17: 508949188 | K17: 311125253 | L17: 0 | M17: 5.6335094e+08 | N17: 311125253 | O17: 0 | P17: 583350942 | Q17: 3.2980694e+08 | R17: 0 | S17: 618350942 | T17: 363366966 | U17: 0 | V17: 7.0605493e+08 | W17: 3.261174e+08 | X17: 0 | Y17: 452060736 | Z17: 3.1042885e+08 | AA17: 267991724 | AB17: 4.1425969e+08 | AC17: 3.1933904e+08 | AD17: 2.4537526e+08 | AE17: 4.0996884e+08 | AF17: 3.0829747e+08 | AG17: 2.4257465e+08 | AH17: 0 | AI17: 0 | AJ17: 0 | AK17: 0 | AL17: 0 | AM17: 0
B18: MODERN TRADE + GENERAL TRADE | C18: SRIASIH | D18: 332561215 | E18: 240289310 | F18: 0 | G18: 291935697 | H18: 225689650 | I18: 0 | J18: 283512056 | K18: 239288340 | L18: 0 | M18: 2.3952569e+08 | N18: 239288340 | O18: 0 | P18: 259525689 | Q18: 2.5797003e+08 | R18: 0 | S18: 294525689 | T18: 291530053 | U18: 0 | V18: 3.786021e+08 | W18: 2.1151056e+08 | X18: 0 | Y18: 165415307 | Z18: 1.95822e+08 | AA18: 227184322 | AB18: 1.2761426e+08 | AC18: 2.047322e+08 | AD18: 2.0456786e+08 | AE18: 1.2332341e+08 | AF18: 1.9369063e+08 | AG18: 2.0176725e+08 | AH18: 0 | AI18: 0 | AJ18: 0 | AK18: 0 | AL18: 0 | AM18: 0
B20: NESTLE TARGETS
B21: CHANNEL | C21: SALES | D21: JAN | E21: FEB | F21: MAR | G21: APR | H21: MEI | I21: JUN | J21: JUL | K21: AGU | L21: SEP | M21: OKT | N21: NOV | O21: DES
B22: NP - 1 | C22: RIDWAN | D22: 333545989 | E22: 332600635 | F22: 323873505 | G22: 2.793919e+08 | H22: 2.7806462e+08 | I22: 285530553 | J22: 2.9313694e+08 | K22: 2.9810147e+08 | L22: 2.562575e+08 | M22: 2.6937807e+08 | N22: 0 | O22: 0
B23: NP - 2 | C23: VACANT | D23: 439764978 | E23: 467649702 | F23: 455379010 | G23: 4.1961196e+08 | H23: 4.1761855e+08 | I23: 428831462 | J23: 4.3643784e+08 | K23: 4.4140238e+08 | L23: 3.9955841e+08 | M23: 4.1267898e+08 | N23: 0 | O23: 0
B24: NP - 3 | C24: GEK MAS | D24: 403437384 | E24: 1016486951 | F24: 989815282 | G24: 1.0924855e+09 | H24: 1.0872956e+09 | I24: 1116489049 | J24: 1121489049 | K24: 1.1264536e+09 | L24: 1.0846096e+09 | M24: 1.0977302e+09 | N24: 0 | O24: 0
B25: NP - 4 | C25: VACANT | D25: 490272925 | E25: 0 | F25: 0 | G25: 0 | H25: 0 | I25: 0 | J25: 0 | K25: 0 | L25: 0 | M25: 0 | N25: 0 | O25: 0
B26: NP - 5 | C26: - | D26: 0 | E26: 0 | F26: 0 | G26: 0 | H26: 0 | I26: 0 | J26: 0 | K26: 0 | L26: 0 | M26: 0 | N26: 0 | O26: 0
B29: 💡 Sel berwarna KUNING dapat diubah untuk memperbarui target. Angka biru = input manual.

Sheet JAN
B1: DATA PENCAPAIAN — FEBRUARY 2026 | G1: ⚙️ KALENDER KERJA — INPUT MANUAL
G2: Total hari kalender bulan ini (auto) | J2: =E3 -> 31
B3: HARI TERSISA (auto): | C3: =IF($J$5<>"",$J$5,MAX(0,NETWORKDAYS.INTL(MAX(TODAY(),DATE(YEAR(TODAY()),1,1)),EOMONTH(DATE(YEAR(TODAY()),1,1),0),11)-MAX(0,$J$3-$J$4))) -> 0 | D3: Hari kerja tersisa bulan ini (Sab s/d akhir bulan) — otomatis | E3: =DAY(EOMONTH(DATE(YEAR(TODAY()),1,1),0)) -> 31 | G3: Total hari LIBUR / OFF bulan ini | J3: 0
G4: Libur yang SUDAH lewat | J4: 0
G5: Override HARI TERSISA (kosong = auto)
B6: 📥 INPUT DATA HARIAN — Paste dari file sistem di sini | P6: FOOD_ACHIV (calc) | Q6: BEV_ACHIV (calc)
B7: INPUT: DATA MKS (FOOD & BEVERAGES) | P7: =C9 -> 0 | Q7: =D9 -> 0
B8: Nama_Kry | C8: FOOD | D8: BEVERAGE | E8: Grand Total | P8: =C22 -> 0 | Q8: =D22 -> 0
P9: =C12+C13 -> 0 | Q9: =D12+D13 -> 0
B10: Dewi Kristiani | P10: =C14 -> 0 | Q10: =D14 -> 0
B11: Eka | P11: =C17 -> 0 | Q11: =D17 -> 0
B12: I MADE LUIH | P12: =C16 -> 0 | Q12: =D16 -> 0
B13: I Made Luih (Sanur) | P13: =C19 -> 0 | Q13: =D19 -> 0
B14: Juni | P14: =C23 -> 0 | Q14: =D23 -> 0
B15: KA | P15: =C11 -> 0 | Q15: =D11 -> 0
B16: LANI | P16: =C24 -> 0 | Q16: =D24 -> 0
B17: Lani P | P17: =C10 -> 0 | Q17: =D10 -> 0
B18: Management Bali | P18: =C25 -> 0 | Q18: =D25 -> 0
B19: Monica | P19: =C20+C21 -> 0 | Q19: =D20+D21 -> 0
B20: Ni Ketut Sriasih (GT) | P20: =IFERROR(C29,0)+IFERROR(C15,0)+IFERROR(C34,0) -> 0 | Q20: NP5_calc
B21: Ni Ketut Sriasih (MT) | P21: =IFERROR(C32,0)+IFERROR(C33,0)+P20 -> 0 | Q21: NP3_final
B22: Picrom Stalyon
B23: Sujana
B24: Taufik
B25: Wira
B27: INPUT: DATA NESTLE
B28: Nama Kry | C28: Total
B30: NP1
B31: NP2
B32: NP3
B33: NP4
B34: NP5
B39: DATA PENCAPAIAN — GLOBAL — APRIL 2026 | E39: TARGET | F39: 1
B40: KATAGORI | C40: AREA | D40: TARGET | E40: ACHIEVEMENT | F40: % | G40: SELISIH | H40: PER HARI
B41: FOOD | C41: HORECA, GT, MT | D41: =SUM(TARGETS!D5:D18) -> 7715107456 | E41: =P8+P9+P10+P11+P12+P13+P14+P15+P16+P17+P18+P19 -> 0 | F41: =IFERROR(E41/D41,0) -> 0 | G41: =D41-E41 -> 7715107456 | H41: =IFERROR(G41/C3,0) -> 0
B42: BEVERAGE | C42: HORECA, GT, MT | D42: =SUM(TARGETS!E5:E18) -> 1276773007 | E42: =Q8+Q9+Q10+Q11+Q12+Q13+Q14+Q15+Q16+Q17+Q18+Q19 -> 0 | F42: =IFERROR(E42/D42,0) -> 0 | G42: =D42-E42 -> 1276773007 | H42: =IFERROR(G42/C3,0) -> 0
B43: NESTLE | C43: HORECA, GT, MT | D43: =SUM(TARGETS!D22:D26) -> 1667021276 | E43: =IFERROR(C30,0)+IFERROR(C31,0)+P21+E9 -> 0 | F43: =IFERROR(E43/D43,0) -> 0 | G43: =D43-E43 -> 1667021276 | H43: =IFERROR(G43/C3,0) -> 0
B44: TOTAL | D44: =D41+D42+D43 -> 10658901739 | E44: =E41+E42+E43 -> 0 | F44: =IFERROR(E44/D44,0) -> 0 | G44: =G41+G42+G43 -> 10658901739 | H44: =IFERROR(G44/C3,0) -> 0
B46: FOOD & BEVERAGES
B47: AREA | C47: SALES | D47: TARGET | G47: ACHIEVEMENT | J47: % | K47: SELISIH (Target - Achiv) | N47: PER HARI (sisa hari)
...

Sheet FEB
B1: DATA PENCAPAIAN — FEBRUARY 2026 | G1: ⚙️ KALENDER KERJA — INPUT MANUAL
G2: Total hari kalender bulan ini (auto) | J2: =E3 -> 28
B3: HARI TERSISA (auto): | C3: =IF($J$5<>"",$J$5,MAX(0,NETWORKDAYS.INTL(MAX(TODAY(),DATE(YEAR(TODAY()),2,1)),EOMONTH(DATE(YEAR(TODAY()),2,1),0),11)-MAX(0,$J$3-$J$4))) -> 0 | D3: Hari kerja tersisa bulan ini (Sab s/d akhir bulan) — otomatis | E3: =DAY(EOMONTH(DATE(YEAR(TODAY()),2,1),0)) -> 28 | G3: Total hari LIBUR / OFF bulan ini | J3: 0
G4: Libur yang SUDAH lewat | J4: 0
G5: Override HARI TERSISA (kosong = auto)
B6: 📥 INPUT DATA HARIAN — Paste dari file sistem di sini | P6: FOOD_ACHIV (calc) | Q6: BEV_ACHIV (calc)
B7: INPUT: DATA MKS (FOOD & BEVERAGES) | P7: =C9 -> 0 | Q7: =D9 -> 0
B8: Nama_Kry | C8: FOOD | D8: BEVERAGE | E8: Grand Total | P8: =C22 -> 0 | Q8: =D22 -> 0
P9: =C12+C13 -> 0 | Q9: =D12+D13 -> 0
B10: Dewi Kristiani | P10: =C14 -> 0 | Q10: =D14 -> 0
B11: Eka | P11: =C17 -> 0 | Q11: =D17 -> 0
B12: I MADE LUIH | P12: =C16 -> 0 | Q12: =D16 -> 0
B13: I Made Luih (Sanur) | P13: =C19 -> 0 | Q13: =D19 -> 0
B14: Juni | P14: =C23 -> 0 | Q14: =D23 -> 0
B15: KA | P15: =C11 -> 0 | Q15: =D11 -> 0
B16: LANI | P16: =C24 -> 0 | Q16: =D24 -> 0
B17: Lani P | P17: =C10 -> 0 | Q17: =D10 -> 0
B18: Management Bali | P18: =C25 -> 0 | Q18: =D25 -> 0
B19: Monica | P19: =C20+C21 -> 0 | Q19: =D20+D21 -> 0
B20: Ni Ketut Sriasih (GT) | P20: =IFERROR(C29,0)+IFERROR(C15,0)+IFERROR(C34,0) -> 0 | Q20: NP5_calc
B21: Ni Ketut Sriasih (MT) | P21: =IFERROR(C32,0)+IFERROR(C33,0)+P20 -> 0 | Q21: NP3_final
B22: Picrom Stalyon
B23: Sujana
B24: Taufik
B25: Wira
B27: INPUT: DATA NESTLE
B28: Nama Kry | C28: Total
B30: NP1
B31: NP2
B32: NP3
B33: NP4
B34: NP5
B39: DATA PENCAPAIAN — GLOBAL — APRIL 2026 | E39: TARGET | F39: 1
B40: KATAGORI | C40: AREA | D40: TARGET | E40: ACHIEVEMENT | F40: % | G40: SELISIH | H40: PER HARI
B41: FOOD | C41: HORECA, GT, MT | D41: =SUM(TARGETS!G5:G18) -> 6785121897 | E41: =P8+P9+P10+P11+P12+P13+P14+P15+P16+P17+P18+P19 -> 0 | F41: =IFERROR(E41/D41,0) -> 0 | G41: =D41-E41 -> 6785121897 | H41: =IFERROR(G41/C3,0) -> 0
B42: BEVERAGE | C42: HORECA, GT, MT | D42: =SUM(TARGETS!H5:H18) -> 1174575386 | E42: =Q8+Q9+Q10+Q11+Q12+Q13+Q14+Q15+Q16+Q17+Q18+Q19 -> 0 | F42: =IFERROR(E42/D42,0) -> 0 | G42: =D42-E42 -> 1174575386 | H42: =IFERROR(G42/C3,0) -> 0
B43: NESTLE | C43: HORECA, GT, MT | D43: =SUM(TARGETS!E22:E26) -> 1816737288 | E43: =IFERROR(C30,0)+IFERROR(C31,0)+P21+E9 -> 0 | F43: =IFERROR(E43/D43,0) -> 0 | G43: =D43-E43 -> 1816737288 | H43: =IFERROR(G43/C3,0) -> 0
B44: TOTAL | D44: =D41+D42+D43 -> 9776434571 | E44: =E41+E42+E43 -> 0 | F44: =IFERROR(E44/D44,0) -> 0 | G44: =G41+G42+G43 -> 9776434571 | H44: =IFERROR(G44/C3,0) -> 0
B46: FOOD & BEVERAGES
B47: AREA | C47: SALES | D47: TARGET | G47: ACHIEVEMENT | J47: % | K47: SELISIH (Target - Achiv) | N47: PER HARI (sisa hari)
...

Sheet MAR
B1: DATA PENCAPAIAN — MARET 2026 | G1: ⚙️ KALENDER KERJA — INPUT MANUAL
G2: Total hari kalender bulan ini (auto) | J2: =E3 -> 31
B3: HARI TERSISA (auto): | C3: =IF($J$5<>"",$J$5,MAX(0,NETWORKDAYS.INTL(MAX(TODAY(),DATE(YEAR(TODAY()),3,1)),EOMONTH(DATE(YEAR(TODAY()),3,1),0),11)-MAX(0,$J$3-$J$4))) -> 0 | D3: Hari kerja tersisa bulan ini (Sab s/d akhir bulan) — otomatis | E3: =DAY(EOMONTH(DATE(YEAR(TODAY()),3,1),0)) -> 31 | G3: Total hari LIBUR / OFF bulan ini | J3: 0
G4: Libur yang SUDAH lewat | J4: 0
G5: Override HARI TERSISA (kosong = auto)
B6: 📥 INPUT DATA HARIAN — Paste dari file sistem di sini | P6: FOOD_ACHIV (calc) | Q6: BEV_ACHIV (calc)
B7: INPUT: DATA MKS (FOOD & BEVERAGES) | P7: =C9 -> 188107.92 | Q7: =D9 -> 0
B8: Nama_Kry | C8: FOOD | D8: BEVERAGE | E8: Grand Total | P8: =C22 -> 2.5616173e+08 | Q8: =D22 -> 33244870
B9: ANGELIA | C9: 188107.92 | D9: 0 | E9: 188107.92 | P9: =C12+C13 -> 4.009844e+08 | Q9: =D12+D13 -> 97493652
B10: Dewi Kristiani | C10: 2.4179305e+08 | D10: 27052169 | E10: 2.6884521e+08 | P10: =C14 -> 4.4895174e+08 | Q10: =D14 -> 25395525
B11: Eka | C11: 2.7524889e+08 | D11: 67651089 | E11: 3.4289998e+08 | P11: =C17 -> 2.7357432e+08 | Q11: =D17 -> 65561081
B12: I MADE LUIH | C12: 1.8366472e+08 | D12: 65497608 | E12: 2.4916233e+08 | P12: =C16 -> 3.4153385e+08 | Q12: =D16 -> 55146187
B13: I Made Luih (Sanur) | C13: 2.1731968e+08 | D13: 31996044 | E13: 2.4931573e+08 | P13: =C19 -> 7.2499612e+08 | Q13: =D19 -> 66333666
B14: Juni | C14: 4.4895174e+08 | D14: 25395525 | E14: 4.7434727e+08 | P14: =C23 -> 4.7402635e+08 | Q14: =D23 -> 42452264
B15: KA | C15: 282161.88 | E15: 282161.88 | P15: =C11 -> 2.7524889e+08 | Q15: =D11 -> 67651089
B16: LANI | C16: 3.4153385e+08 | D16: 55146187 | E16: 3.9668003e+08 | P16: =C24 -> 3.9123193e+08 | Q16: =D24 -> 47651173
B17: Lani P | C17: 2.7357432e+08 | D17: 65561081 | E17: 3.391354e+08 | P17: =C10 -> 2.4179305e+08 | Q17: =D10 -> 27052169
B18: Management Bali | C18: 1.4545809e+09 | D18: 24019256 | E18: 1.4786001e+09 | P18: =C25 -> 5.5177326e+08 | Q18: =D25 -> 1.7603189e+08
B19: Monica | C19: 7.2499612e+08 | D19: 66333666 | E19: 7.9132978e+08 | P19: =C20+C21 -> 1.8568238e+08 | Q19: =D20+D21 -> 1.4648446e+08
B20: Ni Ketut Sriasih (GT) | C20: 1.4318064e+08 | D20: 24973221 | E20: 1.6815386e+08 | P20: =IFERROR(C29,0)+IFERROR(C15,0)+IFERROR(C34,0) -> 11690499 | Q20: NP5_calc
B21: Ni Ketut Sriasih (MT) | C21: 42501732 | D21: 1.2151124e+08 | E21: 1.6401297e+08 | P21: =IFERROR(C32,0)+IFERROR(C33,0)+P20 -> 6.873782e+08 | Q21: NP3_final
B22: Picrom Stalyon | C22: 2.5616173e+08 | D22: 33244870 | E22: 2.894066e+08
B23: Sujana | C23: 4.7402635e+08 | D23: 42452264 | E23: 5.1647861e+08
B24: Taufik | C24: 3.9123193e+08 | D24: 47651173 | E24: 4.3888311e+08
B25: Wira | C25: 5.5177326e+08 | D25: 1.7603189e+08 | E25: 7.2780515e+08
B27: INPUT: DATA NESTLE
B28: Nama Kry | C28: Total
C29: 3087270.3
B30: NP1 | C30: 1.7421393e+08
B31: NP2 | C31: 3.0977874e+08
B32: NP3 | C32: 2.7639741e+08
B33: NP4 | C33: 3.992903e+08
B34: NP5 | C34: 8321067.2
B39: DATA PENCAPAIAN — GLOBAL — MARET 2026 | E39: TARGET | F39: 1
B40: KATAGORI | C40: AREA | D40: TARGET | E40: ACHIEVEMENT | G40: SELISIH | H40: PER HARI
B41: FOOD | C41: HORECA, GT, MT | D41: =SUM(TARGETS!J5:J18) -> 6726156407 | E41: =P8+P9+P10+P11+P12+P13+P14+P15+P16+P17+P18+P19 -> 4.565958e+09 | F41: =IFERROR(E41/D41,0) -> 0.67883613 | G41: =D41-E41 -> 2.1601984e+09 | H41: =IFERROR(G41/C3,0) -> 0
B42: BEVERAGE | C42: HORECA, GT, MT | D42: =SUM(TARGETS!K5:K18) -> 1269766212 | E42: =Q7+Q8+Q9+Q10+Q11+Q12+Q13+Q14+Q15+Q16+Q17+Q18+Q19 -> 8.5049803e+08 | F42: =IFERROR(E42/D42,0) -> 0.66980679 | G42: =D42-E42 -> 4.1926819e+08 | H42: =IFERROR(G42/C3,0) -> 0
B43: NESTLE | C43: HORECA, GT, MT | D43: =SUM(TARGETS!F22:F26) -> 1769067797 | E43: =IFERROR(C30,0)+IFERROR(C31,0)+P21+E9 -> 1.171559e+09 | F43: =IFERROR(E43/D43,0) -> 0.66224651 | G43: =D43-E43 -> 5.9750882e+08 | H43: =IFERROR(G43/C3,0) -> 0
B44: TOTAL | D44: =D41+D42+D43 -> 9764990416 | E44: =E41+E42+E43 -> 6.588015e+09 | F44: =IFERROR(E44/D44,0) -> 0.67465658 | G44: =G41+G42+G43 -> 3.1769754e+09 | H44: =IFERROR(G44/C3,0) -> 0
B46: FOOD & BEVERAGES
...

Sheet APR
B1: DATA PENCAPAIAN — APRIL 2026 | G1: ⚙️ KALENDER KERJA — INPUT MANUAL
G2: Total hari kalender bulan ini (auto) | J2: =E3 -> 30
B3: HARI TERSISA (auto): | C3: =IF($J$5<>"",$J$5,MAX(0,NETWORKDAYS.INTL(MAX(TODAY(),DATE(YEAR(TODAY()),4,1)),EOMONTH(DATE(YEAR(TODAY()),4,1),0),11)-MAX(0,$J$3-$J$4))) -> 0 | D3: Hari kerja tersisa bulan ini (Sab s/d akhir bulan) — otomatis | E3: =DAY(EOMONTH(DATE(YEAR(TODAY()),4,1),0)) -> 30 | G3: Total hari LIBUR / OFF bulan ini | J3: 0
G4: Libur yang SUDAH lewat | J4: 0
G5: Override HARI TERSISA (kosong = auto)
B6: 📥 INPUT DATA HARIAN — Paste dari file sistem di sini | M6: FOOD_ACHIV (calc) | N6: BEV_ACHIV (calc)
B7: INPUT: DATA MKS (FOOD & BEVERAGES) | M7: =C9 -> 0 | N7: =D9 -> 0
B8: Nama_Kry | C8: FOOD | D8: BEVERAGE | E8: Balian | F8: Grand Total | M8: =C24 -> 2.9977057e+08 | N8: =D24 -> 45375105
C9: 0 | D9: 0 | E9: 0 | M9: =C12+C13 -> 4.9166979e+08 | N9: =D12+D13 -> 1.2024821e+08
B10: Dewi Kristiani | C10: 3.0343956e+08 | D10: 28364315 | E10: 61031206 | F10: 3.9283508e+08 | M10: =C14 -> 5.3799728e+08 | N10: =D14 -> 21205741
B11: Eka | C11: 3.0413774e+08 | D11: 1.1970715e+08 | E11: 34053355 | F11: 4.5789825e+08 | M11: =C17 -> 3.5562612e+08 | N11: =D17 -> 44657676
B12: I MADE LUIH | C12: 2.5527224e+08 | D12: 80101515 | E12: 71143242 | F12: 4.06517e+08 | M12: =C16 -> 4.4968261e+08 | N12: =D16 -> 60505589
B13: I Made Luih (Sanur) | C13: 2.3639755e+08 | D13: 40146697 | E13: 10759099 | F13: 2.8730334e+08 | M13: =C19 -> 1.0309154e+09 | N13: =D19 -> 59498536
B14: Juni | C14: 5.3799728e+08 | D14: 21205741 | E14: 66130324 | F14: 6.2533334e+08 | M14: =C25 -> 3.7875454e+08 | N14: =D25 -> 62284985
B15: KA | M15: =C11 -> 3.0413774e+08 | N15: =D11 -> 1.1970715e+08
B16: LANI | C16: 4.4968261e+08 | D16: 60505589 | E16: 2883783.8 | F16: 5.1307199e+08 | M16: =C26 -> 4.7929173e+08 | N16: =D26 -> 61629600
B17: Lani P | C17: 3.5562612e+08 | D17: 44657676 | F17: 4.002838e+08 | M17: =C10 -> 3.0343956e+08 | N17: =D10 -> 28364315
B18: Management Bali | C18: 1.2675771e+09 | D18: 9652531.9 | E18: 3932432.4 | F18: 1.281162e+09 | M18: =C27 -> 6.6355982e+08 | N18: =D27 -> 2.0025323e+08
B19: Monica | C19: 1.0309154e+09 | D19: 59498536 | E19: 2.8720362e+08 | F19: 1.3776175e+09 | M19: =C20+C21 -> 1.62675e+08 | N19: =D20+D21 -> 1.5270811e+08
B20: Ni Ketut Sriasih (GT) | C20: 1.0531506e+08 | D20: 16467728 | F20: 1.2178279e+08 | M20: =IFERROR(C31,0)+IFERROR(C15,0)+IFERROR(C36,0) -> 3.1129081e+08 | N20: NP5_calc
B21: Ni Ketut Sriasih (MT) | C21: 57359939 | D21: 1.3624038e+08 | F21: 1.9360032e+08 | M21: =IFERROR(C34,0)+IFERROR(C35,0)+M20 -> 8.9713048e+08 | N21: NP3_final
B22: NN Made Luih | C22: 38884329 | E22: 12315315 | F22: 51199644
B23: NN Sujana | C23: 1.2055049e+08 | E23: 17151621 | F23: 1.3770211e+08
B24: Picrom Stalyon | C24: 2.9977057e+08 | D24: 45375105 | E24: 24325369 | F24: 3.6947104e+08
B25: Sujana | C25: 3.7875454e+08 | D25: 62284985 | E25: 26407801 | F25: 4.6744732e+08
B26: Taufik | C26: 4.7929173e+08 | D26: 61629600 | E26: 1.1273604e+08 | F26: 6.5365737e+08
B27: Wira | C27: 6.6355982e+08 | D27: 2.0025323e+08 | F27: 8.6381306e+08
B29: INPUT: DATA NESTLE
B30: Nama Kry | C30: Total
B32: NP1 | C32: 2.402376e+08
B33: NP2 | C33: 4.4993374e+08
B34: NP3 | C34: 3.1827859e+08
B35: NP4 | C35: 2.6756109e+08
B36: NP5 | C36: 3.1129081e+08
S40: PILIHAN % TARGET
B41: DATA PENCAPAIAN — GLOBAL — 30 APRIL 2026 | E41: TARGET | F41: 1 | G41: PILIH TARGET % | H41: 0.9 | I41: PILIH TARGET % | J41: 0.95 | K41: PENUH | L41: 1 | S41: 0.7
B42: KATAGORI | C42: AREA | D42: TARGET | E42: ACHIEVEMENT | F42: % | G42: ="SELISIH"&CHAR(10)&TEXT($H$41,"0%") -> SELISIH 90% | H42: ="PER HARI"&CHAR(10)&TEXT($H$41,"0%") -> PER HARI 90% | I42: ="SELISIH"&CHAR(10)&TEXT($J$41,"0%") -> SELISIH 95% | J42: ="PER HARI"&CHAR(10)&TEXT($J$41,"0%") -> PER HARI 95% | K42: ="SELISIH"&CHAR(10)&TEXT($L$41,"0%") -> SELISIH 100% | L42: ="PER HARI"&CHAR(10)&TEXT($L$41,"0%") -> PER HARI 100% | S42: 0.75
B43: FOOD | C43: HORECA, GT, MT | D43: =SUM(TARGETS!M5:M7,TARGETS!M8:M13,TARGETS!M14:M18) -> 6.6192793e+09 | E43: =G65 -> 5.6169549e+09 | F43: =IFERROR(E43/D43,0) -> 0.848575 | G43: =D43*$H$41-E43 -> 3.4039645e+08 | H43: =IFERROR(G43/$C$3,0) -> 0 | I43: =D43*$J$41-E43 -> 6.7136042e+08 | J43: =IFERROR(I43/$C$3,0) -> 0 | K43: =D43*$L$41-E43 -> 1.0023244e+09 | L43: =IFERROR(K43/$C$3,0) -> 0 | S43: 0.8
B44: BEVERAGE | C44: HORECA, GT, MT | D44: =SUM(TARGETS!N5:N6,TARGETS!N8:N12,TARGETS!N14:N18) -> 1269766212 | E44: =N8+N9+N10+N11+N12+N13+N14+N15+N16+N17+N18+N19 -> 9.7643825e+08 | F44: =IFERROR(E44/D44,0) -> 0.76899058 | G44: =D44*$H$41-E44 -> 1.6635134e+08 | H44: =IFERROR(G44/$C$3,0) -> 0 | I44: =D44*$J$41-E44 -> 2.2983965e+08 | J44: =IFERROR(I44/$C$3,0) -> 0 | K44: =D44*$L$41-E44 -> 2.9332796e+08 | L44: =IFERROR(K44/$C$3,0) -> 0 | S44: 0.85
B45: NESTLE | C45: HORECA, GT, MT | D45: =SUM(TARGETS!G22:G26) -> 1.7914894e+09 | E45: =IFERROR(C32,0)+IFERROR(C33,0)+M21+F9 -> 1.5873018e+09 | F45: =IFERROR(E45/D45,0) -> 0.88602358 | G45: =D45*$H$41-E45 -> 25038600 | H45: =IFERROR(G45/$C$3,0) -> 0 | I45: =D45*$J$41-E45 -> 1.1461307e+08 | J45: =IFERROR(I45/$C$3,0) -> 0 | K45: =D45*$L$41-E45 -> 2.0418754e+08 | L45: =IFERROR(K45/$C$3,0) -> 0 | S45: 0.9
...

Sheet MEI
B1: DATA PENCAPAIAN — MEI 2026 | G1: ⚙️ KALENDER KERJA — INPUT MANUAL
G2: Total hari kalender bulan ini (auto) | J2: =E3 -> 31
B3: HARI TERSISA (auto): | C3: =IF($J$5<>"",$J$5,MAX(0,NETWORKDAYS.INTL(MAX(TODAY(),DATE(YEAR(TODAY()),5,1)),EOMONTH(DATE(YEAR(TODAY()),5,1),0),11)-MAX(0,$J$3-$J$4))) -> 0 | D3: Hari kerja tersisa bulan ini (Sab s/d akhir bulan) — otomatis | E3: =DAY(EOMONTH(DATE(YEAR(TODAY()),5,1),0)) -> 31 | G3: Total hari LIBUR / OFF bulan ini | J3: 0
G4: Libur yang SUDAH lewat | J4: 0
G5: Override HARI TERSISA (kosong = auto)
B6: 📥 INPUT DATA HARIAN — Paste dari file sistem di sini | M6: FOOD_ACHIV (calc) | N6: BEV_ACHIV (calc)
B7: INPUT: DATA MKS (FOOD & BEVERAGES) | M7: =C9 -> 0 | N7: =D9 -> 0
B8: Nama_Kry | C8: FOOD | D8: BEVERAGE | E8: Balian | F8: Grand Total | M8: =C24 -> 2.8842402e+08 | N8: =D24 -> 44585739
C9: 0 | D9: 0 | M9: =C12+C13 -> 5.1487341e+08 | N9: =D12+D13 -> 95906107
B10: Dewi Kristiani | C10: 2.9788218e+08 | D10: 34050666 | E10: 1.6278861e+08 | F10: 4.9472146e+08 | M10: =C14 -> 6.7066436e+08 | N10: =D14 -> 27278644
B11: Eka | C11: 3.7446681e+08 | D11: 92402941 | E11: 40868469 | F11: 5.0773822e+08 | M11: =C17 -> 3.143507e+08 | N11: =D17 -> 42787524
B12: I MADE LUIH | C12: 2.7822768e+08 | D12: 62709000 | E12: 52162026 | F12: 3.930987e+08 | M12: =C16 -> 4.1301347e+08 | N12: =D16 -> 61457253
B13: I Made Luih (Sanur) | C13: 2.3664573e+08 | D13: 33197108 | E13: 41510945 | F13: 3.1135379e+08 | M13: =C19 -> 1.0056133e+09 | N13: =D19 -> 73190755
B14: Juni | C14: 6.7066436e+08 | D14: 27278644 | E14: 2.6032432e+08 | F14: 9.5826733e+08 | M14: =C25 -> 3.8987578e+08 | N14: =D25 -> 68378258
B15: KA | M15: =C11 -> 3.7446681e+08 | N15: =D11 -> 92402941
B16: LANI | C16: 4.1301347e+08 | D16: 61457253 | E16: 14439640 | F16: 4.8891036e+08 | M16: =C26 -> 4.5424998e+08 | N16: =D26 -> 58885063
B17: Lani P | C17: 3.143507e+08 | D17: 42787524 | F17: 3.5713822e+08 | M17: =C10 -> 2.9788218e+08 | N17: =D10 -> 34050666
B18: Management Bali | C18: 9.769404e+08 | D18: 11562281 | E18: 11405405 | F18: 9.9990809e+08 | M18: =C27 -> 6.8664525e+08 | N18: =D27 -> 1.9190695e+08
B19: Monica | C19: 1.0056133e+09 | D19: 73190755 | E19: 7.0923797e+08 | F19: 1.788042e+09 | M19: =C20+C21 -> 2.9833662e+08 | N19: =D20+D21 -> 1.2884759e+08
B20: Ni Ketut Sriasih (GT) | C20: 2.3428153e+08 | D20: 28741886 | E20: 3816216.3 | F20: 2.6683963e+08 | M20: =IFERROR(C31,0)+IFERROR(C15,0)+IFERROR(C36,0) -> 296173392 | N20: NP5_calc
B21: Ni Ketut Sriasih (MT) | C21: 64055094 | D21: 1.0010571e+08 | E21: 79070272 | F21: 2.4323107e+08 | M21: =IFERROR(C34,0)+IFERROR(C35,0)+M20 -> 9.4563058e+08 | N21: NP3_final
B22: NN Made Luih | C22: 1.9756785e+08 | E22: 12832432 | F22: 2.1040028e+08
B23: NN Sujana | C23: 3.0052152e+08 | E23: 13813693 | F23: 3.1433522e+08
B24: Picrom Stalyon | C24: 2.8842402e+08 | D24: 44585739 | E24: 1.2621429e+08 | F24: 4.5922404e+08
B25: Sujana | C25: 3.8987578e+08 | D25: 68378258 | E25: 2.4797676e+08 | F25: 7.0623079e+08
B26: Taufik | C26: 4.5424998e+08 | D26: 58885063 | E26: 4.6910396e+08 | F26: 9.82239e+08
B27: Wira | C27: 6.8664525e+08 | D27: 1.9190695e+08 | E27: 19182703 | F27: 8.9773491e+08
B29: INPUT: DATA NESTLE
B30: Nama Kry | C30: Total
B32: NP1 | C32: 2.914276e+08
B33: NP2 | C33: 4.3614804e+08
B34: NP3 | C34: 1.3562804e+08
B35: NP4 | C35: 5.1382915e+08
B36: NP5 | C36: 296173392
S40: PILIHAN % TARGET
B41: DATA PENCAPAIAN — GLOBAL — 30 MEI 2026 | E41: TARGET | F41: 0.97 | G41: PILIH TARGET % | H41: 0.9 | I41: PILIH TARGET % | J41: 0.95 | K41: PENUH | L41: 1 | S41: 0.7
B42: KATAGORI | C42: AREA | D42: TARGET | E42: ACHIEVEMENT | F42: % | G42: ="SELISIH"&CHAR(10)&TEXT($H$41,"0%") -> SELISIH 90% | H42: ="PER HARI"&CHAR(10)&TEXT($H$41,"0%") -> PER HARI 90% | I42: ="SELISIH"&CHAR(10)&TEXT($J$41,"0%") -> SELISIH 95% | J42: ="PER HARI"&CHAR(10)&TEXT($J$41,"0%") -> PER HARI 95% | K42: ="SELISIH"&CHAR(10)&TEXT($L$41,"0%") -> SELISIH 100% | L42: ="PER HARI"&CHAR(10)&TEXT($L$41,"0%") -> PER HARI 100% | S42: 0.75
B43: FOOD | C43: HORECA, GT, MT | D43: =SUM(TARGETS!P5:P7,TARGETS!P8:P13,TARGETS!P14:P18) -> 6839279332 | E43: =G65 -> 6.2064853e+09 | F43: =IFERROR(E43/D43,0) -> 0.9074765 | G43: =D43*$H$41-E43 -> -51133853 | H43: =IFERROR(G43/$C$3,0) -> 0 | I43: =D43*$J$41-E43 -> 2.9083011e+08 | J43: =IFERROR(I43/$C$3,0) -> 0 | K43: =D43*$L$41-E43 -> 6.3279408e+08 | L43: =IFERROR(K43/$C$3,0) -> 0 | S43: 0.8
B44: BEVERAGE | C44: HORECA, GT, MT | D44: =SUM(TARGETS!Q5:Q6,TARGETS!Q8:Q12,TARGETS!Q14:Q18) -> 1.4752648e+09 | E44: =N8+N9+N10+N11+N12+N13+N14+N15+N16+N17+N18+N19 -> 9.1967749e+08 | F44: =IFERROR(E44/D44,0) -> 0.62339824 | G44: =D44*$H$41-E44 -> 4.0806085e+08 | H44: =IFERROR(G44/$C$3,0) -> 0 | I44: =D44*$J$41-E44 -> 4.8182409e+08 | J44: =IFERROR(I44/$C$3,0) -> 0 | K44: =D44*$L$41-E44 -> 5.5558733e+08 | L44: =IFERROR(K44/$C$3,0) -> 0 | S44: 0.85
B45: NESTLE | C45: HORECA, GT, MT | D45: =SUM(TARGETS!H22:H26) -> 1.7829787e+09 | E45: =IFERROR(C32,0)+IFERROR(C33,0)+M21+F9 -> 1.6732062e+09 | F45: =IFERROR(E45/D45,0) -> 0.93843308 | G45: =D45*$H$41-E45 -> -68525358 | H45: =IFERROR(G45/$C$3,0) -> 0 | I45: =D45*$J$41-E45 -> 20623579 | J45: =IFERROR(I45/$C$3,0) -> 0 | K45: =D45*$L$41-E45 -> 1.0977251e+08 | L45: =IFERROR(K45/$C$3,0) -> 0 | S45: 0.9
...

Sheet JUN
B1: DATA PENCAPAIAN — JUNI 2026 | G1: ⚙️ KALENDER KERJA — INPUT MANUAL
G2: Total hari kalender bulan ini (auto) | J2: =E3 -> 30
B3: HARI TERSISA (auto): | C3: =IF($J$5<>"",$J$5,MAX(0,NETWORKDAYS.INTL(MAX(TODAY(),DATE(YEAR(TODAY()),6,1)),EOMONTH(DATE(YEAR(TODAY()),6,1),0),11)-MAX(0,$J$3-$J$4))) -> 0 | D3: Hari kerja tersisa bulan ini (Sab s/d akhir bulan) — otomatis | E3: =DAY(EOMONTH(DATE(YEAR(TODAY()),6,1),0)) -> 30 | G3: Total hari LIBUR / OFF bulan ini | J3: 0
G4: Libur yang SUDAH lewat | J4: 0
G5: Override HARI TERSISA (kosong = auto)
B6: 📥 INPUT DATA HARIAN — Paste dari file sistem di sini | M6: FOOD_ACHIV (calc) | N6: BEV_ACHIV (calc)
B7: INPUT: DATA MKS (FOOD & BEVERAGES) | M7: =C9 -> 0 | N7: =D9 -> 0
B8: Nama_Kry | C8: FOOD | D8: BEVERAGE | E8: Balian | F8: Grand Total | M8: =C24 -> 3.2057529e+08 | N8: =D24 -> 55052088
C9: 0 | D9: 0 | M9: =C12+C13 -> 5.4877295e+08 | N9: =D12+D13 -> 1.3073749e+08
B10: Dewi Kristiani | C10: 3.2228085e+08 | D10: 34873342 | E10: 1.5816224e+08 | F10: 5.1531643e+08 | M10: =C14 -> 9.8945648e+08 | N10: =D14 -> 37132037
B11: Eka | C11: 3.5080024e+08 | D11: 84864795 | E11: 22719654 | F11: 4.5838469e+08 | M11: =C17 -> 3.6816377e+08 | N11: =D17 -> 50693885
B12: I MADE LUIH | C12: 3.0717207e+08 | D12: 78765433 | E12: 52572805 | F12: 4.3851031e+08 | M12: =C16 -> 5.1702851e+08 | N12: =D16 -> 88679408
B13: I Made Luih (Sanur) | C13: 2.4160087e+08 | D13: 51972058 | E13: 36793626 | F13: 3.3036656e+08 | M13: =C19 -> 1.0027561e+09 | N13: =D19 -> 72945098
B14: Juni | C14: 9.8945648e+08 | D14: 37132037 | E14: 2.6658798e+08 | F14: 1.2931765e+09 | M14: =C25 -> 4.6184929e+08 | N14: =D25 -> 75489696
B15: KA | M15: =C11 -> 3.5080024e+08 | N15: =D11 -> 84864795
B16: LANI | C16: 5.1702851e+08 | D16: 88679408 | E16: 34044892 | F16: 6.3975281e+08 | M16: =C26 -> 5.0873588e+08 | N16: =D26 -> 51169801
B17: Lani P | C17: 3.6816377e+08 | D17: 50693885 | F17: 4.1885765e+08 | M17: =C10 -> 3.2228085e+08 | N17: =D10 -> 34873342
B18: Management Bali | C18: 5.1198777e+08 | D18: 7135512 | E18: 11708703 | F18: 5.3083199e+08 | M18: =C27 -> 7.89358e+08 | N18: =D27 -> 2.352123e+08
B19: Monica | C19: 1.0027561e+09 | D19: 72945098 | E19: 1.3298588e+09 | F19: 2.40556e+09 | M19: =C20+C21 -> 1.8636765e+08 | N19: =D20+D21 -> 1.5255207e+08
B20: Ni Ketut Sriasih (GT) | C20: 1.272007e+08 | D20: 22547773 | E20: 10497297 | F20: 1.6024577e+08 | M20: =IFERROR(C31,0)+IFERROR(C15,0)+IFERROR(C36,0) -> 3.0964525e+08 | N20: NP5_calc
B21: Ni Ketut Sriasih (MT) | C21: 59166950 | D21: 1.300043e+08 | E21: 89578380 | F21: 2.7874963e+08 | M21: =IFERROR(C34,0)+IFERROR(C35,0)+M20 -> 1.2085899e+09 | N21: NP3_final
B22: NN Made Luih | C22: 1.6767184e+08 | E22: 12540540 | F22: 1.8021238e+08
B23: NN Sujana | C23: 3.8893768e+08 | E23: 17519369 | F23: 4.0645705e+08
B24: Picrom Stalyon | C24: 3.2057529e+08 | D24: 55052088 | E24: 3.7932902e+08 | F24: 7.549564e+08
B25: Sujana | C25: 4.6184929e+08 | D25: 75489696 | E25: 3.1481229e+08 | F25: 8.5215127e+08
B26: Taufik | C26: 5.0873588e+08 | D26: 51169801 | E26: 5.8102825e+08 | F26: 1.1409339e+09
B27: Wira | C27: 7.89358e+08 | D27: 2.352123e+08 | E27: 17184217 | F27: 1.0417545e+09
B29: INPUT: DATA NESTLE
B30: Nama Kry | C30: Total
B32: NP1 | C32: 1.8527253e+08
B33: NP2 | C33: 3.3487168e+08
B34: NP3 | C34: 1.6425311e+08
B35: NP4 | C35: 7.3469155e+08
B36: NP5 | C36: 3.0964525e+08
S40: PILIHAN % TARGET
B41: DATA PENCAPAIAN — GLOBAL — 30 JUNI 2026 | E41: TARGET | F41: =IF(MONTH(TODAY())=6,DAY(TODAY())/DAY(EOMONTH(TODAY(),0)),IF(MONTH(TODAY())>6,1,0)) -> 1 | G41: PILIH TARGET % | H41: 0.9 | I41: PILIH TARGET % | J41: 0.95 | K41: PENUH | L41: 1 | S41: 0.7
B42: KATAGORI | C42: AREA | D42: TARGET | E42: ACHIEVEMENT | F42: % | G42: ="SELISIH"&CHAR(10)&TEXT($H$41,"0%") -> SELISIH 90% | H42: ="PER HARI"&CHAR(10)&TEXT($H$41,"0%") -> PER HARI 90% | I42: ="SELISIH"&CHAR(10)&TEXT($J$41,"0%") -> SELISIH 95% | J42: ="PER HARI"&CHAR(10)&TEXT($J$41,"0%") -> PER HARI 95% | K42: ="SELISIH"&CHAR(10)&TEXT($L$41,"0%") -> SELISIH 100% | L42: ="PER HARI"&CHAR(10)&TEXT($L$41,"0%") -> PER HARI 100% | S42: 0.75
B43: FOOD | C43: HORECA, GT, MT | D43: =SUM(TARGETS!S5:S7,TARGETS!S8:S13,TARGETS!S14:S18) -> 7259279332 | E43: =G65 -> 6.9227545e+09 | F43: =IFERROR(E43/D43,0) -> 0.95364212 | G43: =D43*$H$41-E43 -> -3.894031e+08 | H43: =IFERROR(G43/$C$3,0) -> 0 | I43: =D43*$J$41-E43 -> -26439134 | J43: =IFERROR(I43/$C$3,0) -> 0 | K43: =D43*$L$41-E43 -> 3.3652483e+08 | L43: =IFERROR(K43/$C$3,0) -> 0 | S43: 0.8
B44: BEVERAGE | C44: HORECA, GT, MT | D44: =SUM(TARGETS!T5:T6,TARGETS!T8:T12,TARGETS!T14:T18) -> 1809425059 | E44: =N8+N9+N10+N11+N12+N13+N14+N15+N16+N17+N18+N19 -> 1.069402e+09 | F44: =IFERROR(E44/D44,0) -> 0.59101758 | G44: =D44*$H$41-E44 -> 5.5908054e+08 | H44: =IFERROR(G44/$C$3,0) -> 0 | I44: =D44*$J$41-E44 -> 6.4955179e+08 | J44: =IFERROR(I44/$C$3,0) -> 0 | K44: =D44*$L$41-E44 -> 7.4002305e+08 | L44: =IFERROR(K44/$C$3,0) -> 0 | S44: 0.85
B45: NESTLE | C45: HORECA, GT, MT | D45: =SUM(TARGETS!I22:I26) -> 1830851064 | E45: =IFERROR(C32,0)+IFERROR(C33,0)+M21+F9 -> 1.7287341e+09 | F45: =IFERROR(E45/D45,0) -> 0.94422433 | G45: =D45*$H$41-E45 -> -80968167 | H45: =IFERROR(G45/$C$3,0) -> 0 | I45: =D45*$J$41-E45 -> 10574387 | J45: =IFERROR(I45/$C$3,0) -> 0 | K45: =D45*$L$41-E45 -> 1.0211694e+08 | L45: =IFERROR(K45/$C$3,0) -> 0 | S45: 0.9
...

Sheet JUL
B1: DATA PENCAPAIAN — JULI 2026 | G1: ⚙️ KALENDER KERJA — INPUT MANUAL
G2: Total hari kalender bulan ini (auto) | J2: =E3 -> 31
B3: HARI TERSISA (auto): | C3: =IF($J$5<>"",$J$5,MAX(0,NETWORKDAYS.INTL(MAX(TODAY(),DATE(YEAR(TODAY()),7,1)),EOMONTH(DATE(YEAR(TODAY()),7,1),0),11)-MAX(0,$J$3-$J$4))) -> 0 | D3: Hari kerja tersisa bulan ini (Sab s/d akhir bulan) — otomatis | E3: =DAY(EOMONTH(DATE(YEAR(TODAY()),7,1),0)) -> 31 | G3: Total hari LIBUR / OFF bulan ini | J3: 0
G4: Libur yang SUDAH lewat | J4: 0
G5: Override HARI TERSISA (kosong = auto)
B6: 📥 INPUT DATA HARIAN — Paste dari file sistem di sini | M6: FOOD_ACHIV (calc) | N6: BEV_ACHIV (calc)
B7: INPUT: DATA MKS (FOOD & BEVERAGES) | M7: =C9 -> 0 | N7: =D9 -> 0
B8: Nama_Kry | C8: FOOD | D8: BEVERAGE | E8: Balian | F8: Grand Total | M8: =C22 -> 4.485104e+08 | N8: =D22 -> 63011769
C9: 0 | D9: 0 | M9: =C13+C14 -> 6.4575804e+08 | N9: =D13+D14 -> 1.5511396e+08
B10: Dewi Kristiani | C10: 3.9361727e+08 | D10: 52106886 | E10: 1.7862609e+08 | F10: 6.2435024e+08 | M10: =C15 -> 1.0546719e+09 | N10: =D15 -> 29495979
B11: Eka | C11: 3.2468822e+08 | D11: 1.3096968e+08 | E11: 1.2348507e+08 | F11: 5.7914297e+08 | M11: =C12 -> 3.4181982e+08 | N11: =D12 -> 43800016
B12: FIB | C12: 3.4181982e+08 | D12: 43800016 | F12: 3.8561984e+08 | M12: =C25+C26 -> 4.0540108e+08 | N12: =D25+D26 -> 1.1078907e+08
B13: I MADE LUIH | C13: 3.3578326e+08 | D13: 1.1624017e+08 | E13: 62660260 | F13: 5.1468369e+08 | M13: =C17 -> 1.4250263e+09 | N13: =D17 -> 87442239
B14: I Made Luih (Sanur) | C14: 3.0997478e+08 | D14: 38873784 | E14: 61782486 | F14: 4.1063105e+08 | M14: =C23 -> 5.3762496e+08 | N14: =D23 -> 72473353
B15: Juni | C15: 1.0546719e+09 | D15: 29495979 | E15: 4.1021826e+08 | F15: 1.4943861e+09 | M15: =C11 -> 3.2468822e+08 | N15: =D11 -> 1.3096968e+08
B16: Management Bali | C16: 1.5544164e+09 | D16: 10384914 | E16: 8032432.4 | F16: 1.5728338e+09 | M16: =C24 -> 6.8718224e+08 | N16: =D24 -> 61286832
B17: Monica | C17: 1.4250263e+09 | D17: 87442239 | E17: 1.305013e+09 | F17: 2.8174815e+09 | M17: =C10 -> 3.9361727e+08 | N17: =D10 -> 52106886
B18: Ni Ketut Sriasih (GT) | C18: 2.6911917e+08 | D18: 21889933 | E18: 7372973.1 | F18: 2.9838207e+08 | M18: =C27 -> 8.8712302e+08 | N18: =D27 -> 2.6778137e+08
B19: Ni Ketut Sriasih (MT) | C19: 72833050 | D19: 1.2896659e+08 | E19: 85016218 | F19: 2.8681586e+08 | M19: =C18+C19 -> 3.4195222e+08 | N19: =D18+D19 -> 1.5085653e+08
B20: NN Made Luih | C20: 1.954762e+08 | E20: 11387387 | F20: 2.0686359e+08 | M20: =IFERROR(C31,0)+IFERROR(C36,0) -> 31764000 | N20: NP5_calc
B21: NN Sujana | C21: 2.8852489e+08 | E21: 15855585 | F21: 3.0438047e+08 | M21: =IFERROR(C34,0)+IFERROR(C35,0)+M20 -> 6.7036265e+08 | N21: NP3_final
B22: Picrom Stalyon | C22: 4.485104e+08 | D22: 63011769 | E22: 5.0369866e+08 | F22: 1.0152208e+09
B23: Sujana | C23: 5.3762496e+08 | D23: 72473353 | E23: 3.1095847e+08 | F23: 9.2105678e+08
B24: Taufik | C24: 6.8718224e+08 | D24: 61286832 | E24: 7.9213712e+08 | F24: 1.5406062e+09
B25: Vacant Hotel Kuta Seminyak | C25: 2.6731645e+08 | D25: 6945068.9 | E25: 65202432 | F25: 3.3946395e+08
B26: Vacant Hotel Seminyak Kuta | C26: 1.3808463e+08 | D26: 1.03844e+08 | F26: 2.4192863e+08
B27: Wira | C27: 8.8712302e+08 | D27: 2.6778137e+08 | E27: 17830595 | F27: 1.172735e+09
B29: INPUT: DATA NESTLE
B30: Nama Kry | C30: Total
B32: NP1 | C32: 2.4701721e+08
B33: NP2 | C33: 6.0352798e+08
B34: NP3 | C34: 1.3237803e+08
B35: NP4 | C35: 5.0622062e+08
B36: NP5 | C36: 31764000
S40: PILIHAN % TARGET
B41: DATA PENCAPAIAN — GLOBAL — 31 JULI 2026 | E41: TARGET | F41: =IF(MONTH(TODAY())=7,DAY(TODAY())/DAY(EOMONTH(TODAY(),0)),IF(MONTH(TODAY())>7,1,0)) -> 1 | G41: PILIH TARGET % | H41: 0.9 | I41: PILIH TARGET % | J41: 0.95 | K41: PENUH | L41: 1 | S41: 0.7
B42: KATAGORI | C42: AREA | D42: TARGET | E42: ACHIEVEMENT | F42: % | G42: ="SELISIH"&CHAR(10)&TEXT($H$41,"0%") -> SELISIH 90% | H42: ="PER HARI"&CHAR(10)&TEXT($H$41,"0%") -> PER HARI 90% | I42: ="SELISIH"&CHAR(10)&TEXT($J$41,"0%") -> SELISIH 95% | J42: ="PER HARI"&CHAR(10)&TEXT($J$41,"0%") -> PER HARI 95% | K42: ="SELISIH"&CHAR(10)&TEXT($L$41,"0%") -> SELISIH 100% | L42: ="PER HARI"&CHAR(10)&TEXT($L$41,"0%") -> PER HARI 100% | S42: 0.75
B43: FOOD | C43: HORECA, GT, MT | D43: =SUM(TARGETS!V5:V7,TARGETS!V8:V13,TARGETS!V14:V18) -> 7.9478438e+09 | E43: =G65 -> 7.9773765e+09 | F43: =IFERROR(E43/D43,0) -> 1.0037158 | G43: =D43*$H$41-E43 -> -8.2431711e+08 | H43: =IFERROR(G43/C3,0) -> 0 | I43: =D43*$J$41-E43 -> -4.2692491e+08 | J43: =IFERROR(I43/$C$3,0) -> 0 | K43: =D43*$L$41-E43 -> -29532725 | L43: =IFERROR(K43/$C$3,0) -> 0 | S43: 0.8
B44: BEVERAGE | C44: HORECA, GT, MT | D44: =SUM(TARGETS!W5:W6,TARGETS!W8:W12,TARGETS!W14:W18) -> 1.4827057e+09 | E44: =N8+N9+N10+N11+N12+N13+N14+N15+N16+N17+N18+N19 -> 1.2251277e+09 | F44: =IFERROR(E44/D44,0) -> 0.82627841 | G44: =D44*$H$41-E44 -> 1.0930741e+08 | H44: =IFERROR(G44/C3,0) -> 0 | I44: =D44*$J$41-E44 -> 1.8344269e+08 | J44: =IFERROR(I44/$C$3,0) -> 0 | K44: =D44*$L$41-E44 -> 2.5757798e+08 | L44: =IFERROR(K44/$C$3,0) -> 0 | S44: 0.85
B45: NESTLE | C45: HORECA, GT, MT | D45: =SUM(TARGETS!J22:J26) -> 1.8510638e+09 | E45: =IFERROR(C32,0)+IFERROR(C33,0)+M21+F9 -> 1.5209078e+09 | F45: =IFERROR(E45/D45,0) -> 0.82163987 | G45: =D45*$H$41-E45 -> 1.4504961e+08 | H45: =IFERROR(G45/C3,0) -> 0 | I45: =D45*$J$41-E45 -> 2.376028e+08 | J45: =IFERROR(I45/$C$3,0) -> 0 | K45: =D45*$L$41-E45 -> 3.3015599e+08 | L45: =IFERROR(K45/$C$3,0) -> 0 | S45: 0.9
...

Sheet AGU
B1: DATA PENCAPAIAN — AGUSTUS 2026 | G1: ⚙️ KALENDER KERJA — INPUT MANUAL
G2: Total hari kalender bulan ini (auto) | J2: =E3 -> 31
B3: HARI TERSISA (auto): | C3: =IF($J$5<>"",$J$5,MAX(0,NETWORKDAYS.INTL(MAX(TODAY(),DATE(YEAR(TODAY()),8,1)),EOMONTH(DATE(YEAR(TODAY()),8,1),0),11)-MAX(0,$J$3-$J$4))) -> 0 | D3: Hari kerja tersisa bulan ini (Sab s/d akhir bulan) — otomatis | E3: =DAY(EOMONTH(DATE(YEAR(TODAY()),8,1),0)) -> 31 | G3: Total hari LIBUR / OFF bulan ini | J3: 2
G4: Libur yang SUDAH lewat | J4: 0
G5: Override HARI TERSISA (kosong = auto) | J5: 0
B6: 📥 INPUT DATA HARIAN — Paste dari file sistem di sini | M6: FOOD_ACHIV (calc) | N6: BEV_ACHIV (calc) | O6: BAK_ACHIV (calc)
B7: INPUT: DATA MKS (FOOD & BEVERAGES) | M7: =SUM(C9) -> 0 | N7: =SUM(D9) -> 0 | O7: =SUM(E9) -> 0
B8: Nama_Kry | C8: FOOD | D8: BEVERAGE | E8: BAKERY | F8: Balian | G8: Grand Total
C9: 0 | D9: 0
B10: Dewi Kristiani | C10: 1.685379e+08 | D10: 36713911 | E10: 2.3791014e+08 | F10: 1.8410588e+08 | G10: 6.2726783e+08
B11: Eka/Wahyu - Kuta/Legian | C11: 3.9175416e+08 | D11: 83228395 | E11: 1.3109597e+08 | F11: 3.0388449e+08 | G11: 9.0996302e+08
B12: Eka/Wahyu - FIB | C12: 3123423.4 | D12: 30403217 | E12: 3.5295496e+08 | G12: 3.864816e+08
B13: I MADE LUIH | C13: 1.8205927e+08 | D13: 62051193 | E13: 1.7608436e+08 | F13: 1.1855585e+08 | G13: 5.3875068e+08
B14: I Made Luih (Sanur) | C14: 42773807 | D14: 38226126 | E14: 2.4698916e+08 | F14: 60587163 | G14: 3.8857626e+08
B15: Juni | C15: 8.0693562e+08 | D15: 28388679 | E15: 1.7655266e+08 | F15: 4.4046945e+08 | G15: 1.4523464e+09
B16: Management Bali | C16: 8.98604e+08 | D16: 1359864.9 | E16: 1.0267548e+08 | F16: 18108379 | G16: 1.0207477e+09
B17: Monica | C17: 6.947464e+08 | D17: 83310744 | E17: 3.6189586e+08 | F17: 1.7266265e+09 | G17: 2.8665795e+09
B18: Ni Ketut Sriasih (GT) | C18: 1.2126771e+08 | D18: 15763473 | E18: 1.1845374e+08 | F18: 44710812 | G18: 3.0019574e+08
B19: Ni Ketut Sriasih (MT) | C19: 18170681 | D19: 1.1947952e+08 | E19: 53705086 | F19: 1.2177298e+08 | G19: 3.1312826e+08
B20: NN Made Luih | C20: 1.8623737e+08 | F20: 13081081 | G20: 1.9931845e+08 | M20: =SUM(C30,C35)+M7 -> 1.5543912e+08 | N20: NP5_calc = baris kosong (C30) + NP5 raw (C35) + KA dari MKS (M7)
B21: NN Sujana | C21: 4.2749123e+08 | F21: 16534324 | G21: 4.4402556e+08 | M21: =SUM(C33,C34)+M20 -> 9.5724197e+08 | N21: NP3_final = NP3 raw (C33) + NP4 (C34) + NP5_calc (M20)
B22: Picrom Stalyon | C22: 2.9012801e+08 | D22: 54566849 | E22: 1.5336108e+08 | F22: 5.5174403e+08 | G22: 1.0498e+09
B23: Sujana | C23: 3.366246e+08 | D23: 91520735 | E23: 2.3193149e+08 | F23: 4.0302216e+08 | G23: 1.063099e+09
B24: Taufik | C24: 4.4461944e+08 | D24: 61211234 | E24: 2.2629467e+08 | F24: 7.2668125e+08 | G24: 1.4588066e+09
B25: Vacant Hotel Kuta Seminyak | C25: 1.6019701e+08 | D25: 1.0767016e+08 | E25: 1.7745527e+08 | F25: 57669378 | G25: 5.0299182e+08
B26: Wira | C26: 3.522996e+08 | D26: 3.0696558e+08 | E26: 3.4669295e+08 | F26: 20800433 | G26: 1.0267586e+09
B28: INPUT: DATA NESTLE
B29: Nama Kry | C29: Total
B31: NP1 | C31: 2.7046825e+08
B32: NP2 | C32: 4.5912596e+08
B33: NP3 | C33: 1.5455852e+08
B34: NP4 | C34: 6.4724433e+08
B35: NP5 | C35: 1.5543912e+08
S39: PILIHAN % TARGET
B40: DATA PENCAPAIAN — GLOBAL — 31 AGUSTUS 2026 | E40: TARGET | F40: =IF(MONTH(TODAY())=8,DAY(TODAY())/DAY(EOMONTH(TODAY(),0)),IF(MONTH(TODAY())>8,1,0)) -> 1 | G40: PILIH TARGET % | H40: 0.9 | I40: PILIH TARGET % | J40: 0.95 | K40: PENUH | L40: 1 | S40: 0.7
B41: KATAGORI | C41: AREA | D41: TARGET | E41: ACHIEVEMENT | F41: % | G41: ="SELISIH"&CHAR(10)&TEXT($H$40,"0%") -> SELISIH 90% | H41: ="PER HARI"&CHAR(10)&TEXT($H$40,"0%") -> PER HARI 90% | I41: ="SELISIH"&CHAR(10)&TEXT($J$40,"0%") -> SELISIH 95% | J41: ="PER HARI"&CHAR(10)&TEXT($J$40,"0%") -> PER HARI 95% | K41: ="SELISIH"&CHAR(10)&TEXT($L$40,"0%") -> SELISIH 100% | L41: ="PER HARI"&CHAR(10)&TEXT($L$40,"0%") -> PER HARI 100% | S41: 0.75
B42: FOOD | C42: HORECA, GT, MT | D42: =SUM(TARGETS!Y5:Y7,TARGETS!Y8:Y13,TARGETS!Y14:Y18) -> 4927597521 | E42: =H65 -> 4.6269662e+09 | F42: =IFERROR(E42/D42,0) -> 0.93899029 | G42: =D42*$H$40-E42 -> -1.9212847e+08 | H42: =IFERROR(G42/$C$3,0) -> 0 | I42: =D42*$J$40-E42 -> 54251405 | J42: =IFERROR(I42/$C$3,0) -> 0 | K42: =D42*$L$40-E42 -> 3.0063128e+08 | L42: =IFERROR(K42/$C$3,0) -> 0 | S42: 0.8
B43: BEVERAGE | C43: HORECA, GT, MT | D43: =SUM(TARGETS!Z5:Z6,TARGETS!Z8:Z12,TARGETS!Z14:Z18) -> 1.294443e+09 | E43: =I65 -> 1.1194998e+09 | F43: =IFERROR(E43/D43,0) -> 0.86485061 | G43: =D43*$H$40-E43 -> 45498876 | H43: =IFERROR(G43/$C$3,0) -> 0 | I43: =D43*$J$40-E43 -> 1.1022103e+08 | J43: =IFERROR(I43/$C$3,0) -> 0 | K43: =D43*$L$40-E43 -> 1.7494318e+08 | L43: =IFERROR(K43/$C$3,0) -> 0 | S43: 0.85
B44: BAKERY | C44: HORECA, GT, MT | D44: =SUM(TARGETS!AA5:AA18) -> 3216211725 | E44: =J65 -> 2.9913774e+09 | F44: =IFERROR(E44/D44,0) -> 0.93009343 | G44: =IF(D44=0,0,D44*$H$40-E44) -> -96786848 | H44: =IFERROR(G44/$C$3,0) -> 0 | I44: =IF(D44=0,0,D44*$J$40-E44) -> 64023738 | J44: =IFERROR(I44/$C$3,0) -> 0 | K44: =IF(D44=0,0,D44*$L$40-E44) -> 2.2483432e+08 | L44: =IFERROR(K44/$C$3,0) -> 0 | S44: 0.9
B45: NESTLE | C45: HORECA, GT, MT | D45: =SUM(TARGETS!K22:K26) -> 1.8659574e+09 | E45: =E74 -> 1.6868362e+09 | F45: =IFERROR(E45/D45,0) -> 0.90400571 | G45: =D45*$H$40-E45 -> -7474478 | H45: =IFERROR(G45/$C$3,0) -> 0 | I45: =D45*$J$40-E45 -> 85823394 | J45: =IFERROR(I45/$C$3,0) -> 0 | K45: =D45*$L$40-E45 -> 1.7912127e+08 | L45: =IFERROR(K45/$C$3,0) -> 0 | S45: 0.95
...

Sheet SEP
B1: DATA PENCAPAIAN — SEPTEMBER 2026 | G1: ⚙️ KALENDER KERJA — INPUT MANUAL
G2: Total hari kalender bulan ini (auto) | J2: =E3 -> 30
B3: HARI TERSISA (auto): | C3: =IF($J$5<>"",$J$5,MAX(0,NETWORKDAYS.INTL(MAX(TODAY(),DATE(YEAR(TODAY()),9,1)),EOMONTH(DATE(YEAR(TODAY()),9,1),0),11)-MAX(0,$J$3-$J$4))) -> 0 | D3: Hari kerja tersisa bulan ini (Sab s/d akhir bulan) — otomatis | E3: =DAY(EOMONTH(DATE(YEAR(TODAY()),9,1),0)) -> 30 | G3: Total hari LIBUR / OFF bulan ini | J3: 0
G4: Libur yang SUDAH lewat | J4: 0
G5: Override HARI TERSISA (kosong = auto)
B6: 📥 INPUT DATA HARIAN — Paste dari file sistem di sini | M6: FOOD_ACHIV (calc) | N6: BEV_ACHIV (calc) | O6: BAK_ACHIV (calc)
B7: INPUT: DATA MKS (FOOD & BEVERAGES) | M7: =SUM(C9) -> 0 | N7: =SUM(D9) -> 0 | O7: =SUM(E9) -> 0
B8: Nama_Kry | C8: FOOD | D8: BEVERAGE | E8: BAKERY | F8: Balian | G8: Grand Total
C9: 0 | D9: 0
B10: Dewi Kristiani | C10: 1.4474016e+08 | D10: 42947490 | E10: 2.0302594e+08 | F10: 1.6702082e+08 | G10: 5.5773441e+08
B11: FIB | C11: 5673423.4 | D11: 42317827 | E11: 2.9487388e+08 | G11: 3.4286513e+08
B12: I MADE LUIH | C12: 1.8434205e+08 | D12: 73221835 | E12: 1.7914199e+08 | F12: 73537257 | G12: 5.1024313e+08
B13: I Made Luih (Sanur) | C13: 34096172 | D13: 24478710 | E13: 2.2091297e+08 | F13: 92206408 | G13: 3.7169427e+08
B14: Juni | C14: 5.196056e+08 | D14: 46985541 | E14: 1.5468789e+08 | F14: 4.351825e+08 | G14: 1.1564615e+09
B15: Management Bali | C15: 1.6719304e+09 | D15: 12877002 | E15: 95420197 | F15: 18848649 | G15: 1.7990762e+09
B16: Monica | C16: 5.2108979e+08 | D16: 57488126 | E16: 3.3155059e+08 | F16: 1.0859958e+09 | G16: 1.9961243e+09
B17: Ni Ketut Sriasih (GT) | C17: 1.0981523e+08 | D17: 13122554 | E17: 1.1157293e+08 | F17: 50871893 | G17: 2.853826e+08
B18: Ni Ketut Sriasih (MT) | C18: 15069698 | D18: 1.5943342e+08 | E18: 64345106 | F18: 1.0941622e+08 | G18: 3.4826445e+08
B19: NN Made Luih | C19: 48019875 | F19: 9945945.7 | G19: 57965821
B20: NN Sujana | C20: 2.2840668e+08 | F20: 13579549 | G20: 2.4198623e+08 | M20: =SUM(C30,C35)+M7 -> 0 | N20: NP5_calc = baris kosong (C30) + NP5 raw (C35) + KA dari MKS (M7)
B21: Picrom Stalyon | C21: 2.9325195e+08 | D21: 52174490 | E21: 1.6069217e+08 | F21: 4.4095854e+08 | G21: 9.4707714e+08 | M21: =SUM(C33,C34)+M20 -> 1.0484009e+09 | N21: NP3_final = NP3 raw (C33) + NP4 (C34) + NP5_calc (M20)
B22: Ronald | C22: 2.0325437e+08 | D22: 64276669 | E22: 1.6408615e+08 | F22: 65793423 | G22: 4.9741061e+08
B23: Sujana | C23: 2.8201157e+08 | D23: 74809273 | E23: 1.9365008e+08 | F23: 3.4709853e+08 | G23: 8.9756946e+08
B24: Taufik | C24: 4.7335869e+08 | D24: 68355377 | E24: 2.1422101e+08 | F24: 6.3707636e+08 | G24: 1.3930114e+09
B25: Wahyu | C25: 3.5012761e+08 | D25: 90343081 | E25: 1.0423016e+08 | F25: 50324325 | G25: 5.9502517e+08
B26: Wira | C26: 5.4795939e+08 | D26: 2.9087957e+08 | E26: 2.8651343e+08 | F26: 21926703 | G26: 1.1472791e+09
B28: INPUT: DATA NESTLE
B29: Nama Kry | C29: Total
B31: NP1 | C31: 2.8053517e+08
B32: NP2 | C32: 4.7349285e+08
B33: NP3 | C33: 5.1515892e+08
B34: NP4 | C34: 5.3324194e+08
B35: NP5 | C35: 0
S39: PILIHAN % TARGET
B40: DATA PENCAPAIAN — GLOBAL — 30 SEPTEMBER 2026 | E40: TARGET | F40: =IF(MONTH(TODAY())=9,DAY(TODAY())/DAY(EOMONTH(TODAY(),0)),IF(MONTH(TODAY())>9,1,0)) -> 1 | G40: PILIH TARGET % | H40: 0.95 | I40: PILIH TARGET % | J40: 1 | K40: PENUH | L40: 1 | S40: 0.7
B41: KATAGORI | C41: AREA | D41: TARGET | E41: ACHIEVEMENT | F41: % | G41: ="SELISIH"&CHAR(10)&TEXT($H$40,"0%") -> SELISIH 95% | H41: ="PER HARI"&CHAR(10)&TEXT($H$40,"0%") -> PER HARI 95% | I41: ="SELISIH"&CHAR(10)&TEXT($J$40,"0%") -> SELISIH 100% | J41: ="PER HARI"&CHAR(10)&TEXT($J$40,"0%") -> PER HARI 100% | K41: ="SELISIH"&CHAR(10)&TEXT($L$40,"0%") -> SELISIH 100% | L41: ="PER HARI"&CHAR(10)&TEXT($L$40,"0%") -> PER HARI 100% | S41: 0.75
B42: FOOD | C42: HORECA, GT, MT | D42: =SUM(TARGETS!AB5:AB18) -> 4.511786e+09 | E42: =H65 -> 3.9608223e+09 | F42: =IFERROR(E42/D42,0) -> 0.87788344 | G42: =D42*$H$40-E42 -> 3.2537448e+08 | H42: =IFERROR(G42/$C$3,0) -> 0 | I42: =D42*$J$40-E42 -> 5.5096378e+08 | J42: =IFERROR(I42/$C$3,0) -> 0 | K42: =D42*$L$40-E42 -> 5.5096378e+08 | L42: =IFERROR(K42/$C$3,0) -> 0 | S42: 0.8
B43: BEVERAGE | C43: HORECA, GT, MT | D43: =SUM(TARGETS!AC5:AC18) -> 1.4013653e+09 | E43: =I65 -> 1.100834e+09 | F43: =IFERROR(E43/D43,0) -> 0.7855439 | G43: =D43*$H$40-E43 -> 2.3046307e+08 | H43: =IFERROR(G43/$C$3,0) -> 0 | I43: =D43*$J$40-E43 -> 3.0053134e+08 | J43: =IFERROR(I43/$C$3,0) -> 0 | K43: =D43*$L$40-E43 -> 3.0053134e+08 | L43: =IFERROR(K43/$C$3,0) -> 0 | S43: 0.85
B44: BAKERY | C44: HORECA, GT, MT | D44: =SUM(TARGETS!AD5:AD18) -> 2.9448142e+09 | E44: =J65 -> 2.6835043e+09 | F44: =IFERROR(E44/D44,0) -> 0.91126438 | G44: =IF(D44=0,0,D44*$H$40-E44) -> 1.1406921e+08 | H44: =IFERROR(G44/$C$3,0) -> 0 | I44: =IF(D44=0,0,D44*$J$40-E44) -> 2.6130992e+08 | J44: =IFERROR(I44/$C$3,0) -> 0 | K44: =IF(D44=0,0,D44*$L$40-E44) -> 2.6130992e+08 | L44: =IFERROR(K44/$C$3,0) -> 0 | S44: 0.9
B45: NESTLE | C45: HORECA, GT, MT | D45: =SUM(TARGETS!L22:L26) -> 1.7404255e+09 | E45: =E74 -> 1.8024289e+09 | F45: =IFERROR(E45/D45,0) -> 1.0356254 | G45: =D45*$H$40-E45 -> -1.4902463e+08 | H45: =IFERROR(G45/$C$3,0) -> 0 | I45: =D45*$J$40-E45 -> -62003358 | J45: =IFERROR(I45/$C$3,0) -> 0 | K45: =D45*$L$40-E45 -> -62003358 | L45: =IFERROR(K45/$C$3,0) -> 0 | S45: 0.95
...

Sheet OKT
B1: DATA PENCAPAIAN — OKTOBER 2026 | G1: ⚙️ KALENDER KERJA — INPUT MANUAL
G2: Total hari kalender bulan ini (auto) | J2: =E3 -> 31
B3: HARI TERSISA (auto): | C3: =IF($J$5<>"",$J$5,MAX(0,NETWORKDAYS.INTL(MAX(TODAY(),DATE(YEAR(TODAY()),10,1)),EOMONTH(DATE(YEAR(TODAY()),10,1),0),11)-MAX(0,$J$3-$J$4))) -> 3 | D3: Hari kerja tersisa bulan ini (Sab s/d akhir bulan) — otomatis | E3: =DAY(EOMONTH(DATE(YEAR(TODAY()),10,1),0)) -> 31 | G3: Total hari LIBUR / OFF bulan ini | J3: 1
G4: Libur yang SUDAH lewat | J4: 0
G5: Override HARI TERSISA (kosong = auto)
B6: 📥 INPUT DATA HARIAN — Paste dari file sistem di sini | M6: FOOD_ACHIV (calc) | N6: BEV_ACHIV (calc) | O6: BAK_ACHIV (calc)
B7: INPUT: DATA MKS (FOOD & BEVERAGES) | M7: =SUM(C9) -> 0 | N7: =SUM(D9) -> 0 | O7: =SUM(E9) -> 0
B8: Nama_Kry | C8: FOOD | D8: BEVERAGE | E8: BAKERY | F8: Balian | G8: Grand Total
C9: 0 | D9: 0
B10: Dewi Kristiani | C10: 1.8183888e+08 | D10: 48782899 | E10: 2.090424e+08 | F10: 1.5078559e+08 | G10: 5.9331127e+08
B11: FIB | C11: 3670270.3 | D11: 37900456 | E11: 3.2790091e+08 | F11: 0 | G11: 3.6947163e+08
B12: I MADE LUIH | C12: 1.7688448e+08 | D12: 53497044 | E12: 1.5217936e+08 | F12: 1.1433513e+08 | G12: 5.0871852e+08
B13: I Made Luih (Sanur) | C13: 26230284 | D13: 45465020 | E13: 2.3074977e+08 | F13: 82572976 | G13: 3.8695805e+08
B14: Juni | C14: 4.3458189e+08 | D14: 34283176 | E14: 1.4906367e+08 | F14: 3.0563028e+08 | G14: 9.2157301e+08
B15: Management Bali | C15: 1.3157949e+09 | D15: 8412923.6 | E15: 27680309 | F15: 15262703 | G15: 1.3671509e+09
B16: Monica | C16: 5.0244865e+08 | D16: 67632213 | E16: 3.3225036e+08 | F16: 1.1013631e+09 | G16: 2.1885343e+09
B17: Ni Ketut Sriasih (GT) | C17: 1.4136397e+08 | D17: 22741586 | E17: 96799554 | F17: 32257298 | G17: 2.931624e+08
B18: Ni Ketut Sriasih (MT) | C18: 17516336 | D18: 83059959 | E18: 51785245 | F18: 1.2222703e+08 | G18: 2.7458857e+08
B19: NN Made Luih | C19: 19889996 | D19: 0 | E19: 0 | F19: 13405405 | G19: 36495401
B20: NN Sujana | C20: 1.4385957e+08 | D20: 0 | E20: 0 | F20: 13729729 | G20: 1.575893e+08 | M20: =SUM(C31,C36)+M7 -> 0 | N20: NP5_calc = baris kosong (C30) + NP5 raw (C35) + KA dari MKS (M7)
B21: Picrom Stalyon | C21: 2.6130807e+08 | D21: 39705698 | E21: 1.3209194e+08 | F21: 3.9373298e+08 | G21: 8.7138269e+08 | M21: =SUM(C34,C35)+M20 -> 7.5314633e+08 | N21: NP3_final = NP3 raw (C33) + NP4 (C34) + NP5_calc (M20)
B22: Ronald | C22: 1.9658878e+08 | D22: 62156569 | E22: 1.3363452e+08 | F22: 98141442 | G22: 5.1090131e+08
B23: Sujana | C23: 2.7646669e+08 | D23: 61402480 | E23: 1.7373499e+08 | F23: 2.9415857e+08 | G23: 8.1082722e+08
B24: Taufik | C24: 4.2157395e+08 | D24: 65606920 | E24: 1.9784206e+08 | F24: 6.2796542e+08 | G24: 1.3406573e+09
B25: Wahyu | C25: 2.8926067e+08 | D25: 85225753 | E25: 1.0038896e+08 | F25: 75549351 | G25: 5.5178473e+08
B26: Wira | C26: 4.8395013e+08 | D26: 1.6756623e+08 | E26: 2.1469188e+08 | F26: 19107676 | G26: 8.8531592e+08
B27: Yuangga | C27: 0 | D27: 0 | E27: 0 | F27: 3405405.6 | G27: 5205405.6
B29: INPUT: DATA NESTLE
B30: Nama Kry | C30: Total
B32: NP1 | C32: 2.2071554e+08
B33: NP2 | C33: 3.9329365e+08
B34: NP3 | C34: 1.3461773e+08
B35: NP4 | C35: 6.185286e+08
B36: NP5 | C36: 0
S40: PILIHAN % TARGET
B41: DATA PENCAPAIAN — GLOBAL — 28 OKTOBER 2026 | E41: TARGET | F41: =IF(MONTH(TODAY())=10,DAY(TODAY())/DAY(EOMONTH(TODAY(),0)),IF(MONTH(TODAY())>10,1,0)) -> 0.90322581 | G41: PILIH TARGET % | H41: 1 | I41: PILIH TARGET % | J41: 1 | K41: PENUH | L41: 1 | S41: 0.7
B42: KATAGORI | C42: AREA | D42: TARGET | E42: ACHIEVEMENT | F42: % | G42: ="SELISIH"&CHAR(10)&TEXT($H$41,"0%") -> SELISIH 100% | H42: ="PER HARI"&CHAR(10)&TEXT($H$41,"0%") -> PER HARI 100% | I42: ="SELISIH"&CHAR(10)&TEXT($J$41,"0%") -> SELISIH 100% | J42: ="PER HARI"&CHAR(10)&TEXT($J$41,"0%") -> PER HARI 100% | K42: ="SELISIH"&CHAR(10)&TEXT($L$41,"0%") -> SELISIH 100% | L42: ="PER HARI"&CHAR(10)&TEXT($L$41,"0%") -> PER HARI 100% | S42: 0.75
B43: FOOD | C43: HORECA, GT, MT | D43: =SUM(TARGETS!AE5:AE18) -> 4.4645867e+09 | E43: =H66 -> 3.5774326e+09 | F43: =IFERROR(E43/D43,0) -> 0.80129088 | G43: =D43*$H$41-E43 -> 8.8715408e+08 | H43: =IFERROR(G43/$C$3,0) -> 2.9571803e+08 | I43: =D43*$J$41-E43 -> 8.8715408e+08 | J43: =IFERROR(I43/$C$3,0) -> 2.9571803e+08 | K43: =D43*$L$41-E43 -> 8.8715408e+08 | L43: =IFERROR(K43/$C$3,0) -> 2.9571803e+08 | S43: 0.8
B44: BEVERAGE | C44: HORECA, GT, MT | D44: =SUM(TARGETS!AF5:AF18) -> 1.2799081e+09 | E44: =I66 -> 8.75026e+08 | F44: =IFERROR(E44/D44,0) -> 0.68366317 | G44: =D44*$H$41-E44 -> 4.0488206e+08 | H44: =IFERROR(G44/$C$3,0) -> 1.3496069e+08 | I44: =D44*$J$41-E44 -> 4.0488206e+08 | J44: =IFERROR(I44/$C$3,0) -> 1.3496069e+08 | K44: =D44*$L$41-E44 -> 4.0488206e+08 | L44: =IFERROR(K44/$C$3,0) -> 1.3496069e+08 | S44: 0.85
B45: BAKERY | C45: HORECA, GT, MT | D45: =SUM(TARGETS!AG5:AG18) -> 2.9140075e+09 | E45: =J66 -> 2.5021556e+09 | F45: =IFERROR(E45/D45,0) -> 0.85866479 | G45: =IF(D45=0,0,D45*$H$41-E45) -> 4.1185185e+08 | H45: =IFERROR(G45/$C$3,0) -> 1.3728395e+08 | I45: =IF(D45=0,0,D45*$J$41-E45) -> 4.1185185e+08 | J45: =IFERROR(I45/$C$3,0) -> 1.3728395e+08 | K45: =IF(D45=0,0,D45*$L$41-E45) -> 4.1185185e+08 | L45: =IFERROR(K45/$C$3,0) -> 1.3728395e+08 | S45: 0.9
...

Sheet NOV
B1: DATA PENCAPAIAN — NOVEMBER 2026 | G1: ⚙️ KALENDER KERJA — INPUT MANUAL
G2: Total hari kalender bulan ini (auto) | J2: =E3 -> 30
B3: HARI TERSISA (auto): | C3: =IF($J$5<>"",$J$5,MAX(0,NETWORKDAYS.INTL(MAX(TODAY(),DATE(YEAR(TODAY()),11,1)),EOMONTH(DATE(YEAR(TODAY()),11,1),0),11)-MAX(0,$J$3-$J$4))) -> 25 | D3: Hari kerja tersisa bulan ini (Sab s/d akhir bulan) — otomatis | E3: =DAY(EOMONTH(DATE(YEAR(TODAY()),11,1),0)) -> 30 | G3: Total hari LIBUR / OFF bulan ini | J3: 0
G4: Libur yang SUDAH lewat | J4: 0
G5: Override HARI TERSISA (kosong = auto)
B6: 📥 INPUT DATA HARIAN — Paste dari file sistem di sini | M6: FOOD_ACHIV (calc) | N6: BEV_ACHIV (calc) | O6: BAK_ACHIV (calc)
B7: INPUT: DATA MKS (FOOD & BEVERAGES) | M7: =SUM(C9) -> 0 | N7: =SUM(D9) -> 0 | O7: =SUM(E9) -> 0
B8: Nama_Kry | C8: FOOD | D8: BEVERAGE | E8: BAKERY | F8: Balian | G8: Grand Total
C9: 0 | D9: 0
B10: Dewi Kristiani | G10: =SUM(C10:F10) -> 0
B11: Wahyu | G11: =SUM(C11:F11) -> 0
B12: FIB | G12: =SUM(C12:F12) -> 0
B13: I MADE LUIH | G13: =SUM(C13:F13) -> 0
B14: I Made Luih (Sanur) | G14: =SUM(C14:F14) -> 0
B15: Juni | G15: =SUM(C15:F15) -> 0
B16: Management Bali | G16: =SUM(C16:F16) -> 0
B17: Monica | G17: =SUM(C17:F17) -> 0
B18: Ni Ketut Sriasih (GT) | G18: =SUM(C18:F18) -> 0
B19: Ni Ketut Sriasih (MT) | G19: =SUM(C19:F19) -> 0
B20: NN Made Luih | G20: =SUM(C20:F20) -> 0 | M20: =SUM(C30,C35)+M7 -> 0 | N20: NP5_calc = baris kosong (C30) + NP5 raw (C35) + KA dari MKS (M7)
B21: NN Sujana | G21: =SUM(C21:F21) -> 0 | M21: =SUM(C33,C34)+M20 -> 0 | N21: NP3_final = NP3 raw (C33) + NP4 (C34) + NP5_calc (M20)
B22: Picrom Stalyon | G22: =SUM(C22:F22) -> 0
B23: Sujana | G23: =SUM(C23:F23) -> 0
B24: Taufik | G24: =SUM(C24:F24) -> 0
B25: Ronald | G25: =SUM(C25:F25) -> 0
B26: Wira | G26: =SUM(C26:F26) -> 0
