Workbook

Sheet Read Me
A1: HOW TO USE THIS FILE / CARA PAKAI FILE INI
A2: 1. Paste the new day's raw export into the 'Data' tab, starting at cell A2, columns A through R. | B2: Tempel data harian baru ke tab 'Data', mulai dari sel A2, kolom A sampai R.
A3: 2. Do NOT delete or edit columns S onward on 'Data' — those are hidden helper formulas that power every other tab. | B3: JANGAN hapus atau ubah kolom S dst di 'Data' — itu rumus bantu tersembunyi yang menggerakkan semua tab lain.
A4: 3. All other tabs (Butter, Pristine, O Sole, Osterberg, Agristo & Maestro, Soejasch Product, IQF, Masterista, Mikol, Savis, Stok Kosong) update automatically. Nothing else to do. | B4: Semua tab lain (Butter, Pristine, O Sole, Osterberg, Agristo & Maestro, Soejasch Product, IQF, Masterista, Mikol, Savis, Stok Kosong) otomatis ter-update. Tidak perlu tindakan lain.
A5: 4. If a NEW product code should belong to a specific brand tab but doesn't show up there, add its code to the matching column on the 'CategoryLists' tab. | B5: Jika ada KODE PRODUK BARU yang seharusnya masuk tab tertentu tapi tidak muncul, tambahkan kodenya di kolom yang sesuai pada tab 'CategoryLists'.
A6: 5. Capacity: formulas cover up to 5,000 product rows. If the list grows beyond that, ask for the formulas to be extended. | B6: Kapasitas: rumus mendukung hingga 5.000 baris produk. Jika daftar produk melebihi itu, minta rumus diperpanjang.

Sheet Data
A1: Kode_Brg | B1: Nama_Brg | C1: Kode_sat_Std | D1: Saldo Akhir (Std) | E1: Penjualan 3 Bulan (June 2026) | F1: Penjualan 3 Bulan (July 2026) | G1: Penjualan 3 Bulan (August 2026) | H1: Rata - Rata 3 Bulan | I1: Buffer Month (3 Bulan) | J1: Buffer Day (3 Bulan) | K1: Penjualan Bulan Sama Tahun lalu | L1: Buffer Month (Bulan Sama Tahun Lalu) | M1: Buffer Day (Bulan Sama Tahun Lalu) | N1: Penjualan Tgl 1 sd 02 Sep 2026 | O1: Buffer Month (Tgl 1 sd 02 Sep 2026) | P1: Buffer Day (Tgl 1 sd 02 Sep 2026) | Q1: Tgl_LPB | R1: Qty_LPB | S1: Qty PO yg belum LPB | T1: Is_Pristine | U1: Is_OSole | V1: Is_Osterberg | W1: Is_AgristoMaestro | X1: Is_Soejasch | Y1: Is_IQF | Z1: Is_Masterista | AA1: Is_Mikol | AB1: Is_Savis | AC1: Is_StokKosong | AD1: Is_Butter
A2: ASS-PE-TC30 | B2: Pappermint@30g/Tincan | C2: TIN | D2: 0 | E2: 0 | F2: 0 | G2: 0 | H2: 0 | I2: 0 | J2: 0 | K2: 0 | L2: 0 | M2: 0 | N2: 0 | O2: 0 | P2: 0 | T2: =COUNTIF(CategoryLists!$B:$B,A2)>0 -> FALSE | U2: =COUNTIF(CategoryLists!$C:$C,A2)>0 -> FALSE | V2: =COUNTIF(CategoryLists!$D:$D,A2)>0 -> FALSE | W2: =COUNTIF(CategoryLists!$E:$E,A2)>0 -> FALSE | X2: =COUNTIF(CategoryLists!$F:$F,A2)>0 -> FALSE | Y2: =COUNTIF(CategoryLists!$G:$G,A2)>0 -> FALSE | Z2: =LEFT(A2,3)="PMS" -> FALSE | AA2: =OR(LEFT(A2,3)="CKP",LEFT(A2,3)="PNL",COUNTIF(CategoryLists!$I:$I,A2)>0) -> FALSE | AB2: =COUNTIF(CategoryLists!$H:$H,A2)>0 -> FALSE | AC2: =AND(A2<>"",D2=0) -> TRUE | AD2: =COUNTIF(CategoryLists!$A:$A,A2)>0 -> FALSE
A3: 010244 | B3: Beer Hoegaarden White 330ML | C3: BTL | D3: 0 | E3: 0 | F3: 0 | G3: 0 | H3: 0 | I3: 0 | J3: 0 | K3: 0 | L3: 0 | M3: 0 | N3: 0 | O3: 0 | P3: 0 | Q3: 44888 | R3: 144 | T3: =COUNTIF(CategoryLists!$B:$B,A3)>0 -> FALSE | U3: =COUNTIF(CategoryLists!$C:$C,A3)>0 -> FALSE | V3: =COUNTIF(CategoryLists!$D:$D,A3)>0 -> FALSE | W3: =COUNTIF(CategoryLists!$E:$E,A3)>0 -> FALSE | X3: =COUNTIF(CategoryLists!$F:$F,A3)>0 -> FALSE | Y3: =COUNTIF(CategoryLists!$G:$G,A3)>0 -> FALSE | Z3: =LEFT(A3,3)="PMS" -> FALSE | AA3: =OR(LEFT(A3,3)="CKP",LEFT(A3,3)="PNL",COUNTIF(CategoryLists!$I:$I,A3)>0) -> TRUE | AB3: =COUNTIF(CategoryLists!$H:$H,A3)>0 -> FALSE | AC3: =AND(A3<>"",D3=0) -> TRUE | AD3: =COUNTIF(CategoryLists!$A:$A,A3)>0 -> FALSE
A4: 010245 | B4: Beer Hoegaarden Rosee 248ML | C4: BTL | D4: 0 | E4: 0 | F4: 0 | G4: 0 | H4: 0 | I4: 0 | J4: 0 | K4: 0 | L4: 0 | M4: 0 | N4: 0 | O4: 0 | P4: 0 | Q4: 44897 | R4: 24 | T4: =COUNTIF(CategoryLists!$B:$B,A4)>0 -> FALSE | U4: =COUNTIF(CategoryLists!$C:$C,A4)>0 -> FALSE | V4: =COUNTIF(CategoryLists!$D:$D,A4)>0 -> FALSE | W4: =COUNTIF(CategoryLists!$E:$E,A4)>0 -> FALSE | X4: =COUNTIF(CategoryLists!$F:$F,A4)>0 -> FALSE | Y4: =COUNTIF(CategoryLists!$G:$G,A4)>0 -> FALSE | Z4: =LEFT(A4,3)="PMS" -> FALSE | AA4: =OR(LEFT(A4,3)="CKP",LEFT(A4,3)="PNL",COUNTIF(CategoryLists!$I:$I,A4)>0) -> TRUE | AB4: =COUNTIF(CategoryLists!$H:$H,A4)>0 -> FALSE | AC4: =AND(A4<>"",D4=0) -> TRUE | AD4: =COUNTIF(CategoryLists!$A:$A,A4)>0 -> FALSE
A5: 10071179043386 | B5: Simplot Conquest Delivery+ 3/8 Straight Cut (13.61/Box) | C5: KTN | D5: 0 | E5: 0 | F5: 0 | G5: 0 | H5: 0 | I5: 0 | J5: 0 | K5: 0 | L5: 0 | M5: 0 | N5: 0 | O5: 0 | P5: 0 | T5: =COUNTIF(CategoryLists!$B:$B,A5)>0 -> FALSE | U5: =COUNTIF(CategoryLists!$C:$C,A5)>0 -> FALSE | V5: =COUNTIF(CategoryLists!$D:$D,A5)>0 -> FALSE | W5: =COUNTIF(CategoryLists!$E:$E,A5)>0 -> FALSE | X5: =COUNTIF(CategoryLists!$F:$F,A5)>0 -> FALSE | Y5: =COUNTIF(CategoryLists!$G:$G,A5)>0 -> FALSE | Z5: =LEFT(A5,3)="PMS" -> FALSE | AA5: =OR(LEFT(A5,3)="CKP",LEFT(A5,3)="PNL",COUNTIF(CategoryLists!$I:$I,A5)>0) -> FALSE | AB5: =COUNTIF(CategoryLists!$H:$H,A5)>0 -> FALSE | AC5: =AND(A5<>"",D5=0) -> TRUE | AD5: =COUNTIF(CategoryLists!$A:$A,A5)>0 -> FALSE
A6: 150226 | B6: Belly Skinless Premium (2.5Kg/Pack) | C6: KG | D6: 121.5305 | E6: 305.799 | F6: 347.2292 | G6: 253.5798 | H6: 302.2026 | I6: 0.4021 | J6: 12.0644 | K6: 626.3896 | L6: 0.194 | M6: 5.8205 | N6: 10.25 | O6: 0.7896 | P6: 23.7132 | Q6: 46265 | R6: 126.56 | S6: 5997.59 | T6: =COUNTIF(CategoryLists!$B:$B,A6)>0 -> FALSE | U6: =COUNTIF(CategoryLists!$C:$C,A6)>0 -> FALSE | V6: =COUNTIF(CategoryLists!$D:$D,A6)>0 -> FALSE | W6: =COUNTIF(CategoryLists!$E:$E,A6)>0 -> FALSE | X6: =COUNTIF(CategoryLists!$F:$F,A6)>0 -> FALSE | Y6: =COUNTIF(CategoryLists!$G:$G,A6)>0 -> FALSE | Z6: =LEFT(A6,3)="PMS" -> FALSE | AA6: =OR(LEFT(A6,3)="CKP",LEFT(A6,3)="PNL",COUNTIF(CategoryLists!$I:$I,A6)>0) -> FALSE | AB6: =COUNTIF(CategoryLists!$H:$H,A6)>0 -> FALSE | AC6: =AND(A6<>"",D6=0) -> FALSE | AD6: =COUNTIF(CategoryLists!$A:$A,A6)>0 -> FALSE
A7: 160072 | B7: Davinci Pump Syrup 10Ml | C7: PCS | D7: 22 | E7: 0 | F7: 0 | G7: 0 | H7: 0 | I7: 0 | J7: 0 | K7: 0 | L7: 0 | M7: 0 | N7: 0 | O7: 0 | P7: 0 | Q7: 44793 | R7: 30 | T7: =COUNTIF(CategoryLists!$B:$B,A7)>0 -> FALSE | U7: =COUNTIF(CategoryLists!$C:$C,A7)>0 -> FALSE | V7: =COUNTIF(CategoryLists!$D:$D,A7)>0 -> FALSE | W7: =COUNTIF(CategoryLists!$E:$E,A7)>0 -> FALSE | X7: =COUNTIF(CategoryLists!$F:$F,A7)>0 -> FALSE | Y7: =COUNTIF(CategoryLists!$G:$G,A7)>0 -> FALSE | Z7: =LEFT(A7,3)="PMS" -> FALSE | AA7: =OR(LEFT(A7,3)="CKP",LEFT(A7,3)="PNL",COUNTIF(CategoryLists!$I:$I,A7)>0) -> FALSE | AB7: =COUNTIF(CategoryLists!$H:$H,A7)>0 -> FALSE | AC7: =AND(A7<>"",D7=0) -> FALSE | AD7: =COUNTIF(CategoryLists!$A:$A,A7)>0 -> FALSE
A8: 160073 | B8: Davinci Pump Syrup 30Ml | C8: PCS | D8: 20 | E8: 0 | F8: 0 | G8: 0 | H8: 0 | I8: 0 | J8: 0 | K8: 0 | L8: 0 | M8: 0 | N8: 0 | O8: 0 | P8: 0 | Q8: 44793 | R8: 30 | T8: =COUNTIF(CategoryLists!$B:$B,A8)>0 -> FALSE | U8: =COUNTIF(CategoryLists!$C:$C,A8)>0 -> FALSE | V8: =COUNTIF(CategoryLists!$D:$D,A8)>0 -> FALSE | W8: =COUNTIF(CategoryLists!$E:$E,A8)>0 -> FALSE | X8: =COUNTIF(CategoryLists!$F:$F,A8)>0 -> FALSE | Y8: =COUNTIF(CategoryLists!$G:$G,A8)>0 -> FALSE | Z8: =LEFT(A8,3)="PMS" -> FALSE | AA8: =OR(LEFT(A8,3)="CKP",LEFT(A8,3)="PNL",COUNTIF(CategoryLists!$I:$I,A8)>0) -> FALSE | AB8: =COUNTIF(CategoryLists!$H:$H,A8)>0 -> FALSE | AC8: =AND(A8<>"",D8=0) -> FALSE | AD8: =COUNTIF(CategoryLists!$A:$A,A8)>0 -> FALSE
A9: 230107 | B9: Davinci Caramel Sauce 2L | C9: BTL | D9: 0 | E9: 0 | F9: 0 | G9: 0 | H9: 0 | I9: 0 | J9: 0 | K9: 0 | L9: 0 | M9: 0 | N9: 0 | O9: 0 | P9: 0 | Q9: 44936 | R9: 1 | S9: 6 | T9: =COUNTIF(CategoryLists!$B:$B,A9)>0 -> FALSE | U9: =COUNTIF(CategoryLists!$C:$C,A9)>0 -> FALSE | V9: =COUNTIF(CategoryLists!$D:$D,A9)>0 -> FALSE | W9: =COUNTIF(CategoryLists!$E:$E,A9)>0 -> FALSE | X9: =COUNTIF(CategoryLists!$F:$F,A9)>0 -> FALSE | Y9: =COUNTIF(CategoryLists!$G:$G,A9)>0 -> FALSE | Z9: =LEFT(A9,3)="PMS" -> FALSE | AA9: =OR(LEFT(A9,3)="CKP",LEFT(A9,3)="PNL",COUNTIF(CategoryLists!$I:$I,A9)>0) -> FALSE | AB9: =COUNTIF(CategoryLists!$H:$H,A9)>0 -> FALSE | AC9: =AND(A9<>"",D9=0) -> TRUE | AD9: =COUNTIF(CategoryLists!$A:$A,A9)>0 -> FALSE
A10: 300271 | B10: Hengstenberg Raspberry Vinegar 500ml/Btl | C10: BTL | D10: 0 | E10: 0 | F10: 0 | G10: 0 | H10: 0 | I10: 0 | J10: 0 | K10: 0 | L10: 0 | M10: 0 | N10: 0 | O10: 0 | P10: 0 | T10: =COUNTIF(CategoryLists!$B:$B,A10)>0 -> FALSE | U10: =COUNTIF(CategoryLists!$C:$C,A10)>0 -> FALSE | V10: =COUNTIF(CategoryLists!$D:$D,A10)>0 -> FALSE | W10: =COUNTIF(CategoryLists!$E:$E,A10)>0 -> FALSE | X10: =COUNTIF(CategoryLists!$F:$F,A10)>0 -> FALSE | Y10: =COUNTIF(CategoryLists!$G:$G,A10)>0 -> FALSE | Z10: =LEFT(A10,3)="PMS" -> FALSE | AA10: =OR(LEFT(A10,3)="CKP",LEFT(A10,3)="PNL",COUNTIF(CategoryLists!$I:$I,A10)>0) -> FALSE | AB10: =COUNTIF(CategoryLists!$H:$H,A10)>0 -> FALSE | AC10: =AND(A10<>"",D10=0) -> TRUE | AD10: =COUNTIF(CategoryLists!$A:$A,A10)>0 -> FALSE
A11: AS-CH-TB50-G | B11: Chamomile Dream @50Tb/Box - Grand Hyatt | C11: BOX | D11: 0 | E11: 0 | F11: 0 | G11: 0 | H11: 0 | I11: 0 | J11: 0 | K11: 0 | L11: 0 | M11: 0 | N11: 0 | O11: 0 | P11: 0 | Q11: 45510 | R11: 150 | T11: =COUNTIF(CategoryLists!$B:$B,A11)>0 -> FALSE | U11: =COUNTIF(CategoryLists!$C:$C,A11)>0 -> FALSE | V11: =COUNTIF(CategoryLists!$D:$D,A11)>0 -> FALSE | W11: =COUNTIF(CategoryLists!$E:$E,A11)>0 -> FALSE | X11: =COUNTIF(CategoryLists!$F:$F,A11)>0 -> FALSE | Y11: =COUNTIF(CategoryLists!$G:$G,A11)>0 -> FALSE | Z11: =LEFT(A11,3)="PMS" -> FALSE | AA11: =OR(LEFT(A11,3)="CKP",LEFT(A11,3)="PNL",COUNTIF(CategoryLists!$I:$I,A11)>0) -> FALSE | AB11: =COUNTIF(CategoryLists!$H:$H,A11)>0 -> FALSE | AC11: =AND(A11<>"",D11=0) -> TRUE | AD11: =COUNTIF(CategoryLists!$A:$A,A11)>0 -> FALSE
A12: ASS-001 | B12: SAVIS TEA BREWER | C12: PCS | D12: 0 | E12: 0 | F12: 0 | G12: 0 | H12: 0 | I12: 0 | J12: 0 | K12: 0 | L12: 0 | M12: 0 | N12: 0 | O12: 0 | P12: 0 | T12: =COUNTIF(CategoryLists!$B:$B,A12)>0 -> FALSE | U12: =COUNTIF(CategoryLists!$C:$C,A12)>0 -> FALSE | V12: =COUNTIF(CategoryLists!$D:$D,A12)>0 -> FALSE | W12: =COUNTIF(CategoryLists!$E:$E,A12)>0 -> FALSE | X12: =COUNTIF(CategoryLists!$F:$F,A12)>0 -> FALSE | Y12: =COUNTIF(CategoryLists!$G:$G,A12)>0 -> FALSE | Z12: =LEFT(A12,3)="PMS" -> FALSE | AA12: =OR(LEFT(A12,3)="CKP",LEFT(A12,3)="PNL",COUNTIF(CategoryLists!$I:$I,A12)>0) -> FALSE | AB12: =COUNTIF(CategoryLists!$H:$H,A12)>0 -> FALSE | AC12: =AND(A12<>"",D12=0) -> TRUE | AD12: =COUNTIF(CategoryLists!$A:$A,A12)>0 -> FALSE
A13: ASS-B-ORTC40 | B13: Halimun Red (Organic)@50g/Tincan | C13: TIN | D13: 0 | E13: 0 | F13: 0 | G13: 0 | H13: 0 | I13: 0 | J13: 0 | K13: 0 | L13: 0 | M13: 0 | N13: 0 | O13: 0 | P13: 0 | T13: =COUNTIF(CategoryLists!$B:$B,A13)>0 -> FALSE | U13: =COUNTIF(CategoryLists!$C:$C,A13)>0 -> FALSE | V13: =COUNTIF(CategoryLists!$D:$D,A13)>0 -> FALSE | W13: =COUNTIF(CategoryLists!$E:$E,A13)>0 -> FALSE | X13: =COUNTIF(CategoryLists!$F:$F,A13)>0 -> FALSE | Y13: =COUNTIF(CategoryLists!$G:$G,A13)>0 -> FALSE | Z13: =LEFT(A13,3)="PMS" -> FALSE | AA13: =OR(LEFT(A13,3)="CKP",LEFT(A13,3)="PNL",COUNTIF(CategoryLists!$I:$I,A13)>0) -> FALSE | AB13: =COUNTIF(CategoryLists!$H:$H,A13)>0 -> FALSE | AC13: =AND(A13<>"",D13=0) -> TRUE | AD13: =COUNTIF(CategoryLists!$A:$A,A13)>0 -> FALSE
A14: ASS-BC-B10 | B14: Blackcurrant Tea @10TB/Box | C14: BOX | D14: 0 | E14: 0 | F14: 0 | G14: 0 | H14: 0 | I14: 0 | J14: 0 | K14: 0 | L14: 0 | M14: 0 | N14: 0 | O14: 0 | P14: 0 | T14: =COUNTIF(CategoryLists!$B:$B,A14)>0 -> FALSE | U14: =COUNTIF(CategoryLists!$C:$C,A14)>0 -> FALSE | V14: =COUNTIF(CategoryLists!$D:$D,A14)>0 -> FALSE | W14: =COUNTIF(CategoryLists!$E:$E,A14)>0 -> FALSE | X14: =COUNTIF(CategoryLists!$F:$F,A14)>0 -> FALSE | Y14: =COUNTIF(CategoryLists!$G:$G,A14)>0 -> FALSE | Z14: =LEFT(A14,3)="PMS" -> FALSE | AA14: =OR(LEFT(A14,3)="CKP",LEFT(A14,3)="PNL",COUNTIF(CategoryLists!$I:$I,A14)>0) -> FALSE | AB14: =COUNTIF(CategoryLists!$H:$H,A14)>0 -> FALSE | AC14: =AND(A14<>"",D14=0) -> TRUE | AD14: =COUNTIF(CategoryLists!$A:$A,A14)>0 -> FALSE
A15: ASS-BC-TB50 | B15: Blackcurrant Tea @50TB/Box | C15: BOX | D15: 2 | E15: 9 | F15: 12 | G15: 16 | H15: 12.3333 | I15: 0.1621 | J15: 4.8649 | K15: 9 | L15: 0.2222 | M15: 6.6666 | N15: 0 | O15: 0 | P15: 0 | Q15: 46248 | R15: 7 | T15: =COUNTIF(CategoryLists!$B:$B,A15)>0 -> FALSE | U15: =COUNTIF(CategoryLists!$C:$C,A15)>0 -> FALSE | V15: =COUNTIF(CategoryLists!$D:$D,A15)>0 -> FALSE | W15: =COUNTIF(CategoryLists!$E:$E,A15)>0 -> FALSE | X15: =COUNTIF(CategoryLists!$F:$F,A15)>0 -> FALSE | Y15: =COUNTIF(CategoryLists!$G:$G,A15)>0 -> FALSE | Z15: =LEFT(A15,3)="PMS" -> FALSE | AA15: =OR(LEFT(A15,3)="CKP",LEFT(A15,3)="PNL",COUNTIF(CategoryLists!$I:$I,A15)>0) -> FALSE | AB15: =COUNTIF(CategoryLists!$H:$H,A15)>0 -> FALSE | AC15: =AND(A15<>"",D15=0) -> FALSE | AD15: =COUNTIF(CategoryLists!$A:$A,A15)>0 -> FALSE
A16: ASS-BG-LP250 | B16: Ginger Blue Telang Tea @250gr/Pouch | C16: POU | D16: 0 | E16: 0 | F16: 0 | G16: 0 | H16: 0 | I16: 0 | J16: 0 | K16: 0 | L16: 0 | M16: 0 | N16: 0 | O16: 0 | P16: 0 | Q16: 44749 | R16: 1 | T16: =COUNTIF(CategoryLists!$B:$B,A16)>0 -> FALSE | U16: =COUNTIF(CategoryLists!$C:$C,A16)>0 -> FALSE | V16: =COUNTIF(CategoryLists!$D:$D,A16)>0 -> FALSE | W16: =COUNTIF(CategoryLists!$E:$E,A16)>0 -> FALSE | X16: =COUNTIF(CategoryLists!$F:$F,A16)>0 -> FALSE | Y16: =COUNTIF(CategoryLists!$G:$G,A16)>0 -> FALSE | Z16: =LEFT(A16,3)="PMS" -> FALSE | AA16: =OR(LEFT(A16,3)="CKP",LEFT(A16,3)="PNL",COUNTIF(CategoryLists!$I:$I,A16)>0) -> FALSE | AB16: =COUNTIF(CategoryLists!$H:$H,A16)>0 -> FALSE | AC16: =AND(A16<>"",D16=0) -> TRUE | AD16: =COUNTIF(CategoryLists!$A:$A,A16)>0 -> FALSE
A17: ASS-BO-LP250 | B17: Halimun Red (Organic)@250gr | C17: PACK | D17: 0 | E17: 0 | F17: 0 | G17: 0 | H17: 0 | I17: 0 | J17: 0 | K17: 0 | L17: 0 | M17: 0 | N17: 0 | O17: 0 | P17: 0 | T17: =COUNTIF(CategoryLists!$B:$B,A17)>0 -> FALSE | U17: =COUNTIF(CategoryLists!$C:$C,A17)>0 -> FALSE | V17: =COUNTIF(CategoryLists!$D:$D,A17)>0 -> FALSE | W17: =COUNTIF(CategoryLists!$E:$E,A17)>0 -> FALSE | X17: =COUNTIF(CategoryLists!$F:$F,A17)>0 -> FALSE | Y17: =COUNTIF(CategoryLists!$G:$G,A17)>0 -> FALSE | Z17: =LEFT(A17,3)="PMS" -> FALSE | AA17: =OR(LEFT(A17,3)="CKP",LEFT(A17,3)="PNL",COUNTIF(CategoryLists!$I:$I,A17)>0) -> FALSE | AB17: =COUNTIF(CategoryLists!$H:$H,A17)>0 -> FALSE | AC17: =AND(A17<>"",D17=0) -> TRUE | AD17: =COUNTIF(CategoryLists!$A:$A,A17)>0 -> FALSE
A18: ASS-BOP-L501 | B18: Golden Ring (BOP) @500gr | C18: PACK | D18: 0 | E18: 0 | F18: 0 | G18: 0 | H18: 0 | I18: 0 | J18: 0 | K18: 0 | L18: 0 | M18: 0 | N18: 0 | O18: 0 | P18: 0 | T18: =COUNTIF(CategoryLists!$B:$B,A18)>0 -> FALSE | U18: =COUNTIF(CategoryLists!$C:$C,A18)>0 -> FALSE | V18: =COUNTIF(CategoryLists!$D:$D,A18)>0 -> FALSE | W18: =COUNTIF(CategoryLists!$E:$E,A18)>0 -> FALSE | X18: =COUNTIF(CategoryLists!$F:$F,A18)>0 -> FALSE | Y18: =COUNTIF(CategoryLists!$G:$G,A18)>0 -> FALSE | Z18: =LEFT(A18,3)="PMS" -> FALSE | AA18: =OR(LEFT(A18,3)="CKP",LEFT(A18,3)="PNL",COUNTIF(CategoryLists!$I:$I,A18)>0) -> FALSE | AB18: =COUNTIF(CategoryLists!$H:$H,A18)>0 -> FALSE | AC18: =AND(A18<>"",D18=0) -> TRUE | AD18: =COUNTIF(CategoryLists!$A:$A,A18)>0 -> FALSE
A19: ASS-BT-100TB | B19: Black Tea @100TB/Box | C19: BOX | D19: 14 | E19: 12 | F19: 12 | G19: 0 | H19: 12 | I19: 1.1666 | J19: 35 | K19: 0 | L19: 0 | M19: 0 | N19: 0 | O19: 0 | P19: 0 | Q19: 46244 | R19: 11 | S19: 20 | T19: =COUNTIF(CategoryLists!$B:$B,A19)>0 -> FALSE | U19: =COUNTIF(CategoryLists!$C:$C,A19)>0 -> FALSE | V19: =COUNTIF(CategoryLists!$D:$D,A19)>0 -> FALSE | W19: =COUNTIF(CategoryLists!$E:$E,A19)>0 -> FALSE | X19: =COUNTIF(CategoryLists!$F:$F,A19)>0 -> FALSE | Y19: =COUNTIF(CategoryLists!$G:$G,A19)>0 -> FALSE | Z19: =LEFT(A19,3)="PMS" -> FALSE | AA19: =OR(LEFT(A19,3)="CKP",LEFT(A19,3)="PNL",COUNTIF(CategoryLists!$I:$I,A19)>0) -> FALSE | AB19: =COUNTIF(CategoryLists!$H:$H,A19)>0 -> FALSE | AC19: =AND(A19<>"",D19=0) -> FALSE | AD19: =COUNTIF(CategoryLists!$A:$A,A19)>0 -> FALSE
A20: ASS-BT-L1001 | B20: Bunaken Blue Tea @250g | C20: PACK | D20: 0 | E20: 0 | F20: 0 | G20: 0 | H20: 0 | I20: 0 | J20: 0 | K20: 0 | L20: 0 | M20: 0 | N20: 0 | O20: 0 | P20: 0 | Q20: 45014 | R20: 5 | T20: =COUNTIF(CategoryLists!$B:$B,A20)>0 -> FALSE | U20: =COUNTIF(CategoryLists!$C:$C,A20)>0 -> FALSE | V20: =COUNTIF(CategoryLists!$D:$D,A20)>0 -> FALSE | W20: =COUNTIF(CategoryLists!$E:$E,A20)>0 -> FALSE | X20: =COUNTIF(CategoryLists!$F:$F,A20)>0 -> FALSE | Y20: =COUNTIF(CategoryLists!$G:$G,A20)>0 -> FALSE | Z20: =LEFT(A20,3)="PMS" -> FALSE | AA20: =OR(LEFT(A20,3)="CKP",LEFT(A20,3)="PNL",COUNTIF(CategoryLists!$I:$I,A20)>0) -> FALSE | AB20: =COUNTIF(CategoryLists!$H:$H,A20)>0 -> FALSE | AC20: =AND(A20<>"",D20=0) -> TRUE | AD20: =COUNTIF(CategoryLists!$A:$A,A20)>0 -> FALSE
A21: ASS-BT-TC30 | B21: Bunaken Blue Tea@30g/Tincan | C21: TIN | D21: 0 | E21: 0 | F21: 0 | G21: 0 | H21: 0 | I21: 0 | J21: 0 | K21: 0 | L21: 0 | M21: 0 | N21: 0 | O21: 0 | P21: 0 | T21: =COUNTIF(CategoryLists!$B:$B,A21)>0 -> FALSE | U21: =COUNTIF(CategoryLists!$C:$C,A21)>0 -> FALSE | V21: =COUNTIF(CategoryLists!$D:$D,A21)>0 -> FALSE | W21: =COUNTIF(CategoryLists!$E:$E,A21)>0 -> FALSE | X21: =COUNTIF(CategoryLists!$F:$F,A21)>0 -> FALSE | Y21: =COUNTIF(CategoryLists!$G:$G,A21)>0 -> FALSE | Z21: =LEFT(A21,3)="PMS" -> FALSE | AA21: =OR(LEFT(A21,3)="CKP",LEFT(A21,3)="PNL",COUNTIF(CategoryLists!$I:$I,A21)>0) -> FALSE | AB21: =COUNTIF(CategoryLists!$H:$H,A21)>0 -> FALSE | AC21: =AND(A21<>"",D21=0) -> TRUE | AD21: =COUNTIF(CategoryLists!$A:$A,A21)>0 -> FALSE
A22: ASS-BT-TP15 | B22: Bunaken Blue Tea@10PBx1.5g/Tincan | C22: TIN | D22: 0 | E22: 0 | F22: 0 | G22: 0 | H22: 0 | I22: 0 | J22: 0 | K22: 0 | L22: 0 | M22: 0 | N22: 0 | O22: 0 | P22: 0 | T22: =COUNTIF(CategoryLists!$B:$B,A22)>0 -> FALSE | U22: =COUNTIF(CategoryLists!$C:$C,A22)>0 -> FALSE | V22: =COUNTIF(CategoryLists!$D:$D,A22)>0 -> FALSE | W22: =COUNTIF(CategoryLists!$E:$E,A22)>0 -> FALSE | X22: =COUNTIF(CategoryLists!$F:$F,A22)>0 -> FALSE | Y22: =COUNTIF(CategoryLists!$G:$G,A22)>0 -> FALSE | Z22: =LEFT(A22,3)="PMS" -> FALSE | AA22: =OR(LEFT(A22,3)="CKP",LEFT(A22,3)="PNL",COUNTIF(CategoryLists!$I:$I,A22)>0) -> FALSE | AB22: =COUNTIF(CategoryLists!$H:$H,A22)>0 -> FALSE | AC22: =AND(A22<>"",D22=0) -> TRUE | AD22: =COUNTIF(CategoryLists!$A:$A,A22)>0 -> FALSE
A23: ASS-CBT | B23: Classic Black Tea @50TB/Box | C23: BOX | D23: 11 | E23: 3 | F23: 2 | G23: 3 | H23: 2.6666 | I23: 4.1251 | J23: 123.8738 | K23: 0 | L23: 0 | M23: 0 | N23: 0 | O23: 0 | P23: 0 | Q23: 46248 | R23: 7 | S23: 4 | T23: =COUNTIF(CategoryLists!$B:$B,A23)>0 -> FALSE | U23: =COUNTIF(CategoryLists!$C:$C,A23)>0 -> FALSE | V23: =COUNTIF(CategoryLists!$D:$D,A23)>0 -> FALSE | W23: =COUNTIF(CategoryLists!$E:$E,A23)>0 -> FALSE | X23: =COUNTIF(CategoryLists!$F:$F,A23)>0 -> FALSE | Y23: =COUNTIF(CategoryLists!$G:$G,A23)>0 -> FALSE | Z23: =LEFT(A23,3)="PMS" -> FALSE | AA23: =OR(LEFT(A23,3)="CKP",LEFT(A23,3)="PNL",COUNTIF(CategoryLists!$I:$I,A23)>0) -> FALSE | AB23: =COUNTIF(CategoryLists!$H:$H,A23)>0 -> FALSE | AC23: =AND(A23<>"",D23=0) -> FALSE | AD23: =COUNTIF(CategoryLists!$A:$A,A23)>0 -> FALSE
A24: ASS-CBT10 | B24: Classic Black Tea@10TB/Box | C24: BOX | D24: 0 | E24: 0 | F24: 0 | G24: 0 | H24: 0 | I24: 0 | J24: 0 | K24: 0 | L24: 0 | M24: 0 | N24: 0 | O24: 0 | P24: 0 | T24: =COUNTIF(CategoryLists!$B:$B,A24)>0 -> FALSE | U24: =COUNTIF(CategoryLists!$C:$C,A24)>0 -> FALSE | V24: =COUNTIF(CategoryLists!$D:$D,A24)>0 -> FALSE | W24: =COUNTIF(CategoryLists!$E:$E,A24)>0 -> FALSE | X24: =COUNTIF(CategoryLists!$F:$F,A24)>0 -> FALSE | Y24: =COUNTIF(CategoryLists!$G:$G,A24)>0 -> FALSE | Z24: =LEFT(A24,3)="PMS" -> FALSE | AA24: =OR(LEFT(A24,3)="CKP",LEFT(A24,3)="PNL",COUNTIF(CategoryLists!$I:$I,A24)>0) -> FALSE | AB24: =COUNTIF(CategoryLists!$H:$H,A24)>0 -> FALSE | AC24: =AND(A24<>"",D24=0) -> TRUE | AD24: =COUNTIF(CategoryLists!$A:$A,A24)>0 -> FALSE
A25: ASS-CH-L250 | B25: Chamomile Dream @250gr | C25: PACK | D25: 7 | E25: 7 | F25: 7 | G25: 7 | H25: 7 | I25: 1 | J25: 30.0042 | K25: 14 | L25: 0.5 | M25: 15.0021 | N25: 0 | O25: 0 | P25: 0 | Q25: 46266 | R25: 4 | T25: =COUNTIF(CategoryLists!$B:$B,A25)>0 -> FALSE | U25: =COUNTIF(CategoryLists!$C:$C,A25)>0 -> FALSE | V25: =COUNTIF(CategoryLists!$D:$D,A25)>0 -> FALSE | W25: =COUNTIF(CategoryLists!$E:$E,A25)>0 -> FALSE | X25: =COUNTIF(CategoryLists!$F:$F,A25)>0 -> FALSE | Y25: =COUNTIF(CategoryLists!$G:$G,A25)>0 -> FALSE | Z25: =LEFT(A25,3)="PMS" -> FALSE | AA25: =OR(LEFT(A25,3)="CKP",LEFT(A25,3)="PNL",COUNTIF(CategoryLists!$I:$I,A25)>0) -> FALSE | AB25: =COUNTIF(CategoryLists!$H:$H,A25)>0 -> FALSE | AC25: =AND(A25<>"",D25=0) -> FALSE | AD25: =COUNTIF(CategoryLists!$A:$A,A25)>0 -> FALSE
A26: ASS-CH-LPPO | B26: Chamomile Dream @50Pbx3g | C26: POU | D26: 0 | E26: 0 | F26: 0 | G26: 0 | H26: 0 | I26: 0 | J26: 0 | K26: 0 | L26: 0 | M26: 0 | N26: 0 | O26: 0 | P26: 0 | T26: =COUNTIF(CategoryLists!$B:$B,A26)>0 -> FALSE | U26: =COUNTIF(CategoryLists!$C:$C,A26)>0 -> FALSE | V26: =COUNTIF(CategoryLists!$D:$D,A26)>0 -> FALSE | W26: =COUNTIF(CategoryLists!$E:$E,A26)>0 -> FALSE | X26: =COUNTIF(CategoryLists!$F:$F,A26)>0 -> FALSE | Y26: =COUNTIF(CategoryLists!$G:$G,A26)>0 -> FALSE | Z26: =LEFT(A26,3)="PMS" -> FALSE | AA26: =OR(LEFT(A26,3)="CKP",LEFT(A26,3)="PNL",COUNTIF(CategoryLists!$I:$I,A26)>0) -> FALSE | AB26: =COUNTIF(CategoryLists!$H:$H,A26)>0 -> FALSE | AC26: =AND(A26<>"",D26=0) -> TRUE | AD26: =COUNTIF(CategoryLists!$A:$A,A26)>0 -> FALSE
A27: ASS-CH-TB25 | B27: Chamomile Dream @25Tb/Tincan - Grand Hyatt | C27: TIN | D27: 0 | E27: 0 | F27: 0 | G27: 0 | H27: 0 | I27: 0 | J27: 0 | K27: 0 | L27: 0 | M27: 0 | N27: 0 | O27: 0 | P27: 0 | Q27: 44741 | R27: 18 | S27: 10 | T27: =COUNTIF(CategoryLists!$B:$B,A27)>0 -> FALSE | U27: =COUNTIF(CategoryLists!$C:$C,A27)>0 -> FALSE | V27: =COUNTIF(CategoryLists!$D:$D,A27)>0 -> FALSE | W27: =COUNTIF(CategoryLists!$E:$E,A27)>0 -> FALSE | X27: =COUNTIF(CategoryLists!$F:$F,A27)>0 -> FALSE | Y27: =COUNTIF(CategoryLists!$G:$G,A27)>0 -> FALSE | Z27: =LEFT(A27,3)="PMS" -> FALSE | AA27: =OR(LEFT(A27,3)="CKP",LEFT(A27,3)="PNL",COUNTIF(CategoryLists!$I:$I,A27)>0) -> FALSE | AB27: =COUNTIF(CategoryLists!$H:$H,A27)>0 -> FALSE | AC27: =AND(A27<>"",D27=0) -> TRUE | AD27: =COUNTIF(CategoryLists!$A:$A,A27)>0 -> FALSE
A28: ASS-CH-TB50 | B28: Chamomile Dream @50Tb/Box | C28: BOX | D28: 144 | E28: 151 | F28: 256 | G28: 110 | H28: 172.3333 | I28: 0.8355 | J28: 25.0678 | K28: 162 | L28: 0.8888 | M28: 26.6666 | N28: 14 | O28: 0.685 | P28: 20.5714 | Q28: 46248 | R28: 25 | T28: =COUNTIF(CategoryLists!$B:$B,A28)>0 -> FALSE | U28: =COUNTIF(CategoryLists!$C:$C,A28)>0 -> FALSE | V28: =COUNTIF(CategoryLists!$D:$D,A28)>0 -> FALSE | W28: =COUNTIF(CategoryLists!$E:$E,A28)>0 -> FALSE | X28: =COUNTIF(CategoryLists!$F:$F,A28)>0 -> FALSE | Y28: =COUNTIF(CategoryLists!$G:$G,A28)>0 -> FALSE | Z28: =LEFT(A28,3)="PMS" -> FALSE | AA28: =OR(LEFT(A28,3)="CKP",LEFT(A28,3)="PNL",COUNTIF(CategoryLists!$I:$I,A28)>0) -> FALSE | AB28: =COUNTIF(CategoryLists!$H:$H,A28)>0 -> FALSE | AC28: =AND(A28<>"",D28=0) -> FALSE | AD28: =COUNTIF(CategoryLists!$A:$A,A28)>0 -> FALSE
A29: ASS-CH-TP15 | B29: Chamomile Dream@10PBx1.5g/Tincan | C29: TIN | D29: 0 | E29: 0 | F29: 0 | G29: 0 | H29: 0 | I29: 0 | J29: 0 | K29: 0 | L29: 0 | M29: 0 | N29: 0 | O29: 0 | P29: 0 | T29: =COUNTIF(CategoryLists!$B:$B,A29)>0 -> FALSE | U29: =COUNTIF(CategoryLists!$C:$C,A29)>0 -> FALSE | V29: =COUNTIF(CategoryLists!$D:$D,A29)>0 -> FALSE | W29: =COUNTIF(CategoryLists!$E:$E,A29)>0 -> FALSE | X29: =COUNTIF(CategoryLists!$F:$F,A29)>0 -> FALSE | Y29: =COUNTIF(CategoryLists!$G:$G,A29)>0 -> FALSE | Z29: =LEFT(A29,3)="PMS" -> FALSE | AA29: =OR(LEFT(A29,3)="CKP",LEFT(A29,3)="PNL",COUNTIF(CategoryLists!$I:$I,A29)>0) -> FALSE | AB29: =COUNTIF(CategoryLists!$H:$H,A29)>0 -> FALSE | AC29: =AND(A29<>"",D29=0) -> TRUE | AD29: =COUNTIF(CategoryLists!$A:$A,A29)>0 -> FALSE
A30: ASS-CHTB10 | B30: Chamomile Dream @10Tb/Box | C30: BOX | D30: 16 | E30: 36 | F30: 37 | G30: 12 | H30: 28.3333 | I30: 0.5647 | J30: 16.9419 | K30: 30 | L30: 0.5333 | M30: 16 | N30: 25 | O30: 0.0426 | P30: 1.28 | Q30: 46266 | R30: 15 | S30: 356 | T30: =COUNTIF(CategoryLists!$B:$B,A30)>0 -> FALSE | U30: =COUNTIF(CategoryLists!$C:$C,A30)>0 -> FALSE | V30: =COUNTIF(CategoryLists!$D:$D,A30)>0 -> FALSE | W30: =COUNTIF(CategoryLists!$E:$E,A30)>0 -> FALSE | X30: =COUNTIF(CategoryLists!$F:$F,A30)>0 -> FALSE | Y30: =COUNTIF(CategoryLists!$G:$G,A30)>0 -> FALSE | Z30: =LEFT(A30,3)="PMS" -> FALSE | AA30: =OR(LEFT(A30,3)="CKP",LEFT(A30,3)="PNL",COUNTIF(CategoryLists!$I:$I,A30)>0) -> FALSE | AB30: =COUNTIF(CategoryLists!$H:$H,A30)>0 -> FALSE | AC30: =AND(A30<>"",D30=0) -> FALSE | AD30: =COUNTIF(CategoryLists!$A:$A,A30)>0 -> FALSE
A31: ASS-CM-LP250 | B31: Chamomile @250gr/Pouch | C31: POU | D31: 0 | E31: 0 | F31: 0 | G31: 0 | H31: 0 | I31: 0 | J31: 0 | K31: 0 | L31: 0 | M31: 0 | N31: 0 | O31: 0 | P31: 0 | Q31: 45306 | R31: 10 | T31: =COUNTIF(CategoryLists!$B:$B,A31)>0 -> FALSE | U31: =COUNTIF(CategoryLists!$C:$C,A31)>0 -> FALSE | V31: =COUNTIF(CategoryLists!$D:$D,A31)>0 -> FALSE | W31: =COUNTIF(CategoryLists!$E:$E,A31)>0 -> FALSE | X31: =COUNTIF(CategoryLists!$F:$F,A31)>0 -> FALSE | Y31: =COUNTIF(CategoryLists!$G:$G,A31)>0 -> FALSE | Z31: =LEFT(A31,3)="PMS" -> FALSE | AA31: =OR(LEFT(A31,3)="CKP",LEFT(A31,3)="PNL",COUNTIF(CategoryLists!$I:$I,A31)>0) -> FALSE | AB31: =COUNTIF(CategoryLists!$H:$H,A31)>0 -> FALSE | AC31: =AND(A31<>"",D31=0) -> TRUE | AD31: =COUNTIF(CategoryLists!$A:$A,A31)>0 -> FALSE
A32: ASS-EB-LP250 | B32: English Breakfast @250gr/Pouch | C32: POU | D32: 38 | E32: 63 | F32: 69 | G32: 58 | H32: 63.3333 | I32: 0.6 | J32: 18 | K32: 48 | L32: 0.7916 | M32: 23.75 | N32: 7 | O32: 0.3615 | P32: 10.8571 | Q32: 46266 | R32: 20 | S32: 2 | T32: =COUNTIF(CategoryLists!$B:$B,A32)>0 -> FALSE | U32: =COUNTIF(CategoryLists!$C:$C,A32)>0 -> FALSE | V32: =COUNTIF(CategoryLists!$D:$D,A32)>0 -> FALSE | W32: =COUNTIF(CategoryLists!$E:$E,A32)>0 -> FALSE | X32: =COUNTIF(CategoryLists!$F:$F,A32)>0 -> FALSE | Y32: =COUNTIF(CategoryLists!$G:$G,A32)>0 -> FALSE | Z32: =LEFT(A32,3)="PMS" -> FALSE | AA32: =OR(LEFT(A32,3)="CKP",LEFT(A32,3)="PNL",COUNTIF(CategoryLists!$I:$I,A32)>0) -> FALSE | AB32: =COUNTIF(CategoryLists!$H:$H,A32)>0 -> FALSE | AC32: =AND(A32<>"",D32=0) -> FALSE | AD32: =COUNTIF(CategoryLists!$A:$A,A32)>0 -> FALSE
A33: ASS-EBT | B33: English Breakfast@50TB/Box | C33: BOX | D33: 155 | E33: 392 | F33: 475 | G33: 506 | H33: 457.6666 | I33: 0.3386 | J33: 10.1602 | K33: 422 | L33: 0.3672 | M33: 11.019 | N33: 25 | O33: 0.4129 | P33: 12.4 | Q33: 46266 | R33: 30 | S33: 76 | T33: =COUNTIF(CategoryLists!$B:$B,A33)>0 -> FALSE | U33: =COUNTIF(CategoryLists!$C:$C,A33)>0 -> FALSE | V33: =COUNTIF(CategoryLists!$D:$D,A33)>0 -> FALSE | W33: =COUNTIF(CategoryLists!$E:$E,A33)>0 -> FALSE | X33: =COUNTIF(CategoryLists!$F:$F,A33)>0 -> FALSE | Y33: =COUNTIF(CategoryLists!$G:$G,A33)>0 -> FALSE | Z33: =LEFT(A33,3)="PMS" -> FALSE | AA33: =OR(LEFT(A33,3)="CKP",LEFT(A33,3)="PNL",COUNTIF(CategoryLists!$I:$I,A33)>0) -> FALSE | AB33: =COUNTIF(CategoryLists!$H:$H,A33)>0 -> FALSE | AC33: =AND(A33<>"",D33=0) -> FALSE | AD33: =COUNTIF(CategoryLists!$A:$A,A33)>0 -> FALSE
A34: ASS-EBT-20 | B34: English Breakfast@20tb/box | C34: BOX | D34: 15 | E34: 0 | F34: 0 | G34: 0 | H34: 0 | I34: 0 | J34: 0 | K34: 0 | L34: 0 | M34: 0 | N34: 0 | O34: 0 | P34: 0 | Q34: 46190 | R34: 15 | S34: 20 | T34: =COUNTIF(CategoryLists!$B:$B,A34)>0 -> FALSE | U34: =COUNTIF(CategoryLists!$C:$C,A34)>0 -> FALSE | V34: =COUNTIF(CategoryLists!$D:$D,A34)>0 -> FALSE | W34: =COUNTIF(CategoryLists!$E:$E,A34)>0 -> FALSE | X34: =COUNTIF(CategoryLists!$F:$F,A34)>0 -> FALSE | Y34: =COUNTIF(CategoryLists!$G:$G,A34)>0 -> FALSE | Z34: =LEFT(A34,3)="PMS" -> FALSE | AA34: =OR(LEFT(A34,3)="CKP",LEFT(A34,3)="PNL",COUNTIF(CategoryLists!$I:$I,A34)>0) -> FALSE | AB34: =COUNTIF(CategoryLists!$H:$H,A34)>0 -> FALSE | AC34: =AND(A34<>"",D34=0) -> FALSE | AD34: =COUNTIF(CategoryLists!$A:$A,A34)>0 -> FALSE
A35: ASS-EBT-G | B35: English Breakfast@50TB/Box - Grand Hyatt | C35: BOX | D35: 0 | E35: 0 | F35: 0 | G35: 0 | H35: 0 | I35: 0 | J35: 0 | K35: 0 | L35: 0 | M35: 0 | N35: 0 | O35: 0 | P35: 0 | Q35: 45482 | R35: 100 | S35: 400 | T35: =COUNTIF(CategoryLists!$B:$B,A35)>0 -> FALSE | U35: =COUNTIF(CategoryLists!$C:$C,A35)>0 -> FALSE | V35: =COUNTIF(CategoryLists!$D:$D,A35)>0 -> FALSE | W35: =COUNTIF(CategoryLists!$E:$E,A35)>0 -> FALSE | X35: =COUNTIF(CategoryLists!$F:$F,A35)>0 -> FALSE | Y35: =COUNTIF(CategoryLists!$G:$G,A35)>0 -> FALSE | Z35: =LEFT(A35,3)="PMS" -> FALSE | AA35: =OR(LEFT(A35,3)="CKP",LEFT(A35,3)="PNL",COUNTIF(CategoryLists!$I:$I,A35)>0) -> FALSE | AB35: =COUNTIF(CategoryLists!$H:$H,A35)>0 -> FALSE | AC35: =AND(A35<>"",D35=0) -> TRUE | AD35: =COUNTIF(CategoryLists!$A:$A,A35)>0 -> FALSE
A36: ASS-EBT10 | B36: English Breakfast @10TB/Box | C36: BOX | D36: 0 | E36: 0 | F36: 0 | G36: 0 | H36: 0 | I36: 0 | J36: 0 | K36: 0 | L36: 0 | M36: 0 | N36: 0 | O36: 0 | P36: 0 | T36: =COUNTIF(CategoryLists!$B:$B,A36)>0 -> FALSE | U36: =COUNTIF(CategoryLists!$C:$C,A36)>0 -> FALSE | V36: =COUNTIF(CategoryLists!$D:$D,A36)>0 -> FALSE | W36: =COUNTIF(CategoryLists!$E:$E,A36)>0 -> FALSE | X36: =COUNTIF(CategoryLists!$F:$F,A36)>0 -> FALSE | Y36: =COUNTIF(CategoryLists!$G:$G,A36)>0 -> FALSE | Z36: =LEFT(A36,3)="PMS" -> FALSE | AA36: =OR(LEFT(A36,3)="CKP",LEFT(A36,3)="PNL",COUNTIF(CategoryLists!$I:$I,A36)>0) -> FALSE | AB36: =COUNTIF(CategoryLists!$H:$H,A36)>0 -> FALSE | AC36: =AND(A36<>"",D36=0) -> TRUE | AD36: =COUNTIF(CategoryLists!$A:$A,A36)>0 -> FALSE
A37: ASS-EG-10 | B37: Earl Grey @10TB/Box | C37: BOX | D37: 7 | E37: 0 | F37: 13 | G37: 6 | H37: 9.5 | I37: 0.7368 | J37: 22.1099 | K37: 0 | L37: 0 | M37: 0 | N37: 8 | O37: 0.0582 | P37: 1.75 | Q37: 46266 | R37: 6 | S37: 195 | T37: =COUNTIF(CategoryLists!$B:$B,A37)>0 -> FALSE | U37: =COUNTIF(CategoryLists!$C:$C,A37)>0 -> FALSE | V37: =COUNTIF(CategoryLists!$D:$D,A37)>0 -> FALSE | W37: =COUNTIF(CategoryLists!$E:$E,A37)>0 -> FALSE | X37: =COUNTIF(CategoryLists!$F:$F,A37)>0 -> FALSE | Y37: =COUNTIF(CategoryLists!$G:$G,A37)>0 -> FALSE | Z37: =LEFT(A37,3)="PMS" -> FALSE | AA37: =OR(LEFT(A37,3)="CKP",LEFT(A37,3)="PNL",COUNTIF(CategoryLists!$I:$I,A37)>0) -> FALSE | AB37: =COUNTIF(CategoryLists!$H:$H,A37)>0 -> FALSE | AC37: =AND(A37<>"",D37=0) -> FALSE | AD37: =COUNTIF(CategoryLists!$A:$A,A37)>0 -> FALSE
A38: ASS-EG-LP250 | B38: Earl Grey @250gr | C38: PACK | D38: 6 | E38: 7 | F38: 12 | G38: 13 | H38: 10.6666 | I38: 0.5625 | J38: 16.8776 | K38: 16 | L38: 0.375 | M38: 11.2507 | N38: 2 | O38: 0.1998 | P38: 6 | Q38: 46266 | R38: 5 | S38: 10 | T38: =COUNTIF(CategoryLists!$B:$B,A38)>0 -> FALSE | U38: =COUNTIF(CategoryLists!$C:$C,A38)>0 -> FALSE | V38: =COUNTIF(CategoryLists!$D:$D,A38)>0 -> FALSE | W38: =COUNTIF(CategoryLists!$E:$E,A38)>0 -> FALSE | X38: =COUNTIF(CategoryLists!$F:$F,A38)>0 -> FALSE | Y38: =COUNTIF(CategoryLists!$G:$G,A38)>0 -> FALSE | Z38: =LEFT(A38,3)="PMS" -> FALSE | AA38: =OR(LEFT(A38,3)="CKP",LEFT(A38,3)="PNL",COUNTIF(CategoryLists!$I:$I,A38)>0) -> FALSE | AB38: =COUNTIF(CategoryLists!$H:$H,A38)>0 -> FALSE | AC38: =AND(A38<>"",D38=0) -> FALSE | AD38: =COUNTIF(CategoryLists!$A:$A,A38)>0 -> FALSE
A39: ASS-EG-LPP50 | B39: Earl Greay @50Pbx3g | C39: POU | D39: 0 | E39: 0 | F39: 0 | G39: 0 | H39: 0 | I39: 0 | J39: 0 | K39: 0 | L39: 0 | M39: 0 | N39: 0 | O39: 0 | P39: 0 | T39: =COUNTIF(CategoryLists!$B:$B,A39)>0 -> FALSE | U39: =COUNTIF(CategoryLists!$C:$C,A39)>0 -> FALSE | V39: =COUNTIF(CategoryLists!$D:$D,A39)>0 -> FALSE | W39: =COUNTIF(CategoryLists!$E:$E,A39)>0 -> FALSE | X39: =COUNTIF(CategoryLists!$F:$F,A39)>0 -> FALSE | Y39: =COUNTIF(CategoryLists!$G:$G,A39)>0 -> FALSE | Z39: =LEFT(A39,3)="PMS" -> FALSE | AA39: =OR(LEFT(A39,3)="CKP",LEFT(A39,3)="PNL",COUNTIF(CategoryLists!$I:$I,A39)>0) -> FALSE | AB39: =COUNTIF(CategoryLists!$H:$H,A39)>0 -> FALSE | AC39: =AND(A39<>"",D39=0) -> TRUE | AD39: =COUNTIF(CategoryLists!$A:$A,A39)>0 -> FALSE
A40: ASS-EG-TC60 | B40: Earl Grey @60g/Tincan | C40: TIN | D40: 0 | E40: 0 | F40: 0 | G40: 0 | H40: 0 | I40: 0 | J40: 0 | K40: 0 | L40: 0 | M40: 0 | N40: 0 | O40: 0 | P40: 0 | T40: =COUNTIF(CategoryLists!$B:$B,A40)>0 -> FALSE | U40: =COUNTIF(CategoryLists!$C:$C,A40)>0 -> FALSE | V40: =COUNTIF(CategoryLists!$D:$D,A40)>0 -> FALSE | W40: =COUNTIF(CategoryLists!$E:$E,A40)>0 -> FALSE | X40: =COUNTIF(CategoryLists!$F:$F,A40)>0 -> FALSE | Y40: =COUNTIF(CategoryLists!$G:$G,A40)>0 -> FALSE | Z40: =LEFT(A40,3)="PMS" -> FALSE | AA40: =OR(LEFT(A40,3)="CKP",LEFT(A40,3)="PNL",COUNTIF(CategoryLists!$I:$I,A40)>0) -> FALSE | AB40: =COUNTIF(CategoryLists!$H:$H,A40)>0 -> FALSE | AC40: =AND(A40<>"",D40=0) -> TRUE | AD40: =COUNTIF(CategoryLists!$A:$A,A40)>0 -> FALSE
...

Sheet CategoryLists
A1: Butter | B1: Pristine | C1: OSole | D1: Osterberg | E1: AgristoMaestro | F1: Soejasch | G1: IQF | H1: SavisPAS | I1: Mikol_Exceptions
A2: PEA0004 | B2: PIF0012 | C2: POS0031 | D2: POS0004 | E2: PAS0014 | F2: MRD1318A | G2: PQW0004 | H2: PAS0069 | I2: 010244
A3: PEA0003 | B3: PIF0011 | C3: POS0028 | D3: POS0010 | E3: PAS0053 | F3: MRD0430D | G3: PQW0010 | H3: PAS0068 | I3: 010245
A4: PEA0006 | B4: PIF0006 | C4: POS0027 | D4: POS0001 | E4: PAS0044 | F4: MRD0430D1 | G4: PQW0012 | H4: PAS0070 | I4: POT0001
A5: POT0046 | B5: PIF0007 | C5: POS0026 | D5: POS0002 | E5: PAS0015 | F5: MRD0430D3 | G5: PQW0013 | H5: PAS0047 | I5: POT0009
A6: PEA0010 | B6: PIF0013 | C6: POS0024 | D6: POS0003 | E6: PAS0036 | F6: PSJ0029 | G6: PQW0001 | H6: PAS0007 | I6: POT0044
A7: PEA0005 | B7: PIF0014 | C7: POS0025 | D7: POS0005 | E7: PAS0022 | F7: PSJ0027 | G7: PQW0002 | H7: PAS0067 | I7: POT0045
A8: PEA0007 | C8: POS0029 | D8: POS0006 | E8: PAS0049 | F8: PSJ0019 | G8: PQW0003 | H8: PAS0008 | I8: POT0053
A9: PAN0001 | C9: POS0030 | D9: POS0007 | E9: PAS0039 | F9: PSJ0024 | G9: PQW0005 | H9: PAS0052 | I9: POT0054
A10: PEA0008 | C10: POS0032 | D10: POS0008 | E10: PAS0048 | F10: PSJ0020 | G10: PQW0006 | H10: PAS0005 | I10: POT0055
A11: POT0049 | C11: POS0033 | D11: POS0009 | E11: PAS0037 | F11: PSJ0021 | G11: PQW0007 | H11: PAS0006 | I11: POT0056
A12: PAG0004 | C12: POS0034 | D12: POS0011 | E12: PAS0051 | F12: PSJ0023 | G12: PQW0008 | H12: PAS0012 | I12: POT0057
A13: BKL1533-18 | C13: POS0035 | D13: POS0012 | E13: PAS0031 | F13: PSJ0025 | G13: PQW0009 | H13: PAS0013 | I13: POT0058
A14: PAG0001 | C14: POS0036 | D14: POS0013 | E14: PAS0043 | F14: PSJ0026 | G14: PQW0011 | H14: PAS0062 | I14: POT0059
A15: PAG0002 | C15: POS0037 | D15: POS0014 | E15: PAS0064 | F15: PSJ0022 | H15: PAS0025 | I15: POT0093
A16: PEA0001 | C16: POS0038 | D16: POS0015 | E16: PAS0035 | F16: PSJ0002 | I16: POT0094
A17: PEA0002 | C17: POS0039 | D17: POS0016 | E17: PAS0011 | F17: PSJ0003 | I17: POT0095
D18: POS0017 | E18: PAS0026 | F18: PSJ0004 | I18: POT0096
D19: POS0018 | E19: PAS0027 | F19: PSJ0005 | I19: POT0097
D20: POS0019 | E20: PAS0032 | F20: PSJ0006 | I20: POT0101
D21: POS0020 | E21: PAS0034 | F21: PSJ0007 | I21: POT0103
D22: POS0021 | E22: PAS0040 | F22: PSJ0008
D23: POS0022 | E23: PAS0041 | F23: PSJ0009
D24: POS0023 | E24: PAS0042 | F24: PSJ0011
E25: PAS0050 | F25: PSJ0012
E26: PAS0065 | F26: PSJ0013
F27: PSJ0014
F28: PSJ0015
F29: PSJ0016
F30: PSJ0017
F31: PSJ0018

Sheet Butter
A1: =Data!A1 -> Kode_Brg | B1: =Data!B1 -> Nama_Brg | C1: =Data!C1 -> Kode_sat_Std | D1: =Data!D1 -> Saldo Akhir (Std) | E1: =Data!H1 -> Rata - Rata 3 Bulan | F1: =Data!J1 -> Buffer Day (3 Bulan) | G1: =Data!N1 -> Penjualan Tgl 1 sd 02 Sep 2026 | H1: =Data!P1 -> Buffer Day (Tgl 1 sd 02 Sep 2026) | J1: Helper: Data row# (auto)
A2: {=IFERROR(INDEX(Data!$A$2:$A$5000,$J2),IF(ROW()=2,"No data",""))} -> PEA0004 | B2: {=IFERROR(INDEX(Data!$B$2:$B$5000,$J2),"")} -> Gold Box Extra Butter MP341 | C2: {=IFERROR(INDEX(Data!$C$2:$C$5000,$J2),"")} -> KG | D2: {=IFERROR(INDEX(Data!$D$2:$D$5000,$J2),"")} -> 4300 | E2: {=IFERROR(INDEX(Data!$H$2:$H$5000,$J2),"")} -> 2100 | F2: {=IFERROR(INDEX(Data!$J$2:$J$5000,$J2),"")} -> 61.4285 | G2: {=IFERROR(INDEX(Data!$N$2:$N$5000,$J2),"")} -> 75 | H2: {=IFERROR(INDEX(Data!$P$2:$P$5000,$J2),"")} -> 114.6666 | J2: {=IFERROR(MATCH(_xlfn.AGGREGATE(14,6,(Data!$D$2:$D$5000-ROW(Data!$D$2:$D$5000)*0.0000001)/(--(Data!$AD$2:$AD$5000)),ROW()-1),(Data!$D$2:$D$5000-ROW(Data!$D$2:$D$5000)*0.0000001)/(--(Data!$AD$2:$AD$5000)),0),"")} -> 340
A3: {=IFERROR(INDEX(Data!$A$2:$A$5000,$J3),IF(ROW()=2,"No data",""))} -> PEA0003 | B3: {=IFERROR(INDEX(Data!$B$2:$B$5000,$J3),"")} -> Gold Box Melange Butter MP331 | C3: {=IFERROR(INDEX(Data!$C$2:$C$5000,$J3),"")} -> KG | D3: {=IFERROR(INDEX(Data!$D$2:$D$5000,$J3),"")} -> 3654 | E3: {=IFERROR(INDEX(Data!$H$2:$H$5000,$J3),"")} -> 491.6666 | F3: {=IFERROR(INDEX(Data!$J$2:$J$5000,$J3),"")} -> 222.9571 | G3: {=IFERROR(INDEX(Data!$N$2:$N$5000,$J3),"")} -> 75 | H3: {=IFERROR(INDEX(Data!$P$2:$P$5000,$J3),"")} -> 97.44 | J3: {=IFERROR(MATCH(_xlfn.AGGREGATE(14,6,(Data!$D$2:$D$5000-ROW(Data!$D$2:$D$5000)*0.0000001)/(--(Data!$AD$2:$AD$5000)),ROW()-1),(Data!$D$2:$D$5000-ROW(Data!$D$2:$D$5000)*0.0000001)/(--(Data!$AD$2:$AD$5000)),0),"")} -> 339
A4: {=IFERROR(INDEX(Data!$A$2:$A$5000,$J4),IF(ROW()=2,"No data",""))} -> PEA0006 | B4: {=IFERROR(INDEX(Data!$B$2:$B$5000,$J4),"")} -> Gold Box Extra Butter MP341 5 Kg | C4: {=IFERROR(INDEX(Data!$C$2:$C$5000,$J4),"")} -> KG | D4: {=IFERROR(INDEX(Data!$D$2:$D$5000,$J4),"")} -> 799.2304 | E4: {=IFERROR(INDEX(Data!$H$2:$H$5000,$J4),"")} -> 139.8032 | F4: {=IFERROR(INDEX(Data!$J$2:$J$5000,$J4),"")} -> 171.5049 | G4: {=IFERROR(INDEX(Data!$N$2:$N$5000,$J4),"")} -> 81.1098 | H4: {=IFERROR(INDEX(Data!$P$2:$P$5000,$J4),"")} -> 19.7073 | J4: {=IFERROR(MATCH(_xlfn.AGGREGATE(14,6,(Data!$D$2:$D$5000-ROW(Data!$D$2:$D$5000)*0.0000001)/(--(Data!$AD$2:$AD$5000)),ROW()-1),(Data!$D$2:$D$5000-ROW(Data!$D$2:$D$5000)*0.0000001)/(--(Data!$AD$2:$AD$5000)),0),"")} -> 342
A5: {=IFERROR(INDEX(Data!$A$2:$A$5000,$J5),IF(ROW()=2,"No data",""))} -> POT0046 | B5: {=IFERROR(INDEX(Data!$B$2:$B$5000,$J5),"")} -> Australian Butter Unsalted | C5: {=IFERROR(INDEX(Data!$C$2:$C$5000,$J5),"")} -> KG | D5: {=IFERROR(INDEX(Data!$D$2:$D$5000,$J5),"")} -> 675 | E5: {=IFERROR(INDEX(Data!$H$2:$H$5000,$J5),"")} -> 1366.6666 | F5: {=IFERROR(INDEX(Data!$J$2:$J$5000,$J5),"")} -> 14.817 | G5: {=IFERROR(INDEX(Data!$N$2:$N$5000,$J5),"")} -> 150 | H5: {=IFERROR(INDEX(Data!$P$2:$P$5000,$J5),"")} -> 9 | J5: {=IFERROR(MATCH(_xlfn.AGGREGATE(14,6,(Data!$D$2:$D$5000-ROW(Data!$D$2:$D$5000)*0.0000001)/(--(Data!$AD$2:$AD$5000)),ROW()-1),(Data!$D$2:$D$5000-ROW(Data!$D$2:$D$5000)*0.0000001)/(--(Data!$AD$2:$AD$5000)),0),"")} -> 623
A6: {=IFERROR(INDEX(Data!$A$2:$A$5000,$J6),IF(ROW()=2,"No data",""))} -> PEA0005 | B6: {=IFERROR(INDEX(Data!$B$2:$B$5000,$J6),"")} -> Gold Box Melange Butter MP331 5 Kg | C6: {=IFERROR(INDEX(Data!$C$2:$C$5000,$J6),"")} -> KG | D6: {=IFERROR(INDEX(Data!$D$2:$D$5000,$J6),"")} -> 365.0202 | E6: {=IFERROR(INDEX(Data!$H$2:$H$5000,$J6),"")} -> 281.9261 | F6: {=IFERROR(INDEX(Data!$J$2:$J$5000,$J6),"")} -> 38.8422 | G6: {=IFERROR(INDEX(Data!$N$2:$N$5000,$J6),"")} -> 10.32 | H6: {=IFERROR(INDEX(Data!$P$2:$P$5000,$J6),"")} -> 70.7403 | J6: {=IFERROR(MATCH(_xlfn.AGGREGATE(14,6,(Data!$D$2:$D$5000-ROW(Data!$D$2:$D$5000)*0.0000001)/(--(Data!$AD$2:$AD$5000)),ROW()-1),(Data!$D$2:$D$5000-ROW(Data!$D$2:$D$5000)*0.0000001)/(--(Data!$AD$2:$AD$5000)),0),"")} -> 341
A7: {=IFERROR(INDEX(Data!$A$2:$A$5000,$J7),IF(ROW()=2,"No data",""))} -> PEA0010 | B7: {=IFERROR(INDEX(Data!$B$2:$B$5000,$J7),"")} -> Gold Box Extra Butter MP341 1 Kg | C7: {=IFERROR(INDEX(Data!$C$2:$C$5000,$J7),"")} -> KG | D7: {=IFERROR(INDEX(Data!$D$2:$D$5000,$J7),"")} -> 355.0701 | E7: {=IFERROR(INDEX(Data!$H$2:$H$5000,$J7),"")} -> 118.6149 | F7: {=IFERROR(INDEX(Data!$J$2:$J$5000,$J7),"")} -> 89.8047 | G7: {=IFERROR(INDEX(Data!$N$2:$N$5000,$J7),"")} -> 7.7 | H7: {=IFERROR(INDEX(Data!$P$2:$P$5000,$J7),"")} -> 92.226 | J7: {=IFERROR(MATCH(_xlfn.AGGREGATE(14,6,(Data!$D$2:$D$5000-ROW(Data!$D$2:$D$5000)*0.0000001)/(--(Data!$AD$2:$AD$5000)),ROW()-1),(Data!$D$2:$D$5000-ROW(Data!$D$2:$D$5000)*0.0000001)/(--(Data!$AD$2:$AD$5000)),0),"")} -> 346
A8: {=IFERROR(INDEX(Data!$A$2:$A$5000,$J8),IF(ROW()=2,"No data",""))} -> PEA0007 | B8: {=IFERROR(INDEX(Data!$B$2:$B$5000,$J8),"")} -> Gold Box Melange Butter MP331 250 Gr - Sample | C8: {=IFERROR(INDEX(Data!$C$2:$C$5000,$J8),"")} -> PACK | D8: {=IFERROR(INDEX(Data!$D$2:$D$5000,$J8),"")} -> 22 | E8: {=IFERROR(INDEX(Data!$H$2:$H$5000,$J8),"")} -> 9.6666 | F8: {=IFERROR(INDEX(Data!$J$2:$J$5000,$J8),"")} -> 68.2805 | G8: {=IFERROR(INDEX(Data!$N$2:$N$5000,$J8),"")} -> 0 | H8: {=IFERROR(INDEX(Data!$P$2:$P$5000,$J8),"")} -> 0 | J8: {=IFERROR(MATCH(_xlfn.AGGREGATE(14,6,(Data!$D$2:$D$5000-ROW(Data!$D$2:$D$5000)*0.0000001)/(--(Data!$AD$2:$AD$5000)),ROW()-1),(Data!$D$2:$D$5000-ROW(Data!$D$2:$D$5000)*0.0000001)/(--(Data!$AD$2:$AD$5000)),0),"")} -> 343
A9: {=IFERROR(INDEX(Data!$A$2:$A$5000,$J9),IF(ROW()=2,"No data",""))} -> PAN0001 | B9: {=IFERROR(INDEX(Data!$B$2:$B$5000,$J9),"")} -> Australian Butter Unsalted 5 Kg | C9: {=IFERROR(INDEX(Data!$C$2:$C$5000,$J9),"")} -> KG | D9: {=IFERROR(INDEX(Data!$D$2:$D$5000,$J9),"")} -> 20 | E9: {=IFERROR(INDEX(Data!$H$2:$H$5000,$J9),"")} -> 0 | F9: {=IFERROR(INDEX(Data!$J$2:$J$5000,$J9),"")} -> 0 | G9: {=IFERROR(INDEX(Data!$N$2:$N$5000,$J9),"")} -> 0 | H9: {=IFERROR(INDEX(Data!$P$2:$P$5000,$J9),"")} -> 0 | J9: {=IFERROR(MATCH(_xlfn.AGGREGATE(14,6,(Data!$D$2:$D$5000-ROW(Data!$D$2:$D$5000)*0.0000001)/(--(Data!$AD$2:$AD$5000)),ROW()-1),(Data!$D$2:$D$5000-ROW(Data!$D$2:$D$5000)*0.0000001)/(--(Data!$AD$2:$AD$5000)),0),"")} -> 257
A10: {=IFERROR(INDEX(Data!$A$2:$A$5000,$J10),IF(ROW()=2,"No data",""))} -> PEA0008 | B10: {=IFERROR(INDEX(Data!$B$2:$B$5000,$J10),"")} -> Gold Box Extra Butter MP341 250gr - Sample | C10: {=IFERROR(INDEX(Data!$C$2:$C$5000,$J10),"")} -> PACK | D10: {=IFERROR(INDEX(Data!$D$2:$D$5000,$J10),"")} -> 13 | E10: {=IFERROR(INDEX(Data!$H$2:$H$5000,$J10),"")} -> 9 | F10: {=IFERROR(INDEX(Data!$J$2:$J$5000,$J10),"")} -> 43.3333 | G10: {=IFERROR(INDEX(Data!$N$2:$N$5000,$J10),"")} -> 0 | H10: {=IFERROR(INDEX(Data!$P$2:$P$5000,$J10),"")} -> 0 | J10: {=IFERROR(MATCH(_xlfn.AGGREGATE(14,6,(Data!$D$2:$D$5000-ROW(Data!$D$2:$D$5000)*0.0000001)/(--(Data!$AD$2:$AD$5000)),ROW()-1),(Data!$D$2:$D$5000-ROW(Data!$D$2:$D$5000)*0.0000001)/(--(Data!$AD$2:$AD$5000)),0),"")} -> 344
A11: {=IFERROR(INDEX(Data!$A$2:$A$5000,$J11),IF(ROW()=2,"No data",""))} -> POT0049 | B11: {=IFERROR(INDEX(Data!$B$2:$B$5000,$J11),"")} -> Australian Butter Unsalted 250Gr - Sample | C11: {=IFERROR(INDEX(Data!$C$2:$C$5000,$J11),"")} -> PACK | D11: {=IFERROR(INDEX(Data!$D$2:$D$5000,$J11),"")} -> 13 | E11: {=IFERROR(INDEX(Data!$H$2:$H$5000,$J11),"")} -> 2 | F11: {=IFERROR(INDEX(Data!$J$2:$J$5000,$J11),"")} -> 195.1951 | G11: {=IFERROR(INDEX(Data!$N$2:$N$5000,$J11),"")} -> 0 | H11: {=IFERROR(INDEX(Data!$P$2:$P$5000,$J11),"")} -> 0 | J11: {=IFERROR(MATCH(_xlfn.AGGREGATE(14,6,(Data!$D$2:$D$5000-ROW(Data!$D$2:$D$5000)*0.0000001)/(--(Data!$AD$2:$AD$5000)),ROW()-1),(Data!$D$2:$D$5000-ROW(Data!$D$2:$D$5000)*0.0000001)/(--(Data!$AD$2:$AD$5000)),0),"")} -> 626
A12: {=IFERROR(INDEX(Data!$A$2:$A$5000,$J12),IF(ROW()=2,"No data",""))} -> PAG0004 | B12: {=IFERROR(INDEX(Data!$B$2:$B$5000,$J12),"")} -> Agri-Best Unsalted Butter 250 Gr - Sample | C12: {=IFERROR(INDEX(Data!$C$2:$C$5000,$J12),"")} -> PACK | D12: {=IFERROR(INDEX(Data!$D$2:$D$5000,$J12),"")} -> 12 | E12: {=IFERROR(INDEX(Data!$H$2:$H$5000,$J12),"")} -> 0 | F12: {=IFERROR(INDEX(Data!$J$2:$J$5000,$J12),"")} -> 0 | G12: {=IFERROR(INDEX(Data!$N$2:$N$5000,$J12),"")} -> 0 | H12: {=IFERROR(INDEX(Data!$P$2:$P$5000,$J12),"")} -> 0 | J12: {=IFERROR(MATCH(_xlfn.AGGREGATE(14,6,(Data!$D$2:$D$5000-ROW(Data!$D$2:$D$5000)*0.0000001)/(--(Data!$AD$2:$AD$5000)),ROW()-1),(Data!$D$2:$D$5000-ROW(Data!$D$2:$D$5000)*0.0000001)/(--(Data!$AD$2:$AD$5000)),0),"")} -> 253
A13: {=IFERROR(INDEX(Data!$A$2:$A$5000,$J13),IF(ROW()=2,"No data",""))} -> BKL1533-18 | B13: {=IFERROR(INDEX(Data!$B$2:$B$5000,$J13),"")} -> Butter Oil Substitute | C13: {=IFERROR(INDEX(Data!$C$2:$C$5000,$J13),"")} -> PAIL | D13: {=IFERROR(INDEX(Data!$D$2:$D$5000,$J13),"")} -> 0 | E13: {=IFERROR(INDEX(Data!$H$2:$H$5000,$J13),"")} -> 0 | F13: {=IFERROR(INDEX(Data!$J$2:$J$5000,$J13),"")} -> 0 | G13: {=IFERROR(INDEX(Data!$N$2:$N$5000,$J13),"")} -> 0 | H13: {=IFERROR(INDEX(Data!$P$2:$P$5000,$J13),"")} -> 0 | J13: {=IFERROR(MATCH(_xlfn.AGGREGATE(14,6,(Data!$D$2:$D$5000-ROW(Data!$D$2:$D$5000)*0.0000001)/(--(Data!$AD$2:$AD$5000)),ROW()-1),(Data!$D$2:$D$5000-ROW(Data!$D$2:$D$5000)*0.0000001)/(--(Data!$AD$2:$AD$5000)),0),"")} -> 128
... A37: {=IFERROR(INDEX(Data!$A$2:$A$5000,$J37),IF(ROW()=2,"No data",""))} | B37: {=IFERROR(INDEX(Data!$B$2:$B$5000,$J37),"")} | C37: {=IFERROR(INDEX(Data!$C$2:$C$5000,$J37),"")} | D37: {=IFERROR(INDEX(Data!$D$2:$D$5000,$J37),"")} | E37: {=IFERROR(INDEX(Data!$H$2:$H$5000,$J37),"")} | F37: {=IFERROR(INDEX(Data!$J$2:$J$5000,$J37),"")} | G37: {=IFERROR(INDEX(Data!$N$2:$N$5000,$J37),"")} | H37: {=IFERROR(INDEX(Data!$P$2:$P$5000,$J37),"")} | J37: {=IFERROR(MATCH(_xlfn.AGGREGATE(14,6,(Data!$D$2:$D$5000-ROW(Data!$D$2:$D$5000)*0.0000001)/(--(Data!$AD$2:$AD$5000)),ROW()-1),(Data!$D$2:$D$5000-ROW(Data!$D$2:$D$5000)*0.0000001)/(--(Data!$AD$2:$AD$5000)),0),"")}

Sheet Pristine
A1: =Data!A1 -> Kode_Brg | B1: =Data!B1 -> Nama_Brg | C1: =Data!C1 -> Kode_sat_Std | D1: =Data!D1 -> Saldo Akhir (Std) | E1: =Data!H1 -> Rata - Rata 3 Bulan | F1: =Data!J1 -> Buffer Day (3 Bulan) | G1: =Data!N1 -> Penjualan Tgl 1 sd 02 Sep 2026 | H1: =Data!P1 -> Buffer Day (Tgl 1 sd 02 Sep 2026) | J1: Helper: Data row# (auto)
A2: {=IFERROR(INDEX(Data!$A$2:$A$5000,$J2),IF(ROW()=2,"No data",""))} -> PIF0012 | B2: {=IFERROR(INDEX(Data!$B$2:$B$5000,$J2),"")} -> Pristine Classic Cooking Cream 1 Lt | C2: {=IFERROR(INDEX(Data!$C$2:$C$5000,$J2),"")} -> LTR | D2: {=IFERROR(INDEX(Data!$D$2:$D$5000,$J2),"")} -> 14980 | E2: {=IFERROR(INDEX(Data!$H$2:$H$5000,$J2),"")} -> 930 | F2: {=IFERROR(INDEX(Data!$J$2:$J$5000,$J2),"")} -> 483.2258 | G2: {=IFERROR(INDEX(Data!$N$2:$N$5000,$J2),"")} -> 111 | H2: {=IFERROR(INDEX(Data!$P$2:$P$5000,$J2),"")} -> 269.9099 | J2: {=IFERROR(MATCH(_xlfn.AGGREGATE(14,6,(Data!$D$2:$D$5000-ROW(Data!$D$2:$D$5000)*0.0000001)/(--(Data!$T$2:$T$5000)),ROW()-1),(Data!$D$2:$D$5000-ROW(Data!$D$2:$D$5000)*0.0000001)/(--(Data!$T$2:$T$5000)),0),"")} -> 365
A3: {=IFERROR(INDEX(Data!$A$2:$A$5000,$J3),IF(ROW()=2,"No data",""))} -> PIF0011 | B3: {=IFERROR(INDEX(Data!$B$2:$B$5000,$J3),"")} -> Pristine Classic Whip Topping 1 Lt | C3: {=IFERROR(INDEX(Data!$C$2:$C$5000,$J3),"")} -> LTR | D3: {=IFERROR(INDEX(Data!$D$2:$D$5000,$J3),"")} -> 1161 | E3: {=IFERROR(INDEX(Data!$H$2:$H$5000,$J3),"")} -> 232.3333 | F3: {=IFERROR(INDEX(Data!$J$2:$J$5000,$J3),"")} -> 149.9147 | G3: {=IFERROR(INDEX(Data!$N$2:$N$5000,$J3),"")} -> 8 | H3: {=IFERROR(INDEX(Data!$P$2:$P$5000,$J3),"")} -> 290.25 | J3: {=IFERROR(MATCH(_xlfn.AGGREGATE(14,6,(Data!$D$2:$D$5000-ROW(Data!$D$2:$D$5000)*0.0000001)/(--(Data!$T$2:$T$5000)),ROW()-1),(Data!$D$2:$D$5000-ROW(Data!$D$2:$D$5000)*0.0000001)/(--(Data!$T$2:$T$5000)),0),"")} -> 364
A4: {=IFERROR(INDEX(Data!$A$2:$A$5000,$J4),IF(ROW()=2,"No data",""))} -> PIF0006 | B4: {=IFERROR(INDEX(Data!$B$2:$B$5000,$J4),"")} -> Pristine Classic Whip Topping 12x1 Lt | C4: {=IFERROR(INDEX(Data!$C$2:$C$5000,$J4),"")} -> KTN | D4: {=IFERROR(INDEX(Data!$D$2:$D$5000,$J4),"")} -> 0 | E4: {=IFERROR(INDEX(Data!$H$2:$H$5000,$J4),"")} -> 0 | F4: {=IFERROR(INDEX(Data!$J$2:$J$5000,$J4),"")} -> 0 | G4: {=IFERROR(INDEX(Data!$N$2:$N$5000,$J4),"")} -> 0 | H4: {=IFERROR(INDEX(Data!$P$2:$P$5000,$J4),"")} -> 0 | J4: {=IFERROR(MATCH(_xlfn.AGGREGATE(14,6,(Data!$D$2:$D$5000-ROW(Data!$D$2:$D$5000)*0.0000001)/(--(Data!$T$2:$T$5000)),ROW()-1),(Data!$D$2:$D$5000-ROW(Data!$D$2:$D$5000)*0.0000001)/(--(Data!$T$2:$T$5000)),0),"")} -> 359
A5: {=IFERROR(INDEX(Data!$A$2:$A$5000,$J5),IF(ROW()=2,"No data",""))} -> PIF0007 | B5: {=IFERROR(INDEX(Data!$B$2:$B$5000,$J5),"")} -> Pristine Classic Cooking Cream 12x1 Lt | C5: {=IFERROR(INDEX(Data!$C$2:$C$5000,$J5),"")} -> KTN | D5: {=IFERROR(INDEX(Data!$D$2:$D$5000,$J5),"")} -> 0 | E5: {=IFERROR(INDEX(Data!$H$2:$H$5000,$J5),"")} -> 0 | F5: {=IFERROR(INDEX(Data!$J$2:$J$5000,$J5),"")} -> 0 | G5: {=IFERROR(INDEX(Data!$N$2:$N$5000,$J5),"")} -> 0 | H5: {=IFERROR(INDEX(Data!$P$2:$P$5000,$J5),"")} -> 0 | J5: {=IFERROR(MATCH(_xlfn.AGGREGATE(14,6,(Data!$D$2:$D$5000-ROW(Data!$D$2:$D$5000)*0.0000001)/(--(Data!$T$2:$T$5000)),ROW()-1),(Data!$D$2:$D$5000-ROW(Data!$D$2:$D$5000)*0.0000001)/(--(Data!$T$2:$T$5000)),0),"")} -> 360
A6: {=IFERROR(INDEX(Data!$A$2:$A$5000,$J6),IF(ROW()=2,"No data",""))} -> PIF0013 | B6: {=IFERROR(INDEX(Data!$B$2:$B$5000,$J6),"")} -> Pristine Multipurpose Cream 12x1 Lt | C6: {=IFERROR(INDEX(Data!$C$2:$C$5000,$J6),"")} -> KTN | D6: {=IFERROR(INDEX(Data!$D$2:$D$5000,$J6),"")} -> 0 | E6: {=IFERROR(INDEX(Data!$H$2:$H$5000,$J6),"")} -> 0 | F6: {=IFERROR(INDEX(Data!$J$2:$J$5000,$J6),"")} -> 0 | G6: {=IFERROR(INDEX(Data!$N$2:$N$5000,$J6),"")} -> 0 | H6: {=IFERROR(INDEX(Data!$P$2:$P$5000,$J6),"")} -> 0 | J6: {=IFERROR(MATCH(_xlfn.AGGREGATE(14,6,(Data!$D$2:$D$5000-ROW(Data!$D$2:$D$5000)*0.0000001)/(--(Data!$T$2:$T$5000)),ROW()-1),(Data!$D$2:$D$5000-ROW(Data!$D$2:$D$5000)*0.0000001)/(--(Data!$T$2:$T$5000)),0),"")} -> 366
A7: {=IFERROR(INDEX(Data!$A$2:$A$5000,$J7),IF(ROW()=2,"No data",""))} -> PIF0014 | B7: {=IFERROR(INDEX(Data!$B$2:$B$5000,$J7),"")} -> Pristine Multipurpose Cream 1 Lt | C7: {=IFERROR(INDEX(Data!$C$2:$C$5000,$J7),"")} -> LTR | D7: {=IFERROR(INDEX(Data!$D$2:$D$5000,$J7),"")} -> 0 | E7: {=IFERROR(INDEX(Data!$H$2:$H$5000,$J7),"")} -> 0 | F7: {=IFERROR(INDEX(Data!$J$2:$J$5000,$J7),"")} -> 0 | G7: {=IFERROR(INDEX(Data!$N$2:$N$5000,$J7),"")} -> 0 | H7: {=IFERROR(INDEX(Data!$P$2:$P$5000,$J7),"")} -> 0 | J7: {=IFERROR(MATCH(_xlfn.AGGREGATE(14,6,(Data!$D$2:$D$5000-ROW(Data!$D$2:$D$5000)*0.0000001)/(--(Data!$T$2:$T$5000)),ROW()-1),(Data!$D$2:$D$5000-ROW(Data!$D$2:$D$5000)*0.0000001)/(--(Data!$T$2:$T$5000)),0),"")} -> 367
A8: {=IFERROR(INDEX(Data!$A$2:$A$5000,$J8),IF(ROW()=2,"No data",""))} | B8: {=IFERROR(INDEX(Data!$B$2:$B$5000,$J8),"")} | C8: {=IFERROR(INDEX(Data!$C$2:$C$5000,$J8),"")} | D8: {=IFERROR(INDEX(Data!$D$2:$D$5000,$J8),"")} | E8: {=IFERROR(INDEX(Data!$H$2:$H$5000,$J8),"")} | F8: {=IFERROR(INDEX(Data!$J$2:$J$5000,$J8),"")} | G8: {=IFERROR(INDEX(Data!$N$2:$N$5000,$J8),"")} | H8: {=IFERROR(INDEX(Data!$P$2:$P$5000,$J8),"")} | J8: {=IFERROR(MATCH(_xlfn.AGGREGATE(14,6,(Data!$D$2:$D$5000-ROW(Data!$D$2:$D$5000)*0.0000001)/(--(Data!$T$2:$T$5000)),ROW()-1),(Data!$D$2:$D$5000-ROW(Data!$D$2:$D$5000)*0.0000001)/(--(Data!$T$2:$T$5000)),0),"")}
A9: {=IFERROR(INDEX(Data!$A$2:$A$5000,$J9),IF(ROW()=2,"No data",""))} | B9: {=IFERROR(INDEX(Data!$B$2:$B$5000,$J9),"")} | C9: {=IFERROR(INDEX(Data!$C$2:$C$5000,$J9),"")} | D9: {=IFERROR(INDEX(Data!$D$2:$D$5000,$J9),"")} | E9: {=IFERROR(INDEX(Data!$H$2:$H$5000,$J9),"")} | F9: {=IFERROR(INDEX(Data!$J$2:$J$5000,$J9),"")} | G9: {=IFERROR(INDEX(Data!$N$2:$N$5000,$J9),"")} | H9: {=IFERROR(INDEX(Data!$P$2:$P$5000,$J9),"")} | J9: {=IFERROR(MATCH(_xlfn.AGGREGATE(14,6,(Data!$D$2:$D$5000-ROW(Data!$D$2:$D$5000)*0.0000001)/(--(Data!$T$2:$T$5000)),ROW()-1),(Data!$D$2:$D$5000-ROW(Data!$D$2:$D$5000)*0.0000001)/(--(Data!$T$2:$T$5000)),0),"")}
A10: {=IFERROR(INDEX(Data!$A$2:$A$5000,$J10),IF(ROW()=2,"No data",""))} | B10: {=IFERROR(INDEX(Data!$B$2:$B$5000,$J10),"")} | C10: {=IFERROR(INDEX(Data!$C$2:$C$5000,$J10),"")} | D10: {=IFERROR(INDEX(Data!$D$2:$D$5000,$J10),"")} | E10: {=IFERROR(INDEX(Data!$H$2:$H$5000,$J10),"")} | F10: {=IFERROR(INDEX(Data!$J$2:$J$5000,$J10),"")} | G10: {=IFERROR(INDEX(Data!$N$2:$N$5000,$J10),"")} | H10: {=IFERROR(INDEX(Data!$P$2:$P$5000,$J10),"")} | J10: {=IFERROR(MATCH(_xlfn.AGGREGATE(14,6,(Data!$D$2:$D$5000-ROW(Data!$D$2:$D$5000)*0.0000001)/(--(Data!$T$2:$T$5000)),ROW()-1),(Data!$D$2:$D$5000-ROW(Data!$D$2:$D$5000)*0.0000001)/(--(Data!$T$2:$T$5000)),0),"")}
A11: {=IFERROR(INDEX(Data!$A$2:$A$5000,$J11),IF(ROW()=2,"No data",""))} | B11: {=IFERROR(INDEX(Data!$B$2:$B$5000,$J11),"")} | C11: {=IFERROR(INDEX(Data!$C$2:$C$5000,$J11),"")} | D11: {=IFERROR(INDEX(Data!$D$2:$D$5000,$J11),"")} | E11: {=IFERROR(INDEX(Data!$H$2:$H$5000,$J11),"")} | F11: {=IFERROR(INDEX(Data!$J$2:$J$5000,$J11),"")} | G11: {=IFERROR(INDEX(Data!$N$2:$N$5000,$J11),"")} | H11: {=IFERROR(INDEX(Data!$P$2:$P$5000,$J11),"")} | J11: {=IFERROR(MATCH(_xlfn.AGGREGATE(14,6,(Data!$D$2:$D$5000-ROW(Data!$D$2:$D$5000)*0.0000001)/(--(Data!$T$2:$T$5000)),ROW()-1),(Data!$D$2:$D$5000-ROW(Data!$D$2:$D$5000)*0.0000001)/(--(Data!$T$2:$T$5000)),0),"")}
A12: {=IFERROR(INDEX(Data!$A$2:$A$5000,$J12),IF(ROW()=2,"No data",""))} | B12: {=IFERROR(INDEX(Data!$B$2:$B$5000,$J12),"")} | C12: {=IFERROR(INDEX(Data!$C$2:$C$5000,$J12),"")} | D12: {=IFERROR(INDEX(Data!$D$2:$D$5000,$J12),"")} | E12: {=IFERROR(INDEX(Data!$H$2:$H$5000,$J12),"")} | F12: {=IFERROR(INDEX(Data!$J$2:$J$5000,$J12),"")} | G12: {=IFERROR(INDEX(Data!$N$2:$N$5000,$J12),"")} | H12: {=IFERROR(INDEX(Data!$P$2:$P$5000,$J12),"")} | J12: {=IFERROR(MATCH(_xlfn.AGGREGATE(14,6,(Data!$D$2:$D$5000-ROW(Data!$D$2:$D$5000)*0.0000001)/(--(Data!$T$2:$T$5000)),ROW()-1),(Data!$D$2:$D$5000-ROW(Data!$D$2:$D$5000)*0.0000001)/(--(Data!$T$2:$T$5000)),0),"")}
A13: {=IFERROR(INDEX(Data!$A$2:$A$5000,$J13),IF(ROW()=2,"No data",""))} | B13: {=IFERROR(INDEX(Data!$B$2:$B$5000,$J13),"")} | C13: {=IFERROR(INDEX(Data!$C$2:$C$5000,$J13),"")} | D13: {=IFERROR(INDEX(Data!$D$2:$D$5000,$J13),"")} | E13: {=IFERROR(INDEX(Data!$H$2:$H$5000,$J13),"")} | F13: {=IFERROR(INDEX(Data!$J$2:$J$5000,$J13),"")} | G13: {=IFERROR(INDEX(Data!$N$2:$N$5000,$J13),"")} | H13: {=IFERROR(INDEX(Data!$P$2:$P$5000,$J13),"")} | J13: {=IFERROR(MATCH(_xlfn.AGGREGATE(14,6,(Data!$D$2:$D$5000-ROW(Data!$D$2:$D$5000)*0.0000001)/(--(Data!$T$2:$T$5000)),ROW()-1),(Data!$D$2:$D$5000-ROW(Data!$D$2:$D$5000)*0.0000001)/(--(Data!$T$2:$T$5000)),0),"")}
... A27: {=IFERROR(INDEX(Data!$A$2:$A$5000,$J27),IF(ROW()=2,"No data",""))} | B27: {=IFERROR(INDEX(Data!$B$2:$B$5000,$J27),"")} | C27: {=IFERROR(INDEX(Data!$C$2:$C$5000,$J27),"")} | D27: {=IFERROR(INDEX(Data!$D$2:$D$5000,$J27),"")} | E27: {=IFERROR(INDEX(Data!$H$2:$H$5000,$J27),"")} | F27: {=IFERROR(INDEX(Data!$J$2:$J$5000,$J27),"")} | G27: {=IFERROR(INDEX(Data!$N$2:$N$5000,$J27),"")} | H27: {=IFERROR(INDEX(Data!$P$2:$P$5000,$J27),"")} | J27: {=IFERROR(MATCH(_xlfn.AGGREGATE(14,6,(Data!$D$2:$D$5000-ROW(Data!$D$2:$D$5000)*0.0000001)/(--(Data!$T$2:$T$5000)),ROW()-1),(Data!$D$2:$D$5000-ROW(Data!$D$2:$D$5000)*0.0000001)/(--(Data!$T$2:$T$5000)),0),"")}

Sheet O Sole
A1: =Data!A1 -> Kode_Brg | B1: =Data!B1 -> Nama_Brg | C1: =Data!C1 -> Kode_sat_Std | D1: =Data!D1 -> Saldo Akhir (Std) | E1: =Data!H1 -> Rata - Rata 3 Bulan | F1: =Data!J1 -> Buffer Day (3 Bulan) | G1: =Data!N1 -> Penjualan Tgl 1 sd 02 Sep 2026 | H1: =Data!P1 -> Buffer Day (Tgl 1 sd 02 Sep 2026) | J1: Helper: Data row# (auto)
A2: {=IFERROR(INDEX(Data!$A$2:$A$5000,$J2),IF(ROW()=2,"No data",""))} -> POS0024 | B2: {=IFERROR(INDEX(Data!$B$2:$B$5000,$J2),"")} -> O Sole Pomodori Pelati Peeled Tomatoes 2.5Kg | C2: {=IFERROR(INDEX(Data!$C$2:$C$5000,$J2),"")} -> CAN | D2: {=IFERROR(INDEX(Data!$D$2:$D$5000,$J2),"")} -> 3603 | E2: {=IFERROR(INDEX(Data!$H$2:$H$5000,$J2),"")} -> 4794.6666 | F2: {=IFERROR(INDEX(Data!$J$2:$J$5000,$J2),"")} -> 22.5438 | G2: {=IFERROR(INDEX(Data!$N$2:$N$5000,$J2),"")} -> 653 | H2: {=IFERROR(INDEX(Data!$P$2:$P$5000,$J2),"")} -> 11.0352 | J2: {=IFERROR(MATCH(_xlfn.AGGREGATE(14,6,(Data!$D$2:$D$5000-ROW(Data!$D$2:$D$5000)*0.0000001)/(--(Data!$U$2:$U$5000)),ROW()-1),(Data!$D$2:$D$5000-ROW(Data!$D$2:$D$5000)*0.0000001)/(--(Data!$U$2:$U$5000)),0),"")} -> 583
A3: {=IFERROR(INDEX(Data!$A$2:$A$5000,$J3),IF(ROW()=2,"No data",""))} -> POS0031 | B3: {=IFERROR(INDEX(Data!$B$2:$B$5000,$J3),"")} -> O Sole Don Pistacchio 560 Gr | C3: {=IFERROR(INDEX(Data!$C$2:$C$5000,$J3),"")} -> JAR | D3: {=IFERROR(INDEX(Data!$D$2:$D$5000,$J3),"")} -> 1133 | E3: {=IFERROR(INDEX(Data!$H$2:$H$5000,$J3),"")} -> 1 | F3: {=IFERROR(INDEX(Data!$J$2:$J$5000,$J3),"")} -> 34024.024 | G3: {=IFERROR(INDEX(Data!$N$2:$N$5000,$J3),"")} -> 0 | H3: {=IFERROR(INDEX(Data!$P$2:$P$5000,$J3),"")} -> 0 | J3: {=IFERROR(MATCH(_xlfn.AGGREGATE(14,6,(Data!$D$2:$D$5000-ROW(Data!$D$2:$D$5000)*0.0000001)/(--(Data!$U$2:$U$5000)),ROW()-1),(Data!$D$2:$D$5000-ROW(Data!$D$2:$D$5000)*0.0000001)/(--(Data!$U$2:$U$5000)),0),"")} -> 590
A4: {=IFERROR(INDEX(Data!$A$2:$A$5000,$J4),IF(ROW()=2,"No data",""))} -> POS0025 | B4: {=IFERROR(INDEX(Data!$B$2:$B$5000,$J4),"")} -> O Sole Doppio Concentrato Paste Tomato 2.2 Kg | C4: {=IFERROR(INDEX(Data!$C$2:$C$5000,$J4),"")} -> CAN | D4: {=IFERROR(INDEX(Data!$D$2:$D$5000,$J4),"")} -> 1082 | E4: {=IFERROR(INDEX(Data!$H$2:$H$5000,$J4),"")} -> 23.3333 | F4: {=IFERROR(INDEX(Data!$J$2:$J$5000,$J4),"")} -> 1391.2819 | G4: {=IFERROR(INDEX(Data!$N$2:$N$5000,$J4),"")} -> 0 | H4: {=IFERROR(INDEX(Data!$P$2:$P$5000,$J4),"")} -> 0 | J4: {=IFERROR(MATCH(_xlfn.AGGREGATE(14,6,(Data!$D$2:$D$5000-ROW(Data!$D$2:$D$5000)*0.0000001)/(--(Data!$U$2:$U$5000)),ROW()-1),(Data!$D$2:$D$5000-ROW(Data!$D$2:$D$5000)*0.0000001)/(--(Data!$U$2:$U$5000)),0),"")} -> 584
A5: {=IFERROR(INDEX(Data!$A$2:$A$5000,$J5),IF(ROW()=2,"No data",""))} -> POS0028 | B5: {=IFERROR(INDEX(Data!$B$2:$B$5000,$J5),"")} -> O Sole Pomodori Secchi Oilio Di Gir 960 Gr | C5: {=IFERROR(INDEX(Data!$C$2:$C$5000,$J5),"")} -> JAR | D5: {=IFERROR(INDEX(Data!$D$2:$D$5000,$J5),"")} -> 442 | E5: {=IFERROR(INDEX(Data!$H$2:$H$5000,$J5),"")} -> 16.3333 | F5: {=IFERROR(INDEX(Data!$J$2:$J$5000,$J5),"")} -> 811.903 | G5: {=IFERROR(INDEX(Data!$N$2:$N$5000,$J5),"")} -> 0 | H5: {=IFERROR(INDEX(Data!$P$2:$P$5000,$J5),"")} -> 0 | J5: {=IFERROR(MATCH(_xlfn.AGGREGATE(14,6,(Data!$D$2:$D$5000-ROW(Data!$D$2:$D$5000)*0.0000001)/(--(Data!$U$2:$U$5000)),ROW()-1),(Data!$D$2:$D$5000-ROW(Data!$D$2:$D$5000)*0.0000001)/(--(Data!$U$2:$U$5000)),0),"")} -> 587
A6: {=IFERROR(INDEX(Data!$A$2:$A$5000,$J6),IF(ROW()=2,"No data",""))} -> POS0027 | B6: {=IFERROR(INDEX(Data!$B$2:$B$5000,$J6),"")} -> O Sole Olive Verdi Denocciolate 4.1 Kg | C6: {=IFERROR(INDEX(Data!$C$2:$C$5000,$J6),"")} -> CAN | D6: {=IFERROR(INDEX(Data!$D$2:$D$5000,$J6),"")} -> 342 | E6: {=IFERROR(INDEX(Data!$H$2:$H$5000,$J6),"")} -> 13.6666 | F6: {=IFERROR(INDEX(Data!$J$2:$J$5000,$J6),"")} -> 750.8232 | G6: {=IFERROR(INDEX(Data!$N$2:$N$5000,$J6),"")} -> 6 | H6: {=IFERROR(INDEX(Data!$P$2:$P$5000,$J6),"")} -> 114 | J6: {=IFERROR(MATCH(_xlfn.AGGREGATE(14,6,(Data!$D$2:$D$5000-ROW(Data!$D$2:$D$5000)*0.0000001)/(--(Data!$U$2:$U$5000)),ROW()-1),(Data!$D$2:$D$5000-ROW(Data!$D$2:$D$5000)*0.0000001)/(--(Data!$U$2:$U$5000)),0),"")} -> 586
A7: {=IFERROR(INDEX(Data!$A$2:$A$5000,$J7),IF(ROW()=2,"No data",""))} -> POS0026 | B7: {=IFERROR(INDEX(Data!$B$2:$B$5000,$J7),"")} -> O Sole Olive Nere Denocciolate 4.1 Kg | C7: {=IFERROR(INDEX(Data!$C$2:$C$5000,$J7),"")} -> CAN | D7: {=IFERROR(INDEX(Data!$D$2:$D$5000,$J7),"")} -> 297 | E7: {=IFERROR(INDEX(Data!$H$2:$H$5000,$J7),"")} -> 29 | F7: {=IFERROR(INDEX(Data!$J$2:$J$5000,$J7),"")} -> 307.2625 | G7: {=IFERROR(INDEX(Data!$N$2:$N$5000,$J7),"")} -> 14 | H7: {=IFERROR(INDEX(Data!$P$2:$P$5000,$J7),"")} -> 42.4285 | J7: {=IFERROR(MATCH(_xlfn.AGGREGATE(14,6,(Data!$D$2:$D$5000-ROW(Data!$D$2:$D$5000)*0.0000001)/(--(Data!$U$2:$U$5000)),ROW()-1),(Data!$D$2:$D$5000-ROW(Data!$D$2:$D$5000)*0.0000001)/(--(Data!$U$2:$U$5000)),0),"")} -> 585
A8: {=IFERROR(INDEX(Data!$A$2:$A$5000,$J8),IF(ROW()=2,"No data",""))} -> POS0029 | B8: {=IFERROR(INDEX(Data!$B$2:$B$5000,$J8),"")} -> O Sole Pesto Di Pistacchio 560 Gr | C8: {=IFERROR(INDEX(Data!$C$2:$C$5000,$J8),"")} -> JAR | D8: {=IFERROR(INDEX(Data!$D$2:$D$5000,$J8),"")} -> 0 | E8: {=IFERROR(INDEX(Data!$H$2:$H$5000,$J8),"")} -> 0 | F8: {=IFERROR(INDEX(Data!$J$2:$J$5000,$J8),"")} -> 0 | G8: {=IFERROR(INDEX(Data!$N$2:$N$5000,$J8),"")} -> 0 | H8: {=IFERROR(INDEX(Data!$P$2:$P$5000,$J8),"")} -> 0 | J8: {=IFERROR(MATCH(_xlfn.AGGREGATE(14,6,(Data!$D$2:$D$5000-ROW(Data!$D$2:$D$5000)*0.0000001)/(--(Data!$U$2:$U$5000)),ROW()-1),(Data!$D$2:$D$5000-ROW(Data!$D$2:$D$5000)*0.0000001)/(--(Data!$U$2:$U$5000)),0),"")} -> 588
